Workbook

Sheet 選手一覧
A1: 2028年入学世代（現高校2年）中長距離 選手一覧（5000m順）
A2: 陸マガの5000m・3000mSC・1500mランキングを選手ごとに1行にまとめたもの。並び順＝5000mの順位（5000mの記録がない選手はその後ろに他種目の最高順位順）。順位の色：濃い緑＝10位以内、緑＝50位以内、薄緑＝100位以内。見出しのフィルターで高校名・駅伝出場などを絞り込めます。オレンジ＝注目選手（「注目選手」シートに一覧）。メモ列（黄色）は自由に記入してください。
A4: No | B4: 氏名 | C4: 高校 | D4: 5000m 記録 | E4: 5000m 順位 | F4: 3000mSC 記録 | G4: 3000mSC 順位 | H4: 1500m 記録 | I4: 1500m 順位 | J4: 日本海駅伝 （区・区間順位） | K4: 奥球磨駅伝 （区・区間順位） | L4: 備考 | M4: メモ
A5: 1 | B5: ボイ ビリス | C5: 札幌山の手高 | D5: 0.0091405093 | E5: 1 | H5: 0.0026409722 | I5: 3
A6: 2 | B6: 稲垣 翔馴 | C6: 洛南高 | D6: 0.0096434028 | E6: 2 | F6: 0.0064204861 | G6: 19 | H6: 0.0026045139 | I6: 1 | J6: 1区 2位（28:54）
A7: 3 | B7: 石原 向規 | C7: 洛南高 | D7: 0.0096877315 | E7: 3 | H7: 0.0026280093 | I7: 2 | J7: 7区 2位（14:28）
A8: 4 | B8: 若田 大尚 | C8: 学法石川高 | D8: 0.0097143519 | E8: 4 | H8: 0.002721875 | I8: 51
A9: 5 | B9: パレイヨ アントニーイタ | C9: 福岡一高 | D9: 0.0097422454 | E9: 5 | H9: 0.0026788194 | I9: 13 | J9: 2区 1位（8:06）
A10: 6 | B10: 橋本 蒼平 | C10: 佐久長聖高 | D10: 0.0097591435 | E10: 6 | F10: 0.0062690972 | G10: 2 | H10: 0.0027813657 | I10: 209 | J10: 1区 3位（28:58）
A11: 7 | B11: サイモン ムッソーニ | C11: 鎮西学院高 | D11: 0.0097797454 | E11: 7 | K11: 2区 9位（8:36）
A12: 8 | B12: ポール ジョロゲ | C12: 東海大附福岡高 | D12: 0.0098116898 | E12: 8 | H12: 0.0026980324 | I12: 24 | K12: 2区 2位（8:16）
A13: 9 | B13: 美沢 央佑 | C13: 学法石川高 | D13: 0.0098148148 | E13: 9 | H13: 0.0027796296 | I13: 200
A14: 10 | B14: 伊藤 遼 | C14: 佐久長聖高 | D14: 0.0098652778 | E14: 10 | H14: 0.0028207176 | I14: 367
A15: 11 | B15: 酒井 琉史 | C15: 佐久長聖高 | D15: 0.0098707176 | E15: 11 | H15: 0.0027590278 | I15: 132 | J15: 1区 7位（29:06）
A16: 12 | B16: 野口 琉太 | C16: 小林高 | D16: 0.0098730324 | E16: 12 | H16: 0.0026759259 | I16: 8 | K16: 7区 1位（13:45）
A17: 13 | B17: 朝倉 悠羽 | C17: 山梨学院高 | D17: 0.0099006944 | E17: 14 | H17: 0.0026894676 | I17: 18 | J17: 1区 22位（29:47）
A18: 14 | B18: 竹田 櫂司 | C18: 小林高 | D18: 0.0099078704 | E18: 15 | H18: 0.0028393519 | I18: 491 | K18: 3区 3位（23:54）
A19: 15 | B19: 鴨作 大夢 | C19: 東海大甲府高 | D19: 0.0099289352 | E19: 16 | H19: 0.0027094907 | I19: 34 | M19: 東海大
A20: 16 | B20: 上杉 創亮 | C20: 八千代松陰高 | D20: 0.0099413194 | E20: 17 | H20: 0.0028630787 | I20: 656
A21: 17 | B21: 平井 啓太郎 | C21: 西条農高 | D21: 0.0099462963 | E21: 18 | H21: 0.0027243056 | I21: 55
A22: 18 | B22: 山田 莉生 | C22: 拓大一高 | D22: 0.0099721065 | E22: 19 | H22: 0.0027325231 | I22: 70
A23: 19 | B23: 西川 晴貴 | C23: 洛北高 | D23: 0.0099758102 | E23: 20 | H23: 0.0027356481 | I23: 74 | M23: 長期故障
A24: 20 | B24: 小原 健太郎 | C24: 花巻東高 | D24: 0.0099770833 | E24: 21 | H24: 0.0027244213 | I24: 56 | M24: 國學院
A25: 21 | B25: 高田 康介 | C25: 東海大附相模高 | D25: 0.010002431 | E25: 22 | H25: 0.0029390046 | I25: 1197
A26: 22 | B26: 熊谷 颯柊 | C26: 武蔵野学院高 | D26: 0.010010995 | E26: 23
A27: 23 | B27: 武村 翔月 | C27: 佐久長聖高 | D27: 0.010017014 | E27: 24 | F27: 0.0063674769 | G27: 11 | H27: 0.0028085648 | I27: 320 | J27: 4区 10位（24:31）
A28: 24 | B28: 杉平 颯志 | C28: 鳥栖工高 | D28: 0.010019444 | E28: 25 | H28: 0.0026765046 | I28: 9 | K28: 1区 7位（29:50）
A29: 25 | B29: 増田 大誠 | C29: 上田西高 | D29: 0.010022338 | E29: 26 | H29: 0.0026707176 | I29: 7
A30: 26 | B30: 千葉 海虎 | C30: 西条農高 | D30: 0.010032523 | E30: 27
A31: 27 | B31: 小田 桜雅 | C31: 仙台育英学園高 | D31: 0.010033102 | E31: 28 | H31: 0.0027190972 | I31: 48
A32: 28 | B32: 田代 悠翔 | C32: 鳥栖工高 | D32: 0.010040046 | E32: 29 | F32: 0.0070203704 | G32: 355 | H32: 0.0027059028 | I32: 29 | K32: 4区 3位（23:56）
A33: 29 | B33: 亀山 純平 | C33: 佐野日大高 | D33: 0.010040162 | E33: 30 | H33: 0.0028436343 | I33: 520
A34: 30 | B34: 小林 柾輝 | C34: 八千代松陰高 | D34: 0.010042245 | E34: 31
A35: 31 | B35: 長尾 羚煌 | C35: 市長崎商高 | D35: 0.010043056 | E35: 32 | H35: 0.0027251157 | I35: 58
A36: 32 | B36: 中沢 侑己 | C36: 佐久長聖高 | D36: 0.010045486 | E36: 33 | H36: 0.0027394676 | I36: 84 | J36: 3区 8位（23:52）
A37: 33 | B37: 薮下 殿傑 | C37: 須磨学園高 | D37: 0.010048264 | E37: 34
A38: 34 | B38: 長 煌介 | C38: 鳥取城北高 | D38: 0.010049421 | E38: 35 | H38: 0.0027449074 | I38: 90 | J38: 3区 9位（23:53）
A39: 35 | B39: 後藤 大晴 | C39: 相洋高 | D39: 0.010049653 | E39: 36 | H39: 0.0027736111 | I39: 171
A40: 36 | B40: 中川 悠晴 | C40: 富山商高 | D40: 0.010054977 | E40: 37 | H40: 0.0027759259 | I40: 182
A41: 37 | B41: 向岩 玖恩 | C41: 敦賀気比高 | D41: 0.010054977 | E41: 38 | H41: 0.0027175926 | I41: 46
...

Sheet 注目選手
A1: 注目選手（25人・5000m順）
A2: 選手一覧でオレンジにした選手。記録・駅伝・メモは「選手一覧」から数式で参照（メモは選手一覧のメモ列に記入）。注目選手を増減するときは、どのシートでも行をオレンジ（FFC000）にして返してください。
A4: No | B4: 氏名 | C4: 高校 | D4: 5000m 記録 | E4: 5000m 順位 | F4: 3000mSC 記録 | G4: 3000mSC 順位 | H4: 1500m 記録 | I4: 1500m 順位 | J4: 日本海駅伝 （区・区間順位） | K4: 奥球磨駅伝 （区・区間順位） | L4: 備考 | M4: メモ
A5: 6 | B5: =IF(INDEX(選手一覧!$B$5:$B$2736,$A5)="","",INDEX(選手一覧!$B$5:$B$2736,$A5)) -> 橋本 蒼平 | C5: =IF(INDEX(選手一覧!$C$5:$C$2736,$A5)="","",INDEX(選手一覧!$C$5:$C$2736,$A5)) -> 佐久長聖高 | D5: =IF(INDEX(選手一覧!$D$5:$D$2736,$A5)="","",INDEX(選手一覧!$D$5:$D$2736,$A5)) -> 0.0097591435 | E5: =IF(INDEX(選手一覧!$E$5:$E$2736,$A5)="","",INDEX(選手一覧!$E$5:$E$2736,$A5)) -> 6 | F5: =IF(INDEX(選手一覧!$F$5:$F$2736,$A5)="","",INDEX(選手一覧!$F$5:$F$2736,$A5)) -> 0.0062690972 | G5: =IF(INDEX(選手一覧!$G$5:$G$2736,$A5)="","",INDEX(選手一覧!$G$5:$G$2736,$A5)) -> 2 | H5: =IF(INDEX(選手一覧!$H$5:$H$2736,$A5)="","",INDEX(選手一覧!$H$5:$H$2736,$A5)) -> 0.0027813657 | I5: =IF(INDEX(選手一覧!$I$5:$I$2736,$A5)="","",INDEX(選手一覧!$I$5:$I$2736,$A5)) -> 209 | J5: =IF(INDEX(選手一覧!$J$5:$J$2736,$A5)="","",INDEX(選手一覧!$J$5:$J$2736,$A5)) -> 1区 3位（28:58） | K5: =IF(INDEX(選手一覧!$K$5:$K$2736,$A5)="","",INDEX(選手一覧!$K$5:$K$2736,$A5)) | L5: =IF(INDEX(選手一覧!$L$5:$L$2736,$A5)="","",INDEX(選手一覧!$L$5:$L$2736,$A5)) | M5: =IF(INDEX(選手一覧!$M$5:$M$2736,$A5)="","",INDEX(選手一覧!$M$5:$M$2736,$A5))
A6: 10 | B6: =IF(INDEX(選手一覧!$B$5:$B$2736,$A6)="","",INDEX(選手一覧!$B$5:$B$2736,$A6)) -> 伊藤 遼 | C6: =IF(INDEX(選手一覧!$C$5:$C$2736,$A6)="","",INDEX(選手一覧!$C$5:$C$2736,$A6)) -> 佐久長聖高 | D6: =IF(INDEX(選手一覧!$D$5:$D$2736,$A6)="","",INDEX(選手一覧!$D$5:$D$2736,$A6)) -> 0.0098652778 | E6: =IF(INDEX(選手一覧!$E$5:$E$2736,$A6)="","",INDEX(選手一覧!$E$5:$E$2736,$A6)) -> 10 | F6: =IF(INDEX(選手一覧!$F$5:$F$2736,$A6)="","",INDEX(選手一覧!$F$5:$F$2736,$A6)) | G6: =IF(INDEX(選手一覧!$G$5:$G$2736,$A6)="","",INDEX(選手一覧!$G$5:$G$2736,$A6)) | H6: =IF(INDEX(選手一覧!$H$5:$H$2736,$A6)="","",INDEX(選手一覧!$H$5:$H$2736,$A6)) -> 0.0028207176 | I6: =IF(INDEX(選手一覧!$I$5:$I$2736,$A6)="","",INDEX(選手一覧!$I$5:$I$2736,$A6)) -> 367 | J6: =IF(INDEX(選手一覧!$J$5:$J$2736,$A6)="","",INDEX(選手一覧!$J$5:$J$2736,$A6)) | K6: =IF(INDEX(選手一覧!$K$5:$K$2736,$A6)="","",INDEX(選手一覧!$K$5:$K$2736,$A6)) | L6: =IF(INDEX(選手一覧!$L$5:$L$2736,$A6)="","",INDEX(選手一覧!$L$5:$L$2736,$A6)) | M6: =IF(INDEX(選手一覧!$M$5:$M$2736,$A6)="","",INDEX(選手一覧!$M$5:$M$2736,$A6))
A7: 11 | B7: =IF(INDEX(選手一覧!$B$5:$B$2736,$A7)="","",INDEX(選手一覧!$B$5:$B$2736,$A7)) -> 酒井 琉史 | C7: =IF(INDEX(選手一覧!$C$5:$C$2736,$A7)="","",INDEX(選手一覧!$C$5:$C$2736,$A7)) -> 佐久長聖高 | D7: =IF(INDEX(選手一覧!$D$5:$D$2736,$A7)="","",INDEX(選手一覧!$D$5:$D$2736,$A7)) -> 0.0098707176 | E7: =IF(INDEX(選手一覧!$E$5:$E$2736,$A7)="","",INDEX(選手一覧!$E$5:$E$2736,$A7)) -> 11 | F7: =IF(INDEX(選手一覧!$F$5:$F$2736,$A7)="","",INDEX(選手一覧!$F$5:$F$2736,$A7)) | G7: =IF(INDEX(選手一覧!$G$5:$G$2736,$A7)="","",INDEX(選手一覧!$G$5:$G$2736,$A7)) | H7: =IF(INDEX(選手一覧!$H$5:$H$2736,$A7)="","",INDEX(選手一覧!$H$5:$H$2736,$A7)) -> 0.0027590278 | I7: =IF(INDEX(選手一覧!$I$5:$I$2736,$A7)="","",INDEX(選手一覧!$I$5:$I$2736,$A7)) -> 132 | J7: =IF(INDEX(選手一覧!$J$5:$J$2736,$A7)="","",INDEX(選手一覧!$J$5:$J$2736,$A7)) -> 1区 7位（29:06） | K7: =IF(INDEX(選手一覧!$K$5:$K$2736,$A7)="","",INDEX(選手一覧!$K$5:$K$2736,$A7)) | L7: =IF(INDEX(選手一覧!$L$5:$L$2736,$A7)="","",INDEX(選手一覧!$L$5:$L$2736,$A7)) | M7: =IF(INDEX(選手一覧!$M$5:$M$2736,$A7)="","",INDEX(選手一覧!$M$5:$M$2736,$A7))
A8: 14 | B8: =IF(INDEX(選手一覧!$B$5:$B$2736,$A8)="","",INDEX(選手一覧!$B$5:$B$2736,$A8)) -> 竹田 櫂司 | C8: =IF(INDEX(選手一覧!$C$5:$C$2736,$A8)="","",INDEX(選手一覧!$C$5:$C$2736,$A8)) -> 小林高 | D8: =IF(INDEX(選手一覧!$D$5:$D$2736,$A8)="","",INDEX(選手一覧!$D$5:$D$2736,$A8)) -> 0.0099078704 | E8: =IF(INDEX(選手一覧!$E$5:$E$2736,$A8)="","",INDEX(選手一覧!$E$5:$E$2736,$A8)) -> 15 | F8: =IF(INDEX(選手一覧!$F$5:$F$2736,$A8)="","",INDEX(選手一覧!$F$5:$F$2736,$A8)) | G8: =IF(INDEX(選手一覧!$G$5:$G$2736,$A8)="","",INDEX(選手一覧!$G$5:$G$2736,$A8)) | H8: =IF(INDEX(選手一覧!$H$5:$H$2736,$A8)="","",INDEX(選手一覧!$H$5:$H$2736,$A8)) -> 0.0028393519 | I8: =IF(INDEX(選手一覧!$I$5:$I$2736,$A8)="","",INDEX(選手一覧!$I$5:$I$2736,$A8)) -> 491 | J8: =IF(INDEX(選手一覧!$J$5:$J$2736,$A8)="","",INDEX(選手一覧!$J$5:$J$2736,$A8)) | K8: =IF(INDEX(選手一覧!$K$5:$K$2736,$A8)="","",INDEX(選手一覧!$K$5:$K$2736,$A8)) -> 3区 3位（23:54） | L8: =IF(INDEX(選手一覧!$L$5:$L$2736,$A8)="","",INDEX(選手一覧!$L$5:$L$2736,$A8)) | M8: =IF(INDEX(選手一覧!$M$5:$M$2736,$A8)="","",INDEX(選手一覧!$M$5:$M$2736,$A8))
A9: 16 | B9: =IF(INDEX(選手一覧!$B$5:$B$2736,$A9)="","",INDEX(選手一覧!$B$5:$B$2736,$A9)) -> 上杉 創亮 | C9: =IF(INDEX(選手一覧!$C$5:$C$2736,$A9)="","",INDEX(選手一覧!$C$5:$C$2736,$A9)) -> 八千代松陰高 | D9: =IF(INDEX(選手一覧!$D$5:$D$2736,$A9)="","",INDEX(選手一覧!$D$5:$D$2736,$A9)) -> 0.0099413194 | E9: =IF(INDEX(選手一覧!$E$5:$E$2736,$A9)="","",INDEX(選手一覧!$E$5:$E$2736,$A9)) -> 17 | F9: =IF(INDEX(選手一覧!$F$5:$F$2736,$A9)="","",INDEX(選手一覧!$F$5:$F$2736,$A9)) | G9: =IF(INDEX(選手一覧!$G$5:$G$2736,$A9)="","",INDEX(選手一覧!$G$5:$G$2736,$A9)) | H9: =IF(INDEX(選手一覧!$H$5:$H$2736,$A9)="","",INDEX(選手一覧!$H$5:$H$2736,$A9)) -> 0.0028630787 | I9: =IF(INDEX(選手一覧!$I$5:$I$2736,$A9)="","",INDEX(選手一覧!$I$5:$I$2736,$A9)) -> 656 | J9: =IF(INDEX(選手一覧!$J$5:$J$2736,$A9)="","",INDEX(選手一覧!$J$5:$J$2736,$A9)) | K9: =IF(INDEX(選手一覧!$K$5:$K$2736,$A9)="","",INDEX(選手一覧!$K$5:$K$2736,$A9)) | L9: =IF(INDEX(選手一覧!$L$5:$L$2736,$A9)="","",INDEX(選手一覧!$L$5:$L$2736,$A9)) | M9: =IF(INDEX(選手一覧!$M$5:$M$2736,$A9)="","",INDEX(選手一覧!$M$5:$M$2736,$A9))
A10: 18 | B10: =IF(INDEX(選手一覧!$B$5:$B$2736,$A10)="","",INDEX(選手一覧!$B$5:$B$2736,$A10)) -> 山田 莉生 | C10: =IF(INDEX(選手一覧!$C$5:$C$2736,$A10)="","",INDEX(選手一覧!$C$5:$C$2736,$A10)) -> 拓大一高 | D10: =IF(INDEX(選手一覧!$D$5:$D$2736,$A10)="","",INDEX(選手一覧!$D$5:$D$2736,$A10)) -> 0.0099721065 | E10: =IF(INDEX(選手一覧!$E$5:$E$2736,$A10)="","",INDEX(選手一覧!$E$5:$E$2736,$A10)) -> 19 | F10: =IF(INDEX(選手一覧!$F$5:$F$2736,$A10)="","",INDEX(選手一覧!$F$5:$F$2736,$A10)) | G10: =IF(INDEX(選手一覧!$G$5:$G$2736,$A10)="","",INDEX(選手一覧!$G$5:$G$2736,$A10)) | H10: =IF(INDEX(選手一覧!$H$5:$H$2736,$A10)="","",INDEX(選手一覧!$H$5:$H$2736,$A10)) -> 0.0027325231 | I10: =IF(INDEX(選手一覧!$I$5:$I$2736,$A10)="","",INDEX(選手一覧!$I$5:$I$2736,$A10)) -> 70 | J10: =IF(INDEX(選手一覧!$J$5:$J$2736,$A10)="","",INDEX(選手一覧!$J$5:$J$2736,$A10)) | K10: =IF(INDEX(選手一覧!$K$5:$K$2736,$A10)="","",INDEX(選手一覧!$K$5:$K$2736,$A10)) | L10: =IF(INDEX(選手一覧!$L$5:$L$2736,$A10)="","",INDEX(選手一覧!$L$5:$L$2736,$A10)) | M10: =IF(INDEX(選手一覧!$M$5:$M$2736,$A10)="","",INDEX(選手一覧!$M$5:$M$2736,$A10))
A11: 21 | B11: =IF(INDEX(選手一覧!$B$5:$B$2736,$A11)="","",INDEX(選手一覧!$B$5:$B$2736,$A11)) -> 高田 康介 | C11: =IF(INDEX(選手一覧!$C$5:$C$2736,$A11)="","",INDEX(選手一覧!$C$5:$C$2736,$A11)) -> 東海大附相模高 | D11: =IF(INDEX(選手一覧!$D$5:$D$2736,$A11)="","",INDEX(選手一覧!$D$5:$D$2736,$A11)) -> 0.010002431 | E11: =IF(INDEX(選手一覧!$E$5:$E$2736,$A11)="","",INDEX(選手一覧!$E$5:$E$2736,$A11)) -> 22 | F11: =IF(INDEX(選手一覧!$F$5:$F$2736,$A11)="","",INDEX(選手一覧!$F$5:$F$2736,$A11)) | G11: =IF(INDEX(選手一覧!$G$5:$G$2736,$A11)="","",INDEX(選手一覧!$G$5:$G$2736,$A11)) | H11: =IF(INDEX(選手一覧!$H$5:$H$2736,$A11)="","",INDEX(選手一覧!$H$5:$H$2736,$A11)) -> 0.0029390046 | I11: =IF(INDEX(選手一覧!$I$5:$I$2736,$A11)="","",INDEX(選手一覧!$I$5:$I$2736,$A11)) -> 1197 | J11: =IF(INDEX(選手一覧!$J$5:$J$2736,$A11)="","",INDEX(選手一覧!$J$5:$J$2736,$A11)) | K11: =IF(INDEX(選手一覧!$K$5:$K$2736,$A11)="","",INDEX(選手一覧!$K$5:$K$2736,$A11)) | L11: =IF(INDEX(選手一覧!$L$5:$L$2736,$A11)="","",INDEX(選手一覧!$L$5:$L$2736,$A11)) | M11: =IF(INDEX(選手一覧!$M$5:$M$2736,$A11)="","",INDEX(選手一覧!$M$5:$M$2736,$A11))
A12: 27 | B12: =IF(INDEX(選手一覧!$B$5:$B$2736,$A12)="","",INDEX(選手一覧!$B$5:$B$2736,$A12)) -> 小田 桜雅 | C12: =IF(INDEX(選手一覧!$C$5:$C$2736,$A12)="","",INDEX(選手一覧!$C$5:$C$2736,$A12)) -> 仙台育英学園高 | D12: =IF(INDEX(選手一覧!$D$5:$D$2736,$A12)="","",INDEX(選手一覧!$D$5:$D$2736,$A12)) -> 0.010033102 | E12: =IF(INDEX(選手一覧!$E$5:$E$2736,$A12)="","",INDEX(選手一覧!$E$5:$E$2736,$A12)) -> 28 | F12: =IF(INDEX(選手一覧!$F$5:$F$2736,$A12)="","",INDEX(選手一覧!$F$5:$F$2736,$A12)) | G12: =IF(INDEX(選手一覧!$G$5:$G$2736,$A12)="","",INDEX(選手一覧!$G$5:$G$2736,$A12)) | H12: =IF(INDEX(選手一覧!$H$5:$H$2736,$A12)="","",INDEX(選手一覧!$H$5:$H$2736,$A12)) -> 0.0027190972 | I12: =IF(INDEX(選手一覧!$I$5:$I$2736,$A12)="","",INDEX(選手一覧!$I$5:$I$2736,$A12)) -> 48 | J12: =IF(INDEX(選手一覧!$J$5:$J$2736,$A12)="","",INDEX(選手一覧!$J$5:$J$2736,$A12)) | K12: =IF(INDEX(選手一覧!$K$5:$K$2736,$A12)="","",INDEX(選手一覧!$K$5:$K$2736,$A12)) | L12: =IF(INDEX(選手一覧!$L$5:$L$2736,$A12)="","",INDEX(選手一覧!$L$5:$L$2736,$A12)) | M12: =IF(INDEX(選手一覧!$M$5:$M$2736,$A12)="","",INDEX(選手一覧!$M$5:$M$2736,$A12))
A13: 30 | B13: =IF(INDEX(選手一覧!$B$5:$B$2736,$A13)="","",INDEX(選手一覧!$B$5:$B$2736,$A13)) -> 小林 柾輝 | C13: =IF(INDEX(選手一覧!$C$5:$C$2736,$A13)="","",INDEX(選手一覧!$C$5:$C$2736,$A13)) -> 八千代松陰高 | D13: =IF(INDEX(選手一覧!$D$5:$D$2736,$A13)="","",INDEX(選手一覧!$D$5:$D$2736,$A13)) -> 0.010042245 | E13: =IF(INDEX(選手一覧!$E$5:$E$2736,$A13)="","",INDEX(選手一覧!$E$5:$E$2736,$A13)) -> 31 | F13: =IF(INDEX(選手一覧!$F$5:$F$2736,$A13)="","",INDEX(選手一覧!$F$5:$F$2736,$A13)) | G13: =IF(INDEX(選手一覧!$G$5:$G$2736,$A13)="","",INDEX(選手一覧!$G$5:$G$2736,$A13)) | H13: =IF(INDEX(選手一覧!$H$5:$H$2736,$A13)="","",INDEX(選手一覧!$H$5:$H$2736,$A13)) | I13: =IF(INDEX(選手一覧!$I$5:$I$2736,$A13)="","",INDEX(選手一覧!$I$5:$I$2736,$A13)) | J13: =IF(INDEX(選手一覧!$J$5:$J$2736,$A13)="","",INDEX(選手一覧!$J$5:$J$2736,$A13)) | K13: =IF(INDEX(選手一覧!$K$5:$K$2736,$A13)="","",INDEX(選手一覧!$K$5:$K$2736,$A13)) | L13: =IF(INDEX(選手一覧!$L$5:$L$2736,$A13)="","",INDEX(選手一覧!$L$5:$L$2736,$A13)) | M13: =IF(INDEX(選手一覧!$M$5:$M$2736,$A13)="","",INDEX(選手一覧!$M$5:$M$2736,$A13))
A14: 31 | B14: =IF(INDEX(選手一覧!$B$5:$B$2736,$A14)="","",INDEX(選手一覧!$B$5:$B$2736,$A14)) -> 長尾 羚煌 | C14: =IF(INDEX(選手一覧!$C$5:$C$2736,$A14)="","",INDEX(選手一覧!$C$5:$C$2736,$A14)) -> 市長崎商高 | D14: =IF(INDEX(選手一覧!$D$5:$D$2736,$A14)="","",INDEX(選手一覧!$D$5:$D$2736,$A14)) -> 0.010043056 | E14: =IF(INDEX(選手一覧!$E$5:$E$2736,$A14)="","",INDEX(選手一覧!$E$5:$E$2736,$A14)) -> 32 | F14: =IF(INDEX(選手一覧!$F$5:$F$2736,$A14)="","",INDEX(選手一覧!$F$5:$F$2736,$A14)) | G14: =IF(INDEX(選手一覧!$G$5:$G$2736,$A14)="","",INDEX(選手一覧!$G$5:$G$2736,$A14)) | H14: =IF(INDEX(選手一覧!$H$5:$H$2736,$A14)="","",INDEX(選手一覧!$H$5:$H$2736,$A14)) -> 0.0027251157 | I14: =IF(INDEX(選手一覧!$I$5:$I$2736,$A14)="","",INDEX(選手一覧!$I$5:$I$2736,$A14)) -> 58 | J14: =IF(INDEX(選手一覧!$J$5:$J$2736,$A14)="","",INDEX(選手一覧!$J$5:$J$2736,$A14)) | K14: =IF(INDEX(選手一覧!$K$5:$K$2736,$A14)="","",INDEX(選手一覧!$K$5:$K$2736,$A14)) | L14: =IF(INDEX(選手一覧!$L$5:$L$2736,$A14)="","",INDEX(選手一覧!$L$5:$L$2736,$A14)) | M14: =IF(INDEX(選手一覧!$M$5:$M$2736,$A14)="","",INDEX(選手一覧!$M$5:$M$2736,$A14))
A15: 32 | B15: =IF(INDEX(選手一覧!$B$5:$B$2736,$A15)="","",INDEX(選手一覧!$B$5:$B$2736,$A15)) -> 中沢 侑己 | C15: =IF(INDEX(選手一覧!$C$5:$C$2736,$A15)="","",INDEX(選手一覧!$C$5:$C$2736,$A15)) -> 佐久長聖高 | D15: =IF(INDEX(選手一覧!$D$5:$D$2736,$A15)="","",INDEX(選手一覧!$D$5:$D$2736,$A15)) -> 0.010045486 | E15: =IF(INDEX(選手一覧!$E$5:$E$2736,$A15)="","",INDEX(選手一覧!$E$5:$E$2736,$A15)) -> 33 | F15: =IF(INDEX(選手一覧!$F$5:$F$2736,$A15)="","",INDEX(選手一覧!$F$5:$F$2736,$A15)) | G15: =IF(INDEX(選手一覧!$G$5:$G$2736,$A15)="","",INDEX(選手一覧!$G$5:$G$2736,$A15)) | H15: =IF(INDEX(選手一覧!$H$5:$H$2736,$A15)="","",INDEX(選手一覧!$H$5:$H$2736,$A15)) -> 0.0027394676 | I15: =IF(INDEX(選手一覧!$I$5:$I$2736,$A15)="","",INDEX(選手一覧!$I$5:$I$2736,$A15)) -> 84 | J15: =IF(INDEX(選手一覧!$J$5:$J$2736,$A15)="","",INDEX(選手一覧!$J$5:$J$2736,$A15)) -> 3区 8位（23:52） | K15: =IF(INDEX(選手一覧!$K$5:$K$2736,$A15)="","",INDEX(選手一覧!$K$5:$K$2736,$A15)) | L15: =IF(INDEX(選手一覧!$L$5:$L$2736,$A15)="","",INDEX(選手一覧!$L$5:$L$2736,$A15)) | M15: =IF(INDEX(選手一覧!$M$5:$M$2736,$A15)="","",INDEX(選手一覧!$M$5:$M$2736,$A15))
A16: 34 | B16: =IF(INDEX(選手一覧!$B$5:$B$2736,$A16)="","",INDEX(選手一覧!$B$5:$B$2736,$A16)) -> 長 煌介 | C16: =IF(INDEX(選手一覧!$C$5:$C$2736,$A16)="","",INDEX(選手一覧!$C$5:$C$2736,$A16)) -> 鳥取城北高 | D16: =IF(INDEX(選手一覧!$D$5:$D$2736,$A16)="","",INDEX(選手一覧!$D$5:$D$2736,$A16)) -> 0.010049421 | E16: =IF(INDEX(選手一覧!$E$5:$E$2736,$A16)="","",INDEX(選手一覧!$E$5:$E$2736,$A16)) -> 35 | F16: =IF(INDEX(選手一覧!$F$5:$F$2736,$A16)="","",INDEX(選手一覧!$F$5:$F$2736,$A16)) | G16: =IF(INDEX(選手一覧!$G$5:$G$2736,$A16)="","",INDEX(選手一覧!$G$5:$G$2736,$A16)) | H16: =IF(INDEX(選手一覧!$H$5:$H$2736,$A16)="","",INDEX(選手一覧!$H$5:$H$2736,$A16)) -> 0.0027449074 | I16: =IF(INDEX(選手一覧!$I$5:$I$2736,$A16)="","",INDEX(選手一覧!$I$5:$I$2736,$A16)) -> 90 | J16: =IF(INDEX(選手一覧!$J$5:$J$2736,$A16)="","",INDEX(選手一覧!$J$5:$J$2736,$A16)) -> 3区 9位（23:53） | K16: =IF(INDEX(選手一覧!$K$5:$K$2736,$A16)="","",INDEX(選手一覧!$K$5:$K$2736,$A16)) | L16: =IF(INDEX(選手一覧!$L$5:$L$2736,$A16)="","",INDEX(選手一覧!$L$5:$L$2736,$A16)) | M16: =IF(INDEX(選手一覧!$M$5:$M$2736,$A16)="","",INDEX(選手一覧!$M$5:$M$2736,$A16))
... A29: 205 | B29: =IF(INDEX(選手一覧!$B$5:$B$2736,$A29)="","",INDEX(選手一覧!$B$5:$B$2736,$A29)) -> 渡辺 志 | C29: =IF(INDEX(選手一覧!$C$5:$C$2736,$A29)="","",INDEX(選手一覧!$C$5:$C$2736,$A29)) -> 自由ケ丘高 | D29: =IF(INDEX(選手一覧!$D$5:$D$2736,$A29)="","",INDEX(選手一覧!$D$5:$D$2736,$A29)) -> 0.01035162 | E29: =IF(INDEX(選手一覧!$E$5:$E$2736,$A29)="","",INDEX(選手一覧!$E$5:$E$2736,$A29)) -> 206 | F29: =IF(INDEX(選手一覧!$F$5:$F$2736,$A29)="","",INDEX(選手一覧!$F$5:$F$2736,$A29)) | G29: =IF(INDEX(選手一覧!$G$5:$G$2736,$A29)="","",INDEX(選手一覧!$G$5:$G$2736,$A29)) | H29: =IF(INDEX(選手一覧!$H$5:$H$2736,$A29)="","",INDEX(選手一覧!$H$5:$H$2736,$A29)) -> 0.0028215278 | I29: =IF(INDEX(選手一覧!$I$5:$I$2736,$A29)="","",INDEX(選手一覧!$I$5:$I$2736,$A29)) -> 372 | J29: =IF(INDEX(選手一覧!$J$5:$J$2736,$A29)="","",INDEX(選手一覧!$J$5:$J$2736,$A29)) | K29: =IF(INDEX(選手一覧!$K$5:$K$2736,$A29)="","",INDEX(選手一覧!$K$5:$K$2736,$A29)) -> 3区 7位（24:25） | L29: =IF(INDEX(選手一覧!$L$5:$L$2736,$A29)="","",INDEX(選手一覧!$L$5:$L$2736,$A29)) | M29: =IF(INDEX(選手一覧!$M$5:$M$2736,$A29)="","",INDEX(選手一覧!$M$5:$M$2736,$A29))

Sheet 日本海駅伝
A1: 第46回 日本海駅伝（2026/10/4）：2028年入学世代（現高2）の区間成績
A2: 全出走者のうち、陸マガランキングに名前と高校が一致する選手のみ掲載（成績表に学年の記載がないため）。ランキング圏外の2年生は含まれません。区間順位は全学年での順位、2年生内順位はこの表の中での順位。区間順位の色：濃い緑＝3位以内、緑＝10位以内、薄緑＝30位以内。
A4: 区 | B4: 距離 (km) | C4: 区間 順位 | D4: 2年生内 順位 | E4: 区間記録 | F4: 1km ペース | G4: 氏名 | H4: チーム | I4: 都道府県 | J4: チーム 総合順位 | K4: No | L4: 5000m 記録 | M4: 5000m 順位 | N4: 3000mSC 記録 | O4: 3000mSC 順位 | P4: 1500m 記録 | Q4: 1500m 順位
A5: 1 | B5: 10 | C5: 2 | D5: =COUNTIFS($A$5:$A$229,A5,$E$5:$E$229,"<"&E5)+1 -> 1 | E5: 0.020069444 | F5: =E5/B5 -> 0.0020069444 | G5: 稲垣 翔馴 | H5: 洛南A | I5: 京都 | J5: 2 | K5: 2 | L5: =IF(INDEX(選手一覧!$D$5:$D$2736,$K5)="","",INDEX(選手一覧!$D$5:$D$2736,$K5)) -> 0.0096434028 | M5: =IF(INDEX(選手一覧!$E$5:$E$2736,$K5)="","",INDEX(選手一覧!$E$5:$E$2736,$K5)) -> 2 | N5: =IF(INDEX(選手一覧!$F$5:$F$2736,$K5)="","",INDEX(選手一覧!$F$5:$F$2736,$K5)) -> 0.0064204861 | O5: =IF(INDEX(選手一覧!$G$5:$G$2736,$K5)="","",INDEX(選手一覧!$G$5:$G$2736,$K5)) -> 19 | P5: =IF(INDEX(選手一覧!$H$5:$H$2736,$K5)="","",INDEX(選手一覧!$H$5:$H$2736,$K5)) -> 0.0026045139 | Q5: =IF(INDEX(選手一覧!$I$5:$I$2736,$K5)="","",INDEX(選手一覧!$I$5:$I$2736,$K5)) -> 1
A6: 1 | B6: 10 | C6: 3 | D6: =COUNTIFS($A$5:$A$229,A6,$E$5:$E$229,"<"&E6)+1 -> 2 | E6: 0.020115741 | F6: =E6/B6 -> 0.0020115741 | G6: 橋本 蒼平 | H6: 佐久長聖B | I6: 長野 | J6: 3 | K6: 6 | L6: =IF(INDEX(選手一覧!$D$5:$D$2736,$K6)="","",INDEX(選手一覧!$D$5:$D$2736,$K6)) -> 0.0097591435 | M6: =IF(INDEX(選手一覧!$E$5:$E$2736,$K6)="","",INDEX(選手一覧!$E$5:$E$2736,$K6)) -> 6 | N6: =IF(INDEX(選手一覧!$F$5:$F$2736,$K6)="","",INDEX(選手一覧!$F$5:$F$2736,$K6)) -> 0.0062690972 | O6: =IF(INDEX(選手一覧!$G$5:$G$2736,$K6)="","",INDEX(選手一覧!$G$5:$G$2736,$K6)) -> 2 | P6: =IF(INDEX(選手一覧!$H$5:$H$2736,$K6)="","",INDEX(選手一覧!$H$5:$H$2736,$K6)) -> 0.0027813657 | Q6: =IF(INDEX(選手一覧!$I$5:$I$2736,$K6)="","",INDEX(選手一覧!$I$5:$I$2736,$K6)) -> 209
A7: 1 | B7: 10 | C7: 7 | D7: =COUNTIFS($A$5:$A$229,A7,$E$5:$E$229,"<"&E7)+1 -> 3 | E7: 0.020208333 | F7: =E7/B7 -> 0.0020208333 | G7: 酒井 琉史 | H7: 佐久長聖A | I7: 長野 | J7: 1 | K7: 11 | L7: =IF(INDEX(選手一覧!$D$5:$D$2736,$K7)="","",INDEX(選手一覧!$D$5:$D$2736,$K7)) -> 0.0098707176 | M7: =IF(INDEX(選手一覧!$E$5:$E$2736,$K7)="","",INDEX(選手一覧!$E$5:$E$2736,$K7)) -> 11 | N7: =IF(INDEX(選手一覧!$F$5:$F$2736,$K7)="","",INDEX(選手一覧!$F$5:$F$2736,$K7)) | O7: =IF(INDEX(選手一覧!$G$5:$G$2736,$K7)="","",INDEX(選手一覧!$G$5:$G$2736,$K7)) | P7: =IF(INDEX(選手一覧!$H$5:$H$2736,$K7)="","",INDEX(選手一覧!$H$5:$H$2736,$K7)) -> 0.0027590278 | Q7: =IF(INDEX(選手一覧!$I$5:$I$2736,$K7)="","",INDEX(選手一覧!$I$5:$I$2736,$K7)) -> 132
A8: 1 | B8: 10 | C8: 12 | D8: =COUNTIFS($A$5:$A$229,A8,$E$5:$E$229,"<"&E8)+1 -> 4 | E8: 0.020428241 | F8: =E8/B8 -> 0.0020428241 | G8: 平田 千隼 | H8: 鳥取城北B | I8: 鳥取 | J8: 11 | K8: 43 | L8: =IF(INDEX(選手一覧!$D$5:$D$2736,$K8)="","",INDEX(選手一覧!$D$5:$D$2736,$K8)) -> 0.010080787 | M8: =IF(INDEX(選手一覧!$E$5:$E$2736,$K8)="","",INDEX(選手一覧!$E$5:$E$2736,$K8)) -> 44 | N8: =IF(INDEX(選手一覧!$F$5:$F$2736,$K8)="","",INDEX(選手一覧!$F$5:$F$2736,$K8)) | O8: =IF(INDEX(選手一覧!$G$5:$G$2736,$K8)="","",INDEX(選手一覧!$G$5:$G$2736,$K8)) | P8: =IF(INDEX(選手一覧!$H$5:$H$2736,$K8)="","",INDEX(選手一覧!$H$5:$H$2736,$K8)) -> 0.0028560185 | Q8: =IF(INDEX(選手一覧!$I$5:$I$2736,$K8)="","",INDEX(選手一覧!$I$5:$I$2736,$K8)) -> 608
A9: 1 | B9: 10 | C9: 13 | D9: =COUNTIFS($A$5:$A$229,A9,$E$5:$E$229,"<"&E9)+1 -> 5 | E9: 0.020439815 | F9: =E9/B9 -> 0.0020439815 | G9: 岸本 周真 | H9: 西脇工A | I9: 兵庫 | J9: 6 | K9: 53 | L9: =IF(INDEX(選手一覧!$D$5:$D$2736,$K9)="","",INDEX(選手一覧!$D$5:$D$2736,$K9)) -> 0.010106134 | M9: =IF(INDEX(選手一覧!$E$5:$E$2736,$K9)="","",INDEX(選手一覧!$E$5:$E$2736,$K9)) -> 54 | N9: =IF(INDEX(選手一覧!$F$5:$F$2736,$K9)="","",INDEX(選手一覧!$F$5:$F$2736,$K9)) | O9: =IF(INDEX(選手一覧!$G$5:$G$2736,$K9)="","",INDEX(選手一覧!$G$5:$G$2736,$K9)) | P9: =IF(INDEX(選手一覧!$H$5:$H$2736,$K9)="","",INDEX(選手一覧!$H$5:$H$2736,$K9)) -> 0.0027699074 | Q9: =IF(INDEX(選手一覧!$I$5:$I$2736,$K9)="","",INDEX(選手一覧!$I$5:$I$2736,$K9)) -> 161
A10: 1 | B10: 10 | C10: 18 | D10: =COUNTIFS($A$5:$A$229,A10,$E$5:$E$229,"<"&E10)+1 -> 6 | E10: 0.020578704 | F10: =E10/B10 -> 0.0020578704 | G10: 千葉 渚斗 | H10: 広島国際学院 | I10: 広島 | J10: 37 | K10: 168 | L10: =IF(INDEX(選手一覧!$D$5:$D$2736,$K10)="","",INDEX(選手一覧!$D$5:$D$2736,$K10)) -> 0.010316435 | M10: =IF(INDEX(選手一覧!$E$5:$E$2736,$K10)="","",INDEX(選手一覧!$E$5:$E$2736,$K10)) -> 169 | N10: =IF(INDEX(選手一覧!$F$5:$F$2736,$K10)="","",INDEX(選手一覧!$F$5:$F$2736,$K10)) | O10: =IF(INDEX(選手一覧!$G$5:$G$2736,$K10)="","",INDEX(選手一覧!$G$5:$G$2736,$K10)) | P10: =IF(INDEX(選手一覧!$H$5:$H$2736,$K10)="","",INDEX(選手一覧!$H$5:$H$2736,$K10)) -> 0.0028357639 | Q10: =IF(INDEX(選手一覧!$I$5:$I$2736,$K10)="","",INDEX(選手一覧!$I$5:$I$2736,$K10)) -> 468
A11: 1 | B11: 10 | C11: 20 | D11: =COUNTIFS($A$5:$A$229,A11,$E$5:$E$229,"<"&E11)+1 -> 7 | E11: 0.020659722 | F11: =E11/B11 -> 0.0020659722 | G11: 坂口 太弥 | H11: 和歌山北 | I11: 和歌山 | J11: 10 | K11: 114 | L11: =IF(INDEX(選手一覧!$D$5:$D$2736,$K11)="","",INDEX(選手一覧!$D$5:$D$2736,$K11)) -> 0.01023588 | M11: =IF(INDEX(選手一覧!$E$5:$E$2736,$K11)="","",INDEX(選手一覧!$E$5:$E$2736,$K11)) -> 115 | N11: =IF(INDEX(選手一覧!$F$5:$F$2736,$K11)="","",INDEX(選手一覧!$F$5:$F$2736,$K11)) | O11: =IF(INDEX(選手一覧!$G$5:$G$2736,$K11)="","",INDEX(選手一覧!$G$5:$G$2736,$K11)) | P11: =IF(INDEX(選手一覧!$H$5:$H$2736,$K11)="","",INDEX(選手一覧!$H$5:$H$2736,$K11)) -> 0.0029318287 | Q11: =IF(INDEX(選手一覧!$I$5:$I$2736,$K11)="","",INDEX(選手一覧!$I$5:$I$2736,$K11)) -> 1177
A12: 1 | B12: 10 | C12: 22 | D12: =COUNTIFS($A$5:$A$229,A12,$E$5:$E$229,"<"&E12)+1 -> 8 | E12: 0.02068287 | F12: =E12/B12 -> 0.002068287 | G12: 朝倉 悠羽 | H12: 山梨学院 | I12: 山梨 | J12: 8 | K12: 13 | L12: =IF(INDEX(選手一覧!$D$5:$D$2736,$K12)="","",INDEX(選手一覧!$D$5:$D$2736,$K12)) -> 0.0099006944 | M12: =IF(INDEX(選手一覧!$E$5:$E$2736,$K12)="","",INDEX(選手一覧!$E$5:$E$2736,$K12)) -> 14 | N12: =IF(INDEX(選手一覧!$F$5:$F$2736,$K12)="","",INDEX(選手一覧!$F$5:$F$2736,$K12)) | O12: =IF(INDEX(選手一覧!$G$5:$G$2736,$K12)="","",INDEX(選手一覧!$G$5:$G$2736,$K12)) | P12: =IF(INDEX(選手一覧!$H$5:$H$2736,$K12)="","",INDEX(選手一覧!$H$5:$H$2736,$K12)) -> 0.0026894676 | Q12: =IF(INDEX(選手一覧!$I$5:$I$2736,$K12)="","",INDEX(選手一覧!$I$5:$I$2736,$K12)) -> 18
A13: 1 | B13: 10 | C13: 26 | D13: =COUNTIFS($A$5:$A$229,A13,$E$5:$E$229,"<"&E13)+1 -> 9 | E13: 0.020717593 | F13: =E13/B13 -> 0.0020717593 | G13: 木村 剛士 | H13: 美濃加茂 | I13: 岐阜 | J13: 38 | K13: 110 | L13: =IF(INDEX(選手一覧!$D$5:$D$2736,$K13)="","",INDEX(選手一覧!$D$5:$D$2736,$K13)) -> 0.010229167 | M13: =IF(INDEX(選手一覧!$E$5:$E$2736,$K13)="","",INDEX(選手一覧!$E$5:$E$2736,$K13)) -> 111 | N13: =IF(INDEX(選手一覧!$F$5:$F$2736,$K13)="","",INDEX(選手一覧!$F$5:$F$2736,$K13)) | O13: =IF(INDEX(選手一覧!$G$5:$G$2736,$K13)="","",INDEX(選手一覧!$G$5:$G$2736,$K13)) | P13: =IF(INDEX(選手一覧!$H$5:$H$2736,$K13)="","",INDEX(選手一覧!$H$5:$H$2736,$K13)) -> 0.0028164352 | Q13: =IF(INDEX(選手一覧!$I$5:$I$2736,$K13)="","",INDEX(選手一覧!$I$5:$I$2736,$K13)) -> 346
A14: 1 | B14: 10 | C14: 30 | D14: =COUNTIFS($A$5:$A$229,A14,$E$5:$E$229,"<"&E14)+1 -> 10 | E14: 0.020868056 | F14: =E14/B14 -> 0.0020868056 | G14: 前 春馬 | H14: 洛南B | I14: 京都 | J14: 23 | K14: 79 | L14: =IF(INDEX(選手一覧!$D$5:$D$2736,$K14)="","",INDEX(選手一覧!$D$5:$D$2736,$K14)) -> 0.01017338 | M14: =IF(INDEX(選手一覧!$E$5:$E$2736,$K14)="","",INDEX(選手一覧!$E$5:$E$2736,$K14)) -> 80 | N14: =IF(INDEX(選手一覧!$F$5:$F$2736,$K14)="","",INDEX(選手一覧!$F$5:$F$2736,$K14)) | O14: =IF(INDEX(選手一覧!$G$5:$G$2736,$K14)="","",INDEX(選手一覧!$G$5:$G$2736,$K14)) | P14: =IF(INDEX(選手一覧!$H$5:$H$2736,$K14)="","",INDEX(選手一覧!$H$5:$H$2736,$K14)) | Q14: =IF(INDEX(選手一覧!$I$5:$I$2736,$K14)="","",INDEX(選手一覧!$I$5:$I$2736,$K14))
A15: 1 | B15: 10 | C15: 32 | D15: =COUNTIFS($A$5:$A$229,A15,$E$5:$E$229,"<"&E15)+1 -> 11 | E15: 0.020902778 | F15: =E15/B15 -> 0.0020902778 | G15: 楯 冬次 | H15: 愛知 | I15: 愛知 | J15: 29 | K15: 222 | L15: =IF(INDEX(選手一覧!$D$5:$D$2736,$K15)="","",INDEX(選手一覧!$D$5:$D$2736,$K15)) -> 0.01036794 | M15: =IF(INDEX(選手一覧!$E$5:$E$2736,$K15)="","",INDEX(選手一覧!$E$5:$E$2736,$K15)) -> 223 | N15: =IF(INDEX(選手一覧!$F$5:$F$2736,$K15)="","",INDEX(選手一覧!$F$5:$F$2736,$K15)) | O15: =IF(INDEX(選手一覧!$G$5:$G$2736,$K15)="","",INDEX(選手一覧!$G$5:$G$2736,$K15)) | P15: =IF(INDEX(選手一覧!$H$5:$H$2736,$K15)="","",INDEX(選手一覧!$H$5:$H$2736,$K15)) -> 0.0028769676 | Q15: =IF(INDEX(選手一覧!$I$5:$I$2736,$K15)="","",INDEX(選手一覧!$I$5:$I$2736,$K15)) -> 747
A16: 1 | B16: 10 | C16: 33 | D16: =COUNTIFS($A$5:$A$229,A16,$E$5:$E$229,"<"&E16)+1 -> 12 | E16: 0.020925926 | F16: =E16/B16 -> 0.0020925926 | G16: 湯浅 紘翔 | H16: 洛北B | I16: 京都 | J16: 31 | K16: 473 | L16: =IF(INDEX(選手一覧!$D$5:$D$2736,$K16)="","",INDEX(選手一覧!$D$5:$D$2736,$K16)) -> 0.010608681 | M16: =IF(INDEX(選手一覧!$E$5:$E$2736,$K16)="","",INDEX(選手一覧!$E$5:$E$2736,$K16)) -> 474 | N16: =IF(INDEX(選手一覧!$F$5:$F$2736,$K16)="","",INDEX(選手一覧!$F$5:$F$2736,$K16)) -> 0.0069862269 | O16: =IF(INDEX(選手一覧!$G$5:$G$2736,$K16)="","",INDEX(選手一覧!$G$5:$G$2736,$K16)) -> 321 | P16: =IF(INDEX(選手一覧!$H$5:$H$2736,$K16)="","",INDEX(選手一覧!$H$5:$H$2736,$K16)) -> 0.0027975694 | Q16: =IF(INDEX(選手一覧!$I$5:$I$2736,$K16)="","",INDEX(選手一覧!$I$5:$I$2736,$K16)) -> 272
... A229: 7 | B229: 5 | C229: 98 | D229: =COUNTIFS($A$5:$A$229,A229,$E$5:$E$229,"<"&E229)+1 -> 29 | E229: 0.012013889 | F229: =E229/B229 -> 0.0024027778 | G229: 山本 碧 | H229: 出雲工 | I229: 島根 | J229: 93 | K229: 1495 | L229: =IF(INDEX(選手一覧!$D$5:$D$2736,$K229)="","",INDEX(選手一覧!$D$5:$D$2736,$K229)) | M229: =IF(INDEX(選手一覧!$E$5:$E$2736,$K229)="","",INDEX(選手一覧!$E$5:$E$2736,$K229)) | N229: =IF(INDEX(選手一覧!$F$5:$F$2736,$K229)="","",INDEX(選手一覧!$F$5:$F$2736,$K229)) -> 0.0070546296 | O229: =IF(INDEX(選手一覧!$G$5:$G$2736,$K229)="","",INDEX(選手一覧!$G$5:$G$2736,$K229)) -> 395 | P229: =IF(INDEX(選手一覧!$H$5:$H$2736,$K229)="","",INDEX(選手一覧!$H$5:$H$2736,$K229)) | Q229: =IF(INDEX(選手一覧!$I$5:$I$2736,$K229)="","",INDEX(選手一覧!$I$5:$I$2736,$K229))

Sheet 奥球磨駅伝
A1: 第5回 奥球磨駅伝 高校の部（2026/10/4）：2028年入学世代（現高2）の区間成績
A2: 全出走者のうち、陸マガランキングに名前と高校が一致する選手のみ掲載（成績表に学年の記載がないため）。ランキング圏外の2年生は含まれません。区間順位は全学年での順位、2年生内順位はこの表の中での順位。区間順位の色：濃い緑＝3位以内、緑＝10位以内、薄緑＝30位以内。
A4: 区 | B4: 距離 (km) | C4: 区間 順位 | D4: 2年生内 順位 | E4: 区間記録 | F4: 1km ペース | G4: 氏名 | H4: チーム | I4: 都道府県 | J4: チーム 総合順位 | K4: No | L4: 5000m 記録 | M4: 5000m 順位 | N4: 3000mSC 記録 | O4: 3000mSC 順位 | P4: 1500m 記録 | Q4: 1500m 順位
A5: 1 | B5: 10 | C5: 6 | D5: =COUNTIFS($A$5:$A$115,A5,$E$5:$E$115,"<"&E5)+1 -> 1 | E5: 0.02068287 | F5: =E5/B5 -> 0.002068287 | G5: 田尻 清雅 | H5: 慶誠高校 | J5: 16 | K5: 40 | L5: =IF(INDEX(選手一覧!$D$5:$D$2736,$K5)="","",INDEX(選手一覧!$D$5:$D$2736,$K5)) -> 0.010075579 | M5: =IF(INDEX(選手一覧!$E$5:$E$2736,$K5)="","",INDEX(選手一覧!$E$5:$E$2736,$K5)) -> 41 | N5: =IF(INDEX(選手一覧!$F$5:$F$2736,$K5)="","",INDEX(選手一覧!$F$5:$F$2736,$K5)) | O5: =IF(INDEX(選手一覧!$G$5:$G$2736,$K5)="","",INDEX(選手一覧!$G$5:$G$2736,$K5)) | P5: =IF(INDEX(選手一覧!$H$5:$H$2736,$K5)="","",INDEX(選手一覧!$H$5:$H$2736,$K5)) -> 0.0027665509 | Q5: =IF(INDEX(選手一覧!$I$5:$I$2736,$K5)="","",INDEX(選手一覧!$I$5:$I$2736,$K5)) -> 153
A6: 1 | B6: 10 | C6: 7 | D6: =COUNTIFS($A$5:$A$115,A6,$E$5:$E$115,"<"&E6)+1 -> 2 | E6: 0.020717593 | F6: =E6/B6 -> 0.0020717593 | G6: 杉平 颯志 | H6: 鳥栖工業高校A | J6: 4 | K6: 24 | L6: =IF(INDEX(選手一覧!$D$5:$D$2736,$K6)="","",INDEX(選手一覧!$D$5:$D$2736,$K6)) -> 0.010019444 | M6: =IF(INDEX(選手一覧!$E$5:$E$2736,$K6)="","",INDEX(選手一覧!$E$5:$E$2736,$K6)) -> 25 | N6: =IF(INDEX(選手一覧!$F$5:$F$2736,$K6)="","",INDEX(選手一覧!$F$5:$F$2736,$K6)) | O6: =IF(INDEX(選手一覧!$G$5:$G$2736,$K6)="","",INDEX(選手一覧!$G$5:$G$2736,$K6)) | P6: =IF(INDEX(選手一覧!$H$5:$H$2736,$K6)="","",INDEX(選手一覧!$H$5:$H$2736,$K6)) -> 0.0026765046 | Q6: =IF(INDEX(選手一覧!$I$5:$I$2736,$K6)="","",INDEX(選手一覧!$I$5:$I$2736,$K6)) -> 9
A7: 1 | B7: 10 | C7: 12 | D7: =COUNTIFS($A$5:$A$115,A7,$E$5:$E$115,"<"&E7)+1 -> 3 | E7: 0.020960648 | F7: =E7/B7 -> 0.0020960648 | G7: 富永 永輝愛 | H7: 開新高校A | J7: 17 | K7: 51 | L7: =IF(INDEX(選手一覧!$D$5:$D$2736,$K7)="","",INDEX(選手一覧!$D$5:$D$2736,$K7)) -> 0.010100347 | M7: =IF(INDEX(選手一覧!$E$5:$E$2736,$K7)="","",INDEX(選手一覧!$E$5:$E$2736,$K7)) -> 52 | N7: =IF(INDEX(選手一覧!$F$5:$F$2736,$K7)="","",INDEX(選手一覧!$F$5:$F$2736,$K7)) | O7: =IF(INDEX(選手一覧!$G$5:$G$2736,$K7)="","",INDEX(選手一覧!$G$5:$G$2736,$K7)) | P7: =IF(INDEX(選手一覧!$H$5:$H$2736,$K7)="","",INDEX(選手一覧!$H$5:$H$2736,$K7)) -> 0.002712963 | Q7: =IF(INDEX(選手一覧!$I$5:$I$2736,$K7)="","",INDEX(選手一覧!$I$5:$I$2736,$K7)) -> 39
A8: 1 | B8: 10 | C8: 19 | D8: =COUNTIFS($A$5:$A$115,A8,$E$5:$E$115,"<"&E8)+1 -> 4 | E8: 0.021180556 | F8: =E8/B8 -> 0.0021180556 | G8: 大野 晃誠 | H8: 飯塚高校B | J8: 26 | K8: 135 | L8: =IF(INDEX(選手一覧!$D$5:$D$2736,$K8)="","",INDEX(選手一覧!$D$5:$D$2736,$K8)) -> 0.010267824 | M8: =IF(INDEX(選手一覧!$E$5:$E$2736,$K8)="","",INDEX(選手一覧!$E$5:$E$2736,$K8)) -> 136 | N8: =IF(INDEX(選手一覧!$F$5:$F$2736,$K8)="","",INDEX(選手一覧!$F$5:$F$2736,$K8)) | O8: =IF(INDEX(選手一覧!$G$5:$G$2736,$K8)="","",INDEX(選手一覧!$G$5:$G$2736,$K8)) | P8: =IF(INDEX(選手一覧!$H$5:$H$2736,$K8)="","",INDEX(選手一覧!$H$5:$H$2736,$K8)) | Q8: =IF(INDEX(選手一覧!$I$5:$I$2736,$K8)="","",INDEX(選手一覧!$I$5:$I$2736,$K8))
A9: 1 | B9: 10 | C9: 22 | D9: =COUNTIFS($A$5:$A$115,A9,$E$5:$E$115,"<"&E9)+1 -> 5 | E9: 0.021469907 | F9: =E9/B9 -> 0.0021469907 | G9: 河合 琢留 | H9: 豊川高校 | J9: 12 | K9: 230 | L9: =IF(INDEX(選手一覧!$D$5:$D$2736,$K9)="","",INDEX(選手一覧!$D$5:$D$2736,$K9)) -> 0.010375347 | M9: =IF(INDEX(選手一覧!$E$5:$E$2736,$K9)="","",INDEX(選手一覧!$E$5:$E$2736,$K9)) -> 231 | N9: =IF(INDEX(選手一覧!$F$5:$F$2736,$K9)="","",INDEX(選手一覧!$F$5:$F$2736,$K9)) | O9: =IF(INDEX(選手一覧!$G$5:$G$2736,$K9)="","",INDEX(選手一覧!$G$5:$G$2736,$K9)) | P9: =IF(INDEX(選手一覧!$H$5:$H$2736,$K9)="","",INDEX(選手一覧!$H$5:$H$2736,$K9)) -> 0.0027912037 | Q9: =IF(INDEX(選手一覧!$I$5:$I$2736,$K9)="","",INDEX(選手一覧!$I$5:$I$2736,$K9)) -> 246
A10: 1 | B10: 10 | C10: 24 | D10: =COUNTIFS($A$5:$A$115,A10,$E$5:$E$115,"<"&E10)+1 -> 6 | E10: 0.02162037 | F10: =E10/B10 -> 0.002162037 | G10: 松本 優哉 | H10: 西京高校B | J10: 34 | K10: 153 | L10: =IF(INDEX(選手一覧!$D$5:$D$2736,$K10)="","",INDEX(選手一覧!$D$5:$D$2736,$K10)) -> 0.010288542 | M10: =IF(INDEX(選手一覧!$E$5:$E$2736,$K10)="","",INDEX(選手一覧!$E$5:$E$2736,$K10)) -> 154 | N10: =IF(INDEX(選手一覧!$F$5:$F$2736,$K10)="","",INDEX(選手一覧!$F$5:$F$2736,$K10)) | O10: =IF(INDEX(選手一覧!$G$5:$G$2736,$K10)="","",INDEX(選手一覧!$G$5:$G$2736,$K10)) | P10: =IF(INDEX(選手一覧!$H$5:$H$2736,$K10)="","",INDEX(選手一覧!$H$5:$H$2736,$K10)) -> 0.0028069444 | Q10: =IF(INDEX(選手一覧!$I$5:$I$2736,$K10)="","",INDEX(選手一覧!$I$5:$I$2736,$K10)) -> 313
A11: 1 | B11: 10 | C11: 28 | D11: =COUNTIFS($A$5:$A$115,A11,$E$5:$E$115,"<"&E11)+1 -> 7 | E11: 0.021782407 | F11: =E11/B11 -> 0.0021782407 | G11: 今西 爽介 | H11: 小林高校C | J11: 24 | K11: 459 | L11: =IF(INDEX(選手一覧!$D$5:$D$2736,$K11)="","",INDEX(選手一覧!$D$5:$D$2736,$K11)) -> 0.010597222 | M11: =IF(INDEX(選手一覧!$E$5:$E$2736,$K11)="","",INDEX(選手一覧!$E$5:$E$2736,$K11)) -> 460 | N11: =IF(INDEX(選手一覧!$F$5:$F$2736,$K11)="","",INDEX(選手一覧!$F$5:$F$2736,$K11)) | O11: =IF(INDEX(選手一覧!$G$5:$G$2736,$K11)="","",INDEX(選手一覧!$G$5:$G$2736,$K11)) | P11: =IF(INDEX(選手一覧!$H$5:$H$2736,$K11)="","",INDEX(選手一覧!$H$5:$H$2736,$K11)) -> 0.0028568287 | Q11: =IF(INDEX(選手一覧!$I$5:$I$2736,$K11)="","",INDEX(選手一覧!$I$5:$I$2736,$K11)) -> 614
A12: 1 | B12: 10 | C12: 30 | D12: =COUNTIFS($A$5:$A$115,A12,$E$5:$E$115,"<"&E12)+1 -> 8 | E12: 0.021990741 | F12: =E12/B12 -> 0.0021990741 | G12: 森山 心翔 | H12: 鳥栖工業高校C | J12: 20 | K12: 183 | L12: =IF(INDEX(選手一覧!$D$5:$D$2736,$K12)="","",INDEX(選手一覧!$D$5:$D$2736,$K12)) -> 0.01033287 | M12: =IF(INDEX(選手一覧!$E$5:$E$2736,$K12)="","",INDEX(選手一覧!$E$5:$E$2736,$K12)) -> 184 | N12: =IF(INDEX(選手一覧!$F$5:$F$2736,$K12)="","",INDEX(選手一覧!$F$5:$F$2736,$K12)) | O12: =IF(INDEX(選手一覧!$G$5:$G$2736,$K12)="","",INDEX(選手一覧!$G$5:$G$2736,$K12)) | P12: =IF(INDEX(選手一覧!$H$5:$H$2736,$K12)="","",INDEX(選手一覧!$H$5:$H$2736,$K12)) -> 0.0028231481 | Q12: =IF(INDEX(選手一覧!$I$5:$I$2736,$K12)="","",INDEX(選手一覧!$I$5:$I$2736,$K12)) -> 382
A13: 1 | B13: 10 | C13: 31 | D13: =COUNTIFS($A$5:$A$115,A13,$E$5:$E$115,"<"&E13)+1 -> 9 | E13: 0.022002315 | F13: =E13/B13 -> 0.0022002315 | G13: 山口 翔馬 | H13: 鳥取城北高校B | J13: 28 | K13: 355 | L13: =IF(INDEX(選手一覧!$D$5:$D$2736,$K13)="","",INDEX(選手一覧!$D$5:$D$2736,$K13)) -> 0.010514699 | M13: =IF(INDEX(選手一覧!$E$5:$E$2736,$K13)="","",INDEX(選手一覧!$E$5:$E$2736,$K13)) -> 356 | N13: =IF(INDEX(選手一覧!$F$5:$F$2736,$K13)="","",INDEX(選手一覧!$F$5:$F$2736,$K13)) | O13: =IF(INDEX(選手一覧!$G$5:$G$2736,$K13)="","",INDEX(選手一覧!$G$5:$G$2736,$K13)) | P13: =IF(INDEX(選手一覧!$H$5:$H$2736,$K13)="","",INDEX(選手一覧!$H$5:$H$2736,$K13)) | Q13: =IF(INDEX(選手一覧!$I$5:$I$2736,$K13)="","",INDEX(選手一覧!$I$5:$I$2736,$K13))
A14: 1 | B14: 10 | C14: 36 | D14: =COUNTIFS($A$5:$A$115,A14,$E$5:$E$115,"<"&E14)+1 -> 10 | E14: 0.022175926 | F14: =E14/B14 -> 0.0022175926 | G14: 成田 光輝 | H14: 鹿児島高校A | J14: 29 | K14: 236 | L14: =IF(INDEX(選手一覧!$D$5:$D$2736,$K14)="","",INDEX(選手一覧!$D$5:$D$2736,$K14)) -> 0.01037662 | M14: =IF(INDEX(選手一覧!$E$5:$E$2736,$K14)="","",INDEX(選手一覧!$E$5:$E$2736,$K14)) -> 237 | N14: =IF(INDEX(選手一覧!$F$5:$F$2736,$K14)="","",INDEX(選手一覧!$F$5:$F$2736,$K14)) | O14: =IF(INDEX(選手一覧!$G$5:$G$2736,$K14)="","",INDEX(選手一覧!$G$5:$G$2736,$K14)) | P14: =IF(INDEX(選手一覧!$H$5:$H$2736,$K14)="","",INDEX(選手一覧!$H$5:$H$2736,$K14)) -> 0.0027631944 | Q14: =IF(INDEX(選手一覧!$I$5:$I$2736,$K14)="","",INDEX(選手一覧!$I$5:$I$2736,$K14)) -> 143
A15: 1 | B15: 10 | C15: 38 | D15: =COUNTIFS($A$5:$A$115,A15,$E$5:$E$115,"<"&E15)+1 -> 11 | E15: 0.022268519 | F15: =E15/B15 -> 0.0022268519 | G15: 中島 宝良 | H15: 鎮西学院高校B | J15: 33 | K15: 747 | L15: =IF(INDEX(選手一覧!$D$5:$D$2736,$K15)="","",INDEX(選手一覧!$D$5:$D$2736,$K15)) -> 0.010802546 | M15: =IF(INDEX(選手一覧!$E$5:$E$2736,$K15)="","",INDEX(選手一覧!$E$5:$E$2736,$K15)) -> 748 | N15: =IF(INDEX(選手一覧!$F$5:$F$2736,$K15)="","",INDEX(選手一覧!$F$5:$F$2736,$K15)) | O15: =IF(INDEX(選手一覧!$G$5:$G$2736,$K15)="","",INDEX(選手一覧!$G$5:$G$2736,$K15)) | P15: =IF(INDEX(選手一覧!$H$5:$H$2736,$K15)="","",INDEX(選手一覧!$H$5:$H$2736,$K15)) | Q15: =IF(INDEX(選手一覧!$I$5:$I$2736,$K15)="","",INDEX(選手一覧!$I$5:$I$2736,$K15))
A16: 1 | B16: 10 | C16: 38 | D16: =COUNTIFS($A$5:$A$115,A16,$E$5:$E$115,"<"&E16)+1 -> 11 | E16: 0.022268519 | F16: =E16/B16 -> 0.0022268519 | G16: 甲斐 蒼心朗 | H16: 小林・延岡工業高校合同 | J16: 42 | K16: 556 | L16: =IF(INDEX(選手一覧!$D$5:$D$2736,$K16)="","",INDEX(選手一覧!$D$5:$D$2736,$K16)) -> 0.010678356 | M16: =IF(INDEX(選手一覧!$E$5:$E$2736,$K16)="","",INDEX(選手一覧!$E$5:$E$2736,$K16)) -> 557 | N16: =IF(INDEX(選手一覧!$F$5:$F$2736,$K16)="","",INDEX(選手一覧!$F$5:$F$2736,$K16)) | O16: =IF(INDEX(選手一覧!$G$5:$G$2736,$K16)="","",INDEX(選手一覧!$G$5:$G$2736,$K16)) | P16: =IF(INDEX(選手一覧!$H$5:$H$2736,$K16)="","",INDEX(選手一覧!$H$5:$H$2736,$K16)) | Q16: =IF(INDEX(選手一覧!$I$5:$I$2736,$K16)="","",INDEX(選手一覧!$I$5:$I$2736,$K16))
... A115: 7 | B115: 4.845 | C115: 51 | D115: =COUNTIFS($A$5:$A$115,A115,$E$5:$E$115,"<"&E115)+1 -> 18 | E115: 0.011018519 | F115: =E115/B115 -> 0.002274204 | G115: 清次 怜桜 | H115: 尚志館高校 | J115: 52 | K115: 2292 | L115: =IF(INDEX(選手一覧!$D$5:$D$2736,$K115)="","",INDEX(選手一覧!$D$5:$D$2736,$K115)) | M115: =IF(INDEX(選手一覧!$E$5:$E$2736,$K115)="","",INDEX(選手一覧!$E$5:$E$2736,$K115)) | N115: =IF(INDEX(選手一覧!$F$5:$F$2736,$K115)="","",INDEX(選手一覧!$F$5:$F$2736,$K115)) -> 0.0077005787 | O115: =IF(INDEX(選手一覧!$G$5:$G$2736,$K115)="","",INDEX(選手一覧!$G$5:$G$2736,$K115)) -> 1066 | P115: =IF(INDEX(選手一覧!$H$5:$H$2736,$K115)="","",INDEX(選手一覧!$H$5:$H$2736,$K115)) | Q115: =IF(INDEX(選手一覧!$I$5:$I$2736,$K115)="","",INDEX(選手一覧!$I$5:$I$2736,$K115))

Sheet 3000mSC
A1: 3000mSC ランキング（陸マガ掲載順）
A2: 記録・順位は元データのまま（同一人物の二重掲載は上位の記録のみ残したため、その順位は欠番）。5000m・1500mは「選手一覧」から数式で参照（同一人物と判定できた場合のみ）。
A4: 順位 | B4: 氏名 | C4: 高校 | D4: 記録 | E4: トップ差 (秒) | F4: No | G4: 5000m 記録 | H4: 5000m 順位 | I4: 1500m 記録 | J4: 1500m 順位
A5: 1 | B5: 横浜 慶 | C5: 八千代松陰高 | D5: 0.0062386574 | E5: =ROUND((D5-$D$5)*86400,2) -> 0 | F5: 103 | G5: =IF(INDEX(選手一覧!$D$5:$D$2736,$F5)="","",INDEX(選手一覧!$D$5:$D$2736,$F5)) -> 0.010214815 | H5: =IF(INDEX(選手一覧!$E$5:$E$2736,$F5)="","",INDEX(選手一覧!$E$5:$E$2736,$F5)) -> 104 | I5: =IF(INDEX(選手一覧!$H$5:$H$2736,$F5)="","",INDEX(選手一覧!$H$5:$H$2736,$F5)) -> 0.0028627315 | J5: =IF(INDEX(選手一覧!$I$5:$I$2736,$F5)="","",INDEX(選手一覧!$I$5:$I$2736,$F5)) -> 654
A6: 2 | B6: 橋本 蒼平 | C6: 佐久長聖高 | D6: 0.0062690972 | E6: =ROUND((D6-$D$5)*86400,2) -> 2.63 | F6: 6 | G6: =IF(INDEX(選手一覧!$D$5:$D$2736,$F6)="","",INDEX(選手一覧!$D$5:$D$2736,$F6)) -> 0.0097591435 | H6: =IF(INDEX(選手一覧!$E$5:$E$2736,$F6)="","",INDEX(選手一覧!$E$5:$E$2736,$F6)) -> 6 | I6: =IF(INDEX(選手一覧!$H$5:$H$2736,$F6)="","",INDEX(選手一覧!$H$5:$H$2736,$F6)) -> 0.0027813657 | J6: =IF(INDEX(選手一覧!$I$5:$I$2736,$F6)="","",INDEX(選手一覧!$I$5:$I$2736,$F6)) -> 209
A7: 3 | B7: 久保 洋斗 | C7: 駒大高 | D7: 0.0062702546 | E7: =ROUND((D7-$D$5)*86400,2) -> 2.73 | F7: 145 | G7: =IF(INDEX(選手一覧!$D$5:$D$2736,$F7)="","",INDEX(選手一覧!$D$5:$D$2736,$F7)) -> 0.010278472 | H7: =IF(INDEX(選手一覧!$E$5:$E$2736,$F7)="","",INDEX(選手一覧!$E$5:$E$2736,$F7)) -> 146 | I7: =IF(INDEX(選手一覧!$H$5:$H$2736,$F7)="","",INDEX(選手一覧!$H$5:$H$2736,$F7)) -> 0.0029193287 | J7: =IF(INDEX(選手一覧!$I$5:$I$2736,$F7)="","",INDEX(選手一覧!$I$5:$I$2736,$F7)) -> 1088
A8: 4 | B8: 大賀 一誠 | C8: 樹徳高 | D8: 0.0063072917 | E8: =ROUND((D8-$D$5)*86400,2) -> 5.93 | F8: 200 | G8: =IF(INDEX(選手一覧!$D$5:$D$2736,$F8)="","",INDEX(選手一覧!$D$5:$D$2736,$F8)) -> 0.010348148 | H8: =IF(INDEX(選手一覧!$E$5:$E$2736,$F8)="","",INDEX(選手一覧!$E$5:$E$2736,$F8)) -> 201 | I8: =IF(INDEX(選手一覧!$H$5:$H$2736,$F8)="","",INDEX(選手一覧!$H$5:$H$2736,$F8)) -> 0.0027387731 | J8: =IF(INDEX(選手一覧!$I$5:$I$2736,$F8)="","",INDEX(選手一覧!$I$5:$I$2736,$F8)) -> 82
A9: 5 | B9: 酒瀬川 新 | C9: 法政二高 | D9: 0.0063265046 | E9: =ROUND((D9-$D$5)*86400,2) -> 7.59 | F9: 154 | G9: =IF(INDEX(選手一覧!$D$5:$D$2736,$F9)="","",INDEX(選手一覧!$D$5:$D$2736,$F9)) -> 0.010291667 | H9: =IF(INDEX(選手一覧!$E$5:$E$2736,$F9)="","",INDEX(選手一覧!$E$5:$E$2736,$F9)) -> 155 | I9: =IF(INDEX(選手一覧!$H$5:$H$2736,$F9)="","",INDEX(選手一覧!$H$5:$H$2736,$F9)) -> 0.0028498843 | J9: =IF(INDEX(選手一覧!$I$5:$I$2736,$F9)="","",INDEX(選手一覧!$I$5:$I$2736,$F9)) -> 569
A10: 6 | B10: 亀田 十羽 | C10: 興国高 | D10: 0.0063355324 | E10: =ROUND((D10-$D$5)*86400,2) -> 8.37 | F10: 101 | G10: =IF(INDEX(選手一覧!$D$5:$D$2736,$F10)="","",INDEX(選手一覧!$D$5:$D$2736,$F10)) -> 0.010214005 | H10: =IF(INDEX(選手一覧!$E$5:$E$2736,$F10)="","",INDEX(選手一覧!$E$5:$E$2736,$F10)) -> 102 | I10: =IF(INDEX(選手一覧!$H$5:$H$2736,$F10)="","",INDEX(選手一覧!$H$5:$H$2736,$F10)) -> 0.0028592593 | J10: =IF(INDEX(選手一覧!$I$5:$I$2736,$F10)="","",INDEX(選手一覧!$I$5:$I$2736,$F10)) -> 630
A11: 7 | B11: 時本 宝琉 | C11: 埼玉栄高 | D11: 0.0063403935 | E11: =ROUND((D11-$D$5)*86400,2) -> 8.79 | F11: 66 | G11: =IF(INDEX(選手一覧!$D$5:$D$2736,$F11)="","",INDEX(選手一覧!$D$5:$D$2736,$F11)) -> 0.010137731 | H11: =IF(INDEX(選手一覧!$E$5:$E$2736,$F11)="","",INDEX(選手一覧!$E$5:$E$2736,$F11)) -> 67 | I11: =IF(INDEX(選手一覧!$H$5:$H$2736,$F11)="","",INDEX(選手一覧!$H$5:$H$2736,$F11)) -> 0.0028818287 | J11: =IF(INDEX(選手一覧!$I$5:$I$2736,$F11)="","",INDEX(選手一覧!$I$5:$I$2736,$F11)) -> 787
A12: 8 | B12: 中田 智紘 | C12: 川崎橘高 | D12: 0.0063445602 | E12: =ROUND((D12-$D$5)*86400,2) -> 9.15 | F12: 219 | G12: =IF(INDEX(選手一覧!$D$5:$D$2736,$F12)="","",INDEX(選手一覧!$D$5:$D$2736,$F12)) -> 0.010364005 | H12: =IF(INDEX(選手一覧!$E$5:$E$2736,$F12)="","",INDEX(選手一覧!$E$5:$E$2736,$F12)) -> 220 | I12: =IF(INDEX(選手一覧!$H$5:$H$2736,$F12)="","",INDEX(選手一覧!$H$5:$H$2736,$F12)) | J12: =IF(INDEX(選手一覧!$I$5:$I$2736,$F12)="","",INDEX(選手一覧!$I$5:$I$2736,$F12))
A13: 9 | B13: 隅田 圭太 | C13: 東京実高 | D13: 0.0063452546 | E13: =ROUND((D13-$D$5)*86400,2) -> 9.21 | F13: 607 | G13: =IF(INDEX(選手一覧!$D$5:$D$2736,$F13)="","",INDEX(選手一覧!$D$5:$D$2736,$F13)) -> 0.010716088 | H13: =IF(INDEX(選手一覧!$E$5:$E$2736,$F13)="","",INDEX(選手一覧!$E$5:$E$2736,$F13)) -> 608 | I13: =IF(INDEX(選手一覧!$H$5:$H$2736,$F13)="","",INDEX(選手一覧!$H$5:$H$2736,$F13)) -> 0.0027759259 | J13: =IF(INDEX(選手一覧!$I$5:$I$2736,$F13)="","",INDEX(選手一覧!$I$5:$I$2736,$F13)) -> 180
A14: 10 | B14: 小早川 駿也 | C14: 洛南高 | D14: 0.006358912 | E14: =ROUND((D14-$D$5)*86400,2) -> 10.39 | F14: 83 | G14: =IF(INDEX(選手一覧!$D$5:$D$2736,$F14)="","",INDEX(選手一覧!$D$5:$D$2736,$F14)) -> 0.010178704 | H14: =IF(INDEX(選手一覧!$E$5:$E$2736,$F14)="","",INDEX(選手一覧!$E$5:$E$2736,$F14)) -> 84 | I14: =IF(INDEX(選手一覧!$H$5:$H$2736,$F14)="","",INDEX(選手一覧!$H$5:$H$2736,$F14)) | J14: =IF(INDEX(選手一覧!$I$5:$I$2736,$F14)="","",INDEX(選手一覧!$I$5:$I$2736,$F14))
A15: 11 | B15: 武村 翔月 | C15: 佐久長聖高 | D15: 0.0063674769 | E15: =ROUND((D15-$D$5)*86400,2) -> 11.13 | F15: 23 | G15: =IF(INDEX(選手一覧!$D$5:$D$2736,$F15)="","",INDEX(選手一覧!$D$5:$D$2736,$F15)) -> 0.010017014 | H15: =IF(INDEX(選手一覧!$E$5:$E$2736,$F15)="","",INDEX(選手一覧!$E$5:$E$2736,$F15)) -> 24 | I15: =IF(INDEX(選手一覧!$H$5:$H$2736,$F15)="","",INDEX(選手一覧!$H$5:$H$2736,$F15)) -> 0.0028085648 | J15: =IF(INDEX(選手一覧!$I$5:$I$2736,$F15)="","",INDEX(選手一覧!$I$5:$I$2736,$F15)) -> 320
A16: 12 | B16: 荒木 琉偉 | C16: 小林高 | D16: 0.0063840278 | E16: =ROUND((D16-$D$5)*86400,2) -> 12.56 | F16: 146 | G16: =IF(INDEX(選手一覧!$D$5:$D$2736,$F16)="","",INDEX(選手一覧!$D$5:$D$2736,$F16)) -> 0.010278472 | H16: =IF(INDEX(選手一覧!$E$5:$E$2736,$F16)="","",INDEX(選手一覧!$E$5:$E$2736,$F16)) -> 147 | I16: =IF(INDEX(選手一覧!$H$5:$H$2736,$F16)="","",INDEX(選手一覧!$H$5:$H$2736,$F16)) -> 0.0027630787 | J16: =IF(INDEX(選手一覧!$I$5:$I$2736,$F16)="","",INDEX(選手一覧!$I$5:$I$2736,$F16)) -> 142
... A1380: 1377 | B1380: 粕谷 悠珠 | C1380: 大田原高 | D1380: 0.010706829 | E1380: =ROUND((D1380-$D$5)*86400,2) -> 386.05 | F1380: 2732 | G1380: =IF(INDEX(選手一覧!$D$5:$D$2736,$F1380)="","",INDEX(選手一覧!$D$5:$D$2736,$F1380)) | H1380: =IF(INDEX(選手一覧!$E$5:$E$2736,$F1380)="","",INDEX(選手一覧!$E$5:$E$2736,$F1380)) | I1380: =IF(INDEX(選手一覧!$H$5:$H$2736,$F1380)="","",INDEX(選手一覧!$H$5:$H$2736,$F1380)) | J1380: =IF(INDEX(選手一覧!$I$5:$I$2736,$F1380)="","",INDEX(選手一覧!$I$5:$I$2736,$F1380))

Sheet 1500m
A1: 1500m ランキング（陸マガ掲載順）
A2: 記録・順位は元データのまま（同一人物の二重掲載は上位の記録のみ残したため、その順位は欠番）。5000m・3000mSCは「選手一覧」から数式で参照（同一人物と判定できた場合のみ）。
A4: 順位 | B4: 氏名 | C4: 高校 | D4: 記録 | E4: トップ差 (秒) | F4: No | G4: 5000m 記録 | H4: 5000m 順位 | I4: 3000mSC 記録 | J4: 3000mSC 順位
A5: 1 | B5: 稲垣 翔馴 | C5: 洛南高 | D5: 0.0026045139 | E5: =ROUND((D5-$D$5)*86400,2) -> 0 | F5: 2 | G5: =IF(INDEX(選手一覧!$D$5:$D$2736,$F5)="","",INDEX(選手一覧!$D$5:$D$2736,$F5)) -> 0.0096434028 | H5: =IF(INDEX(選手一覧!$E$5:$E$2736,$F5)="","",INDEX(選手一覧!$E$5:$E$2736,$F5)) -> 2 | I5: =IF(INDEX(選手一覧!$F$5:$F$2736,$F5)="","",INDEX(選手一覧!$F$5:$F$2736,$F5)) -> 0.0064204861 | J5: =IF(INDEX(選手一覧!$G$5:$G$2736,$F5)="","",INDEX(選手一覧!$G$5:$G$2736,$F5)) -> 19
A6: 2 | B6: 石原 向規 | C6: 洛南高 | D6: 0.0026280093 | E6: =ROUND((D6-$D$5)*86400,2) -> 2.03 | F6: 3 | G6: =IF(INDEX(選手一覧!$D$5:$D$2736,$F6)="","",INDEX(選手一覧!$D$5:$D$2736,$F6)) -> 0.0096877315 | H6: =IF(INDEX(選手一覧!$E$5:$E$2736,$F6)="","",INDEX(選手一覧!$E$5:$E$2736,$F6)) -> 3 | I6: =IF(INDEX(選手一覧!$F$5:$F$2736,$F6)="","",INDEX(選手一覧!$F$5:$F$2736,$F6)) | J6: =IF(INDEX(選手一覧!$G$5:$G$2736,$F6)="","",INDEX(選手一覧!$G$5:$G$2736,$F6))
A7: 3 | B7: ボイ ビリス | C7: 札幌山の手高 | D7: 0.0026409722 | E7: =ROUND((D7-$D$5)*86400,2) -> 3.15 | F7: 1 | G7: =IF(INDEX(選手一覧!$D$5:$D$2736,$F7)="","",INDEX(選手一覧!$D$5:$D$2736,$F7)) -> 0.0091405093 | H7: =IF(INDEX(選手一覧!$E$5:$E$2736,$F7)="","",INDEX(選手一覧!$E$5:$E$2736,$F7)) -> 1 | I7: =IF(INDEX(選手一覧!$F$5:$F$2736,$F7)="","",INDEX(選手一覧!$F$5:$F$2736,$F7)) | J7: =IF(INDEX(選手一覧!$G$5:$G$2736,$F7)="","",INDEX(選手一覧!$G$5:$G$2736,$F7))
A8: 4 | B8: 座光寺 奏 | C8: 佐久長聖高 | D8: 0.0026501157 | E8: =ROUND((D8-$D$5)*86400,2) -> 3.94 | F8: 1291 | G8: =IF(INDEX(選手一覧!$D$5:$D$2736,$F8)="","",INDEX(選手一覧!$D$5:$D$2736,$F8)) | H8: =IF(INDEX(選手一覧!$E$5:$E$2736,$F8)="","",INDEX(選手一覧!$E$5:$E$2736,$F8)) | I8: =IF(INDEX(選手一覧!$F$5:$F$2736,$F8)="","",INDEX(選手一覧!$F$5:$F$2736,$F8)) | J8: =IF(INDEX(選手一覧!$G$5:$G$2736,$F8)="","",INDEX(選手一覧!$G$5:$G$2736,$F8))
A9: 5 | B9: 加田 蒼 | C9: 稲生高 | D9: 0.0026621528 | E9: =ROUND((D9-$D$5)*86400,2) -> 4.98 | F9: 783 | G9: =IF(INDEX(選手一覧!$D$5:$D$2736,$F9)="","",INDEX(選手一覧!$D$5:$D$2736,$F9)) -> 0.010825694 | H9: =IF(INDEX(選手一覧!$E$5:$E$2736,$F9)="","",INDEX(選手一覧!$E$5:$E$2736,$F9)) -> 784 | I9: =IF(INDEX(選手一覧!$F$5:$F$2736,$F9)="","",INDEX(選手一覧!$F$5:$F$2736,$F9)) | J9: =IF(INDEX(選手一覧!$G$5:$G$2736,$F9)="","",INDEX(選手一覧!$G$5:$G$2736,$F9))
A10: 6 | B10: 喜多 勇貴 | C10: 徳島科技高 | D10: 0.0026662037 | E10: =ROUND((D10-$D$5)*86400,2) -> 5.33 | F10: 225 | G10: =IF(INDEX(選手一覧!$D$5:$D$2736,$F10)="","",INDEX(選手一覧!$D$5:$D$2736,$F10)) -> 0.010371181 | H10: =IF(INDEX(選手一覧!$E$5:$E$2736,$F10)="","",INDEX(選手一覧!$E$5:$E$2736,$F10)) -> 226 | I10: =IF(INDEX(選手一覧!$F$5:$F$2736,$F10)="","",INDEX(選手一覧!$F$5:$F$2736,$F10)) | J10: =IF(INDEX(選手一覧!$G$5:$G$2736,$F10)="","",INDEX(選手一覧!$G$5:$G$2736,$F10))
A11: 7 | B11: 増田 大誠 | C11: 上田西高 | D11: 0.0026707176 | E11: =ROUND((D11-$D$5)*86400,2) -> 5.72 | F11: 25 | G11: =IF(INDEX(選手一覧!$D$5:$D$2736,$F11)="","",INDEX(選手一覧!$D$5:$D$2736,$F11)) -> 0.010022338 | H11: =IF(INDEX(選手一覧!$E$5:$E$2736,$F11)="","",INDEX(選手一覧!$E$5:$E$2736,$F11)) -> 26 | I11: =IF(INDEX(選手一覧!$F$5:$F$2736,$F11)="","",INDEX(選手一覧!$F$5:$F$2736,$F11)) | J11: =IF(INDEX(選手一覧!$G$5:$G$2736,$F11)="","",INDEX(選手一覧!$G$5:$G$2736,$F11))
A12: 8 | B12: 野口 琉太 | C12: 小林高 | D12: 0.0026759259 | E12: =ROUND((D12-$D$5)*86400,2) -> 6.17 | F12: 12 | G12: =IF(INDEX(選手一覧!$D$5:$D$2736,$F12)="","",INDEX(選手一覧!$D$5:$D$2736,$F12)) -> 0.0098730324 | H12: =IF(INDEX(選手一覧!$E$5:$E$2736,$F12)="","",INDEX(選手一覧!$E$5:$E$2736,$F12)) -> 12 | I12: =IF(INDEX(選手一覧!$F$5:$F$2736,$F12)="","",INDEX(選手一覧!$F$5:$F$2736,$F12)) | J12: =IF(INDEX(選手一覧!$G$5:$G$2736,$F12)="","",INDEX(選手一覧!$G$5:$G$2736,$F12))
A13: 9 | B13: 杉平 颯志 | C13: 鳥栖工高 | D13: 0.0026765046 | E13: =ROUND((D13-$D$5)*86400,2) -> 6.22 | F13: 24 | G13: =IF(INDEX(選手一覧!$D$5:$D$2736,$F13)="","",INDEX(選手一覧!$D$5:$D$2736,$F13)) -> 0.010019444 | H13: =IF(INDEX(選手一覧!$E$5:$E$2736,$F13)="","",INDEX(選手一覧!$E$5:$E$2736,$F13)) -> 25 | I13: =IF(INDEX(選手一覧!$F$5:$F$2736,$F13)="","",INDEX(選手一覧!$F$5:$F$2736,$F13)) | J13: =IF(INDEX(選手一覧!$G$5:$G$2736,$F13)="","",INDEX(選手一覧!$G$5:$G$2736,$F13))
A14: 10 | B14: 箕浦 悠人 | C14: 草津東高 | D14: 0.0026770833 | E14: =ROUND((D14-$D$5)*86400,2) -> 6.27 | F14: 632 | G14: =IF(INDEX(選手一覧!$D$5:$D$2736,$F14)="","",INDEX(選手一覧!$D$5:$D$2736,$F14)) -> 0.010730903 | H14: =IF(INDEX(選手一覧!$E$5:$E$2736,$F14)="","",INDEX(選手一覧!$E$5:$E$2736,$F14)) -> 633 | I14: =IF(INDEX(選手一覧!$F$5:$F$2736,$F14)="","",INDEX(選手一覧!$F$5:$F$2736,$F14)) | J14: =IF(INDEX(選手一覧!$G$5:$G$2736,$F14)="","",INDEX(選手一覧!$G$5:$G$2736,$F14))
A15: 11 | B15: 辻井 智稀 | C15: 関大北陽高 | D15: 0.0026774306 | E15: =ROUND((D15-$D$5)*86400,2) -> 6.3 | F15: 97 | G15: =IF(INDEX(選手一覧!$D$5:$D$2736,$F15)="","",INDEX(選手一覧!$D$5:$D$2736,$F15)) -> 0.010204167 | H15: =IF(INDEX(選手一覧!$E$5:$E$2736,$F15)="","",INDEX(選手一覧!$E$5:$E$2736,$F15)) -> 98 | I15: =IF(INDEX(選手一覧!$F$5:$F$2736,$F15)="","",INDEX(選手一覧!$F$5:$F$2736,$F15)) | J15: =IF(INDEX(選手一覧!$G$5:$G$2736,$F15)="","",INDEX(選手一覧!$G$5:$G$2736,$F15))
A16: 12 | B16: 小笠原慶翔 | C16: 川口市陸協 | D16: 0.0026788194 | E16: =ROUND((D16-$D$5)*86400,2) -> 6.42 | F16: 235 | G16: =IF(INDEX(選手一覧!$D$5:$D$2736,$F16)="","",INDEX(選手一覧!$D$5:$D$2736,$F16)) -> 0.010376505 | H16: =IF(INDEX(選手一覧!$E$5:$E$2736,$F16)="","",INDEX(選手一覧!$E$5:$E$2736,$F16)) -> 236 | I16: =IF(INDEX(選手一覧!$F$5:$F$2736,$F16)="","",INDEX(選手一覧!$F$5:$F$2736,$F16)) | J16: =IF(INDEX(選手一覧!$G$5:$G$2736,$F16)="","",INDEX(選手一覧!$G$5:$G$2736,$F16))
... A1360: 1357 | B1360: 徳山 泰輝 | C1360: 報徳学園高 | D1360: 0.0029810185 | E1360: =ROUND((D1360-$D$5)*86400,2) -> 32.53 | F1360: 2712 | G1360: =IF(INDEX(選手一覧!$D$5:$D$2736,$F1360)="","",INDEX(選手一覧!$D$5:$D$2736,$F1360)) | H1360: =IF(INDEX(選手一覧!$E$5:$E$2736,$F1360)="","",INDEX(選手一覧!$E$5:$E$2736,$F1360)) | I1360: =IF(INDEX(選手一覧!$F$5:$F$2736,$F1360)="","",INDEX(選手一覧!$F$5:$F$2736,$F1360)) | J1360: =IF(INDEX(選手一覧!$G$5:$G$2736,$F1360)="","",INDEX(選手一覧!$G$5:$G$2736,$F1360))
