Workbook

Sheet 概要
A1: 出雲駅伝 振り返り分析（2022〜2026年）
A2: 目的：近年ピーキングが合わず順位が伸びない原因を、2週間前の5000mと夏合宿のデータから探る
A4: シート一覧
A5: 年別まとめ | B5: 年ごとの総合順位・区間差・悪化率・合宿の負荷を1表に集約。相関係数と区間別平均つき
A6: 出雲区間記録 | B6: 各区間の日本人トップと青学選手のタイム、5km（6区は10km）換算と差
A7: 5000m比較 | B7: 出雲メンバーの2週間前5000m（5km）と組内順位、出雲5km換算ペース、悪化率
A8: 合宿走行距離 | B8: 出雲メンバーの1次・2次合宿の距離（2023〜2026年）
A9: 合宿距離×区間順位 | B9: 1次・2次合宿の距離と区間順位・日本人トップとの差・悪化率を1表に。年平均、相関係数、区間3位以内との比較つき
A10: 合宿消化率 | B10: 出雲メンバーの1〜3次合宿の消化率（2023〜2026年）
A11: 月間走行距離 | B11: 出雲メンバーの月間走行距離（2022・2023年通年、2024年1〜6月）
A12: 合宿距離_上位35人 | B12: 1次・2次合宿の1日あたり走行距離の上位35人（出雲メンバー以外も含む）
A13: 合宿距離ランキング_全員 | B13: 年度ごとの全部員の走行距離ランキング（1次・2次・1次+2次）。出雲メンバーは黄色
A14: チーム平均推移 | B14: 夏合宿・月間のチーム平均走行距離の推移と、上位35人・出雲メンバーとの比較
A15: 区間順位との相関 | B15: 区間順位と各項目（5000m、悪化率、合宿距離、消化率、月間距離）の相関一覧
A16: 合宿メニュー_2023〜2026 | B16: 1〜3次合宿のポイント練習と、出雲メンバー6人の組・消化率
A17: 選手一覧 | B17: 出雲出走選手30人（2022〜2026年）の情報を1行1人で集約した一覧表
A19: 用語と計算方法
A20: 換算タイム | B20: 実タイム×換算距離÷区間距離。1〜5区は5km、6区は10kmあたり
A21: 日本人トップ | B21: 留学生を除いた区間最速の選手（区間賞が留学生だったのは5年とも3区のみ）
A22: 悪化率 | B22: 出雲の5km換算ペース÷2週間前5000m記録−1。大きいほど本番で落ちている
A23: チーム比 | B23: 出雲メンバー6人の1次合宿距離の平均÷チーム全体の平均
A24: 対象 | B24: 出雲駅伝に出走した青学の選手（各年6人）のみ。比較用に日本人トップの区間記録、チーム平均距離、「合宿距離_上位35人」「合宿距離ランキング_全員」シートだけは他の部員も含む
A25: 色の意味 | B25: 緑〜赤の背景色は良い〜悪い。区間賞は黄色の背景
A27: これまでの分析で見えたこと（仮説）
A28: ・ | B28: 2週間前の5000mが速い年ほど出雲での悪化率が大きい（年単位で強い負の相関）。個人単位では関係がほぼない
A29: ・ | B29: 総合3位の2024年だけ、出雲メンバーの1次合宿距離がチーム平均を下回った（93%）。他の年は113〜121%
A30: ・ | B30: 3次合宿の骨組み（距離走→変化走→スピード）と消化率は4年とも大差なく、2024年も最終日は強い練習だった
A31: ・ | B31: 2026年は3次合宿の最終日が9/23と遅く、出雲まで19日（他の年は22〜23日）。最後の練習の4日後の5kmで6人中5人が自己ベスト
A32: ・ | B32: 注意：年単位の比較は4〜5年分しかなく、統計的に確かとは言えない
A34: 未提供のデータ
A35: ・ | B35: 2023〜2025年の5000m記録会の日付
A36: ・ | B36: 3次合宿終了から出雲までの練習内容（2024〜2026年、2023年の9/18〜9/29）
A37: ・ | B37: 2024年7〜10月、2025・2026年の月間走行距離
A38: ・ | B38: 2022年の合宿データ（走行距離・消化率・3次合宿日程）

Sheet 年別まとめ
A1: 年別まとめ：出雲の成績と、2週間前5000m・合宿データの比較
A2: メンバー＝その年の出雲出走6人。順位・チーム平均・日付は元資料からの入力値（出典は各セルのコメント）、それ以外は他シートからの集計式。空欄はデータ未提供
A4: 年 | B4: 出雲 総合順位 | C4: 1〜5区 平均差 (秒/5km) | D4: 6区差 (秒/10km) | E4: メンバー 5000m平均 | F4: 悪化率 平均 | G4: メンバー 1次距離 (km) | H4: チーム 1次平均 (km) | I4: 1次距離 チーム比 | J4: メンバー 2次距離 (km) | K4: メンバー 夏消化率 | L4: メンバー 8月月間 (km) | M4: メンバー 9月月間 (km) | N4: 9月÷8月 | O4: 3次合宿 最終日 | P4: 出雲 開催日 | Q4: 3次終了→ 出雲(日)
A5: 2022 | B5: 4 | C5: =IFERROR(AVERAGEIFS(出雲区間記録!$M$5:$M$34,出雲区間記録!$A$5:$A$34,A5,出雲区間記録!$B$5:$B$34,"<6"),"") -> 17.26 | D5: =IFERROR(AVERAGEIFS(出雲区間記録!$M$5:$M$34,出雲区間記録!$A$5:$A$34,A5,出雲区間記録!$B$5:$B$34,6),"") -> 23.5 | E5: =IFERROR(AVERAGEIFS(5000m比較!$D$5:$D$34,5000m比較!$A$5:$A$34,A5),"") -> 0.009670081 | F5: =IFERROR(AVERAGEIFS(5000m比較!$K$5:$K$34,5000m比較!$A$5:$A$34,A5),"") -> 0.037655676 | G5: =IFERROR(AVERAGEIFS(合宿走行距離!$C$5:$C$28,合宿走行距離!$A$5:$A$28,A5,合宿走行距離!$G$5:$G$28,">0"),"") | I5: =IFERROR(G5/H5,"") | J5: =IFERROR(AVERAGEIFS(合宿走行距離!$D$5:$D$28,合宿走行距離!$A$5:$A$28,A5,合宿走行距離!$G$5:$G$28,">0"),"") | K5: =IFERROR(AVERAGEIFS(合宿消化率!$F$5:$F$28,合宿消化率!$A$5:$A$28,A5,合宿消化率!$G$5:$G$28,">0"),"") | L5: =IFERROR(AVERAGEIFS(月間走行距離!$J$5:$J$22,月間走行距離!$A$5:$A$22,A5,月間走行距離!$P$5:$P$22,">0"),"") -> 675.16667 | M5: =IFERROR(AVERAGEIFS(月間走行距離!$K$5:$K$22,月間走行距離!$A$5:$A$22,A5,月間走行距離!$P$5:$P$22,">0"),"") -> 396.83333 | N5: =IFERROR(M5/L5,"") -> 0.58775611 | P5: 44844 | Q5: =IF(O5="","",P5-O5)
A6: 2023 | B6: 4 | C6: =IFERROR(AVERAGEIFS(出雲区間記録!$M$5:$M$34,出雲区間記録!$A$5:$A$34,A6,出雲区間記録!$B$5:$B$34,"<6"),"") -> 20.2 | D6: =IFERROR(AVERAGEIFS(出雲区間記録!$M$5:$M$34,出雲区間記録!$A$5:$A$34,A6,出雲区間記録!$B$5:$B$34,6),"") -> 82.4 | E6: =IFERROR(AVERAGEIFS(5000m比較!$D$5:$D$34,5000m比較!$A$5:$A$34,A6),"") -> 0.0094771219 | F6: =IFERROR(AVERAGEIFS(5000m比較!$K$5:$K$34,5000m比較!$A$5:$A$34,A6),"") -> 0.064307712 | G6: =IFERROR(AVERAGEIFS(合宿走行距離!$C$5:$C$28,合宿走行距離!$A$5:$A$28,A6,合宿走行距離!$G$5:$G$28,">0"),"") -> 575.25 | H6: 507.9 | I6: =IFERROR(G6/H6,"") -> 1.1326048 | J6: =IFERROR(AVERAGEIFS(合宿走行距離!$D$5:$D$28,合宿走行距離!$A$5:$A$28,A6,合宿走行距離!$G$5:$G$28,">0"),"") -> 232.33333 | K6: =IFERROR(AVERAGEIFS(合宿消化率!$F$5:$F$28,合宿消化率!$A$5:$A$28,A6,合宿消化率!$G$5:$G$28,">0"),"") -> 0.9085 | L6: =IFERROR(AVERAGEIFS(月間走行距離!$J$5:$J$22,月間走行距離!$A$5:$A$22,A6,月間走行距離!$P$5:$P$22,">0"),"") -> 636.33333 | M6: =IFERROR(AVERAGEIFS(月間走行距離!$K$5:$K$22,月間走行距離!$A$5:$A$22,A6,月間走行距離!$P$5:$P$22,">0"),"") -> 468.13333 | N6: =IFERROR(M6/L6,"") -> 0.73567313 | O6: 45186 | P6: 45208 | Q6: =IF(O6="","",P6-O6) -> 22
A7: 2024 | B7: 3 | C7: =IFERROR(AVERAGEIFS(出雲区間記録!$M$5:$M$34,出雲区間記録!$A$5:$A$34,A7,出雲区間記録!$B$5:$B$34,"<6"),"") -> 15.26 | D7: =IFERROR(AVERAGEIFS(出雲区間記録!$M$5:$M$34,出雲区間記録!$A$5:$A$34,A7,出雲区間記録!$B$5:$B$34,6),"") -> 35.3 | E7: =IFERROR(AVERAGEIFS(5000m比較!$D$5:$D$34,5000m比較!$A$5:$A$34,A7),"") -> 0.0095935764 | F7: =IFERROR(AVERAGEIFS(5000m比較!$K$5:$K$34,5000m比較!$A$5:$A$34,A7),"") -> 0.046245094 | G7: =IFERROR(AVERAGEIFS(合宿走行距離!$C$5:$C$28,合宿走行距離!$A$5:$A$28,A7,合宿走行距離!$G$5:$G$28,">0"),"") -> 474.33333 | H7: 510.6 | I7: =IFERROR(G7/H7,"") -> 0.92897245 | J7: =IFERROR(AVERAGEIFS(合宿走行距離!$D$5:$D$28,合宿走行距離!$A$5:$A$28,A7,合宿走行距離!$G$5:$G$28,">0"),"") -> 210.33333 | K7: =IFERROR(AVERAGEIFS(合宿消化率!$F$5:$F$28,合宿消化率!$A$5:$A$28,A7,合宿消化率!$G$5:$G$28,">0"),"") -> 0.97083333 | L7: =IFERROR(AVERAGEIFS(月間走行距離!$J$5:$J$22,月間走行距離!$A$5:$A$22,A7,月間走行距離!$P$5:$P$22,">0"),"") | M7: =IFERROR(AVERAGEIFS(月間走行距離!$K$5:$K$22,月間走行距離!$A$5:$A$22,A7,月間走行距離!$P$5:$P$22,">0"),"") | N7: =IFERROR(M7/L7,"") | O7: 45556 | P7: 45579 | Q7: =IF(O7="","",P7-O7) -> 23
A8: 2025 | B8: 7 | C8: =IFERROR(AVERAGEIFS(出雲区間記録!$M$5:$M$34,出雲区間記録!$A$5:$A$34,A8,出雲区間記録!$B$5:$B$34,"<6"),"") -> 26.68 | D8: =IFERROR(AVERAGEIFS(出雲区間記録!$M$5:$M$34,出雲区間記録!$A$5:$A$34,A8,出雲区間記録!$B$5:$B$34,6),"") -> 0 | E8: =IFERROR(AVERAGEIFS(5000m比較!$D$5:$D$34,5000m比較!$A$5:$A$34,A8),"") -> 0.0095612269 | F8: =IFERROR(AVERAGEIFS(5000m比較!$K$5:$K$34,5000m比較!$A$5:$A$34,A8),"") -> 0.052597877 | G8: =IFERROR(AVERAGEIFS(合宿走行距離!$C$5:$C$28,合宿走行距離!$A$5:$A$28,A8,合宿走行距離!$G$5:$G$28,">0"),"") -> 578.66667 | H8: 481 | I8: =IFERROR(G8/H8,"") -> 1.2030492 | J8: =IFERROR(AVERAGEIFS(合宿走行距離!$D$5:$D$28,合宿走行距離!$A$5:$A$28,A8,合宿走行距離!$G$5:$G$28,">0"),"") -> 230.5 | K8: =IFERROR(AVERAGEIFS(合宿消化率!$F$5:$F$28,合宿消化率!$A$5:$A$28,A8,合宿消化率!$G$5:$G$28,">0"),"") -> 0.98111111 | L8: =IFERROR(AVERAGEIFS(月間走行距離!$J$5:$J$22,月間走行距離!$A$5:$A$22,A8,月間走行距離!$P$5:$P$22,">0"),"") | M8: =IFERROR(AVERAGEIFS(月間走行距離!$K$5:$K$22,月間走行距離!$A$5:$A$22,A8,月間走行距離!$P$5:$P$22,">0"),"") | N8: =IFERROR(M8/L8,"") | O8: 45920 | P8: 45943 | Q8: =IF(O8="","",P8-O8) -> 23
A9: 2026 | B9: 11 | C9: =IFERROR(AVERAGEIFS(出雲区間記録!$M$5:$M$34,出雲区間記録!$A$5:$A$34,A9,出雲区間記録!$B$5:$B$34,"<6"),"") -> 24.36 | D9: =IFERROR(AVERAGEIFS(出雲区間記録!$M$5:$M$34,出雲区間記録!$A$5:$A$34,A9,出雲区間記録!$B$5:$B$34,6),"") -> 83.3 | E9: =IFERROR(AVERAGEIFS(5000m比較!$D$5:$D$34,5000m比較!$A$5:$A$34,A9),"") -> 0.0094695216 | F9: =IFERROR(AVERAGEIFS(5000m比較!$K$5:$K$34,5000m比較!$A$5:$A$34,A9),"") -> 0.051834792 | G9: =IFERROR(AVERAGEIFS(合宿走行距離!$C$5:$C$28,合宿走行距離!$A$5:$A$28,A9,合宿走行距離!$G$5:$G$28,">0"),"") -> 555.5 | H9: 460 | I9: =IFERROR(G9/H9,"") -> 1.2076087 | J9: =IFERROR(AVERAGEIFS(合宿走行距離!$D$5:$D$28,合宿走行距離!$A$5:$A$28,A9,合宿走行距離!$G$5:$G$28,">0"),"") -> 227.66667 | K9: =IFERROR(AVERAGEIFS(合宿消化率!$F$5:$F$28,合宿消化率!$A$5:$A$28,A9,合宿消化率!$G$5:$G$28,">0"),"") -> 0.98 | L9: =IFERROR(AVERAGEIFS(月間走行距離!$J$5:$J$22,月間走行距離!$A$5:$A$22,A9,月間走行距離!$P$5:$P$22,">0"),"") | M9: =IFERROR(AVERAGEIFS(月間走行距離!$K$5:$K$22,月間走行距離!$A$5:$A$22,A9,月間走行距離!$P$5:$P$22,">0"),"") | N9: =IFERROR(M9/L9,"") | O9: 46288 | P9: 46307 | Q9: =IF(O9="","",P9-O9) -> 19
A11: 年単位の相関係数（データのある年のみ。年数が少ないため参考値）
A12: 組み合わせ | E12: 対象年 | F12: 相関係数
A13: メンバー5000m平均 × 悪化率平均 | E13: 2022〜26年 | F13: =CORREL(E5:E9,F5:F9) -> -0.86202747
A14: メンバー5000m平均 × 総合順位 | E14: 2022〜26年 | F14: =CORREL(E5:E9,B5:B9) -> -0.55765554
A15: 悪化率平均 × 総合順位 | E15: 2022〜26年 | F15: =CORREL(F5:F9,B5:B9) -> 0.15400461
A16: 1次距離チーム比 × 総合順位 | E16: 2023〜26年 | F16: =CORREL(I6:I9,B6:B9) -> 0.76023496
A17: 1次距離チーム比 × 悪化率平均 | E17: 2023〜26年 | F17: =CORREL(I6:I9,F6:F9) -> 0.4381253
A19: 区間別の平均（5年間）
A20: 区間 | B20: 距離 (km) | C20: 日本人 トップとの 平均差(秒) | D20: 悪化率 平均 | E20: 区間賞 回数
A21: 1 | B21: 8 | C21: =AVERAGEIFS(出雲区間記録!$M$5:$M$34,出雲区間記録!$B$5:$B$34,A21) -> 9.5 | D21: =AVERAGEIFS(5000m比較!$K$5:$K$34,5000m比較!$B$5:$B$34,A21) -> 0.060414718 | E21: =COUNTIFS(出雲区間記録!$B$5:$B$34,A21,出雲区間記録!$K$5:$K$34,1) -> 1
A22: 2 | B22: 5.8 | C22: =AVERAGEIFS(出雲区間記録!$M$5:$M$34,出雲区間記録!$B$5:$B$34,A22) -> 25.52 | D22: =AVERAGEIFS(5000m比較!$K$5:$K$34,5000m比較!$B$5:$B$34,A22) -> 0.020883105 | E22: =COUNTIFS(出雲区間記録!$B$5:$B$34,A22,出雲区間記録!$K$5:$K$34,1) -> 1
A23: 3 | B23: 8.5 | C23: =AVERAGEIFS(出雲区間記録!$M$5:$M$34,出雲区間記録!$B$5:$B$34,A23) -> 22.84 | D23: =AVERAGEIFS(5000m比較!$K$5:$K$34,5000m比較!$B$5:$B$34,A23) -> 0.054357904 | E23: =COUNTIFS(出雲区間記録!$B$5:$B$34,A23,出雲区間記録!$K$5:$K$34,1) -> 0
A24: 4 | B24: 6.2 | C24: =AVERAGEIFS(出雲区間記録!$M$5:$M$34,出雲区間記録!$B$5:$B$34,A24) -> 23.24 | D24: =AVERAGEIFS(5000m比較!$K$5:$K$34,5000m比較!$B$5:$B$34,A24) -> 0.053213931 | E24: =COUNTIFS(出雲区間記録!$B$5:$B$34,A24,出雲区間記録!$K$5:$K$34,1) -> 1
A25: 5 | B25: 6.4 | C25: =AVERAGEIFS(出雲区間記録!$M$5:$M$34,出雲区間記録!$B$5:$B$34,A25) -> 22.66 | D25: =AVERAGEIFS(5000m比較!$K$5:$K$34,5000m比較!$B$5:$B$34,A25) -> 0.050137841 | E25: =COUNTIFS(出雲区間記録!$B$5:$B$34,A25,出雲区間記録!$K$5:$K$34,1) -> 1
A26: 6 | B26: 10.2 | C26: =AVERAGEIFS(出雲区間記録!$M$5:$M$34,出雲区間記録!$B$5:$B$34,A26) -> 44.9 | D26: =AVERAGEIFS(5000m比較!$K$5:$K$34,5000m比較!$B$5:$B$34,A26) -> 0.064161883 | E26: =COUNTIFS(出雲区間記録!$B$5:$B$34,A26,出雲区間記録!$K$5:$K$34,1) -> 1
A27: ※6区の平均差は10kmあたり。悪化率は全区間とも5kmあたりで比較

Sheet 出雲区間記録
A1: 出雲駅伝 区間記録：日本人トップと青学の比較（2022〜2026）
A2: 換算タイム＝実タイム×換算距離÷区間距離（1〜5区は5km、6区は10km）。差＝換算後の青学−日本人トップ（秒）。日本人トップ＝留学生を除いた区間最速。区間順位は留学生を含む公式記録。出典：各年の公式リザルトPDF
A4: 年 | B4: 区間 | C4: 距離 (km) | D4: 換算距離 (km) | E4: 日本人トップ | F4: 所属 | G4: 実タイム | H4: 換算 | I4: 青学選手 | J4: 実タイム | K4: 区間順位 | L4: 換算 | M4: 差（秒）
A5: 2022 | B5: 1 | C5: 8 | D5: =IF(B5=6,10,5) -> 5 | E5: 吉居 大和 | F5: 中央大学 | G5: 0.015648148 | H5: =G5*D5/C5 -> 0.0097800926 | I5: 目片 将大 | J5: 0.015798611 | K5: 3 | L5: =J5*D5/C5 -> 0.0098741319 | M5: =ROUND((L5-H5)*86400,1) -> 8.1
A6: 2022 | B6: 2 | C6: 5.8 | D6: =IF(B6=6,10,5) -> 5 | E6: 佐藤 圭汰 | F6: 駒澤大学 | G6: 0.010729167 | H6: =G6*D6/C6 -> 0.0092492816 | I6: 横田 俊吾 | J6: 0.010902778 | K6: 4 | L6: =J6*D6/C6 -> 0.0093989464 | M6: =ROUND((L6-H6)*86400,1) -> 12.9
A7: 2022 | B7: 3 | C7: 8.5 | D7: =IF(B7=6,10,5) -> 5 | E7: 田澤 廉 | F7: 駒澤大学 | G7: 0.016550926 | H7: =G7*D7/C7 -> 0.0097358388 | I7: 近藤 幸太郎 | J7: 0.0165625 | K7: 3 | L7: =J7*D7/C7 -> 0.0097426471 | M7: =ROUND((L7-H7)*86400,1) -> 0.6
A8: 2022 | B8: 4 | C8: 6.2 | D8: =IF(B8=6,10,5) -> 5 | E8: 中西 大翔 | F8: 國學院大學 | G8: 0.012384259 | H8: =G8*D8/C8 -> 0.0099873059 | I8: 志貴 勇斗 | J8: 0.013020833 | K8: 6 | L8: =J8*D8/C8 -> 0.010500672 | M8: =ROUND((L8-H8)*86400,1) -> 44.4
A9: 2022 | B9: 5 | C9: 6.4 | D9: =IF(B9=6,10,5) -> 5 | E9: 安原 太陽 | F9: 駒澤大学 | G9: 0.013240741 | H9: =G9*D9/C9 -> 0.010344329 | I9: 田中 悠登 | J9: 0.013541667 | K9: 6 | L9: =J9*D9/C9 -> 0.010579427 | M9: =ROUND((L9-H9)*86400,1) -> 20.3
A10: 2022 | B10: 6 | C10: 10.2 | D10: =IF(B10=6,10,5) -> 10 | E10: 鈴木 芽吹 | F10: 駒澤大学 | G10: 0.020381944 | H10: =G10*D10/C10 -> 0.019982298 | I10: 中村 唯翔 | J10: 0.020659722 | K10: 3 | L10: =J10*D10/C10 -> 0.02025463 | M10: =ROUND((L10-H10)*86400,1) -> 23.5
A11: 2023 | B11: 1 | C11: 8 | D11: =IF(B11=6,10,5) -> 5 | E11: 篠原 倖太朗 | F11: 駒澤大学 | G11: 0.015798611 | H11: =G11*D11/C11 -> 0.0098741319 | I11: 野村 昭夢 | J11: 0.01625 | K11: 6 | L11: =J11*D11/C11 -> 0.01015625 | M11: =ROUND((L11-H11)*86400,1) -> 24.4
A12: 2023 | B12: 2 | C12: 5.8 | D12: =IF(B12=6,10,5) -> 5 | E12: 佐藤 圭汰／黒田 朝日 | F12: 駒澤大学／青山学院大学 | G12: 0.011203704 | H12: =G12*D12/C12 -> 0.0096583653 | I12: 黒田 朝日 | J12: 0.011203704 | K12: 1 | L12: =J12*D12/C12 -> 0.0096583653 | M12: =ROUND((L12-H12)*86400,1) -> 0
A13: 2023 | B13: 3 | C13: 8.5 | D13: =IF(B13=6,10,5) -> 5 | E13: 山川 拓馬 | F13: 駒澤大学 | G13: 0.016898148 | H13: =G13*D13/C13 -> 0.0099400871 | I13: 佐藤 一世 | J13: 0.017268519 | K13: 3 | L13: =J13*D13/C13 -> 0.010157952 | M13: =ROUND((L13-H13)*86400,1) -> 18.8
A14: 2023 | B14: 4 | C14: 6.2 | D14: =IF(B14=6,10,5) -> 5 | E14: 山内 健登 | F14: 青山学院大学 | G14: 0.012210648 | H14: =G14*D14/C14 -> 0.0098472969 | I14: 山内 健登 | J14: 0.012210648 | K14: 1 | L14: =J14*D14/C14 -> 0.0098472969 | M14: =ROUND((L14-H14)*86400,1) -> 0
A15: 2023 | B15: 5 | C15: 6.4 | D15: =IF(B15=6,10,5) -> 5 | E15: 安原 太陽 | F15: 駒澤大学 | G15: 0.012395833 | H15: =G15*D15/C15 -> 0.0096842448 | I15: 鳥井 健太 | J15: 0.013252315 | K15: 9 | L15: =J15*D15/C15 -> 0.010353371 | M15: =ROUND((L15-H15)*86400,1) -> 57.8
A16: 2023 | B16: 6 | C16: 10.2 | D16: =IF(B16=6,10,5) -> 10 | E16: 鈴木 芽吹 | F16: 駒澤大学 | G16: 0.020138889 | H16: =G16*D16/C16 -> 0.019744009 | I16: 鶴川 正也 | J16: 0.021111111 | K16: 7 | L16: =J16*D16/C16 -> 0.020697168 | M16: =ROUND((L16-H16)*86400,1) -> 82.4
... A34: 2026 | B34: 6 | C34: 10.2 | D34: =IF(B34=6,10,5) -> 10 | E34: 工藤 慎作 | F34: 早稲田大学 | G34: 0.020138889 | H34: =G34*D34/C34 -> 0.019744009 | I34: 前川 竜之将 | J34: 0.021122685 | K34: 9 | L34: =J34*D34/C34 -> 0.020708515 | M34: =ROUND((L34-H34)*86400,1) -> 83.3

Sheet 5000m比較
A1: 2週間前の5000m（5km）と出雲の比較：出雲出走メンバー
A2: 出雲5km換算＝出雲の実タイム×5÷区間距離（6区も5kmあたりに換算）。悪化率＝出雲5km換算÷2週間前5000m−1。2026年はロード5km、他の年はトラック5000m。組内順位は留学生・他大学を含むその組の順位。出典：各年の記録会リザルト、出雲公式リザルト
A4: 年 | B4: 区間 | C4: 選手 | D4: 2週間前 5000m | E4: レース種別 | F4: 出雲 実タイム | G4: 区間順位 | H4: 区間距離 (km) | I4: 出雲 5km換算 | J4: 差（秒） | K4: 悪化率 | L4: 5000m 組内順位
A5: 2022 | B5: 1 | C5: 目片将大 | D5: 0.00959375 | E5: トラック5000m（4組） | F5: 0.015798611 | G5: 3 | H5: 8 | I5: =F5*5/H5 -> 0.0098741319 | J5: =ROUND((I5-D5)*86400,1) -> 24.2 | K5: =I5/D5-1 -> 0.02922548 | L5: 8
A6: 2022 | B6: 2 | C6: 横田俊吾 | D6: 0.0095695602 | E6: トラック5000m（4組） | F6: 0.010902778 | G6: 4 | H6: 5.8 | I6: =F6*5/H6 -> 0.0093989464 | J6: =ROUND((I6-D6)*86400,1) -> -14.7 | K6: =I6/D6-1 -> -0.017828805 | L6: 7
A7: 2022 | B7: 3 | C7: 近藤幸太郎 | D7: 0.0095262731 | E7: トラック5000m（4組） | F7: 0.0165625 | G7: 3 | H7: 8.5 | I7: =F7*5/H7 -> 0.0097426471 | J7: =ROUND((I7-D7)*86400,1) -> 18.7 | K7: =I7/D7-1 -> 0.022713385 | L7: 3
A8: 2022 | B8: 4 | C8: 志貴勇斗 | D8: 0.0099141204 | E8: トラック5000m（4組） | F8: 0.013020833 | G8: 6 | H8: 6.2 | I8: =F8*5/H8 -> 0.010500672 | J8: =ROUND((I8-D8)*86400,1) -> 50.7 | K8: =I8/D8-1 -> 0.059163259 | L8: 18
A9: 2022 | B9: 5 | C9: 田中悠登 | D9: 0.0098586806 | E9: トラック5000m（4組） | F9: 0.013541667 | G9: 6 | H9: 6.4 | I9: =F9*5/H9 -> 0.010579427 | J9: =ROUND((I9-D9)*86400,1) -> 62.3 | K9: =I9/D9-1 -> 0.073107808 | L9: 15
A10: 2022 | B10: 6 | C10: 中村唯翔 | D10: 0.0095581019 | E10: トラック5000m（4組） | F10: 0.020659722 | G10: 3 | H10: 10.2 | I10: =F10*5/H10 -> 0.010127315 | J10: =ROUND((I10-D10)*86400,1) -> 49.2 | K10: =I10/D10-1 -> 0.059552929 | L10: 6
A11: 2023 | B11: 1 | C11: 野村昭夢 | D11: 0.0094552083 | E11: トラック5000m（3組） | F11: 0.01625 | G11: 6 | H11: 8 | I11: =F11*5/H11 -> 0.01015625 | J11: =ROUND((I11-D11)*86400,1) -> 60.6 | K11: =I11/D11-1 -> 0.074143439 | L11: 7
A12: 2023 | B12: 2 | C12: 黒田朝日 | D12: 0.0094508102 | E12: トラック5000m（3組） | F12: 0.011203704 | G12: 1 | H12: 5.8 | I12: =F12*5/H12 -> 0.0096583653 | J12: =ROUND((I12-D12)*86400,1) -> 17.9 | K12: =I12/D12-1 -> 0.021961617 | L12: 5
A13: 2023 | B13: 3 | C13: 佐藤一世 | D13: 0.0094494213 | E13: トラック5000m（3組） | F13: 0.017268519 | G13: 3 | H13: 8.5 | I13: =F13*5/H13 -> 0.010157952 | J13: =ROUND((I13-D13)*86400,1) -> 61.2 | K13: =I13/D13-1 -> 0.074981393 | L13: 4
A14: 2023 | B14: 4 | C14: 山内健登 | D14: 0.0094333333 | E14: トラック5000m（3組） | F14: 0.012210648 | G14: 1 | H14: 6.2 | I14: =F14*5/H14 -> 0.0098472969 | J14: =ROUND((I14-D14)*86400,1) -> 35.8 | K14: =I14/D14-1 -> 0.043883063 | L14: 3
A15: 2023 | B15: 5 | C15: 鳥井健太 | D15: 0.0094528935 | E15: トラック5000m（3組） | F15: 0.013252315 | G15: 9 | H15: 6.4 | I15: =F15*5/H15 -> 0.010353371 | J15: =ROUND((I15-D15)*86400,1) -> 77.8 | K15: =I15/D15-1 -> 0.095259449 | L15: 6
A16: 2023 | B16: 6 | C16: 鶴川正也 | D16: 0.0096210648 | E16: トラック5000m（3組） | F16: 0.021111111 | G16: 7 | H16: 10.2 | I16: =F16*5/H16 -> 0.010348584 | J16: =ROUND((I16-D16)*86400,1) -> 62.9 | K16: =I16/D16-1 -> 0.075617312 | L16: 13
... A34: 2026 | B34: 6 | C34: 前川竜之将 | D34: 0.0094791667 | E34: ロード5km（adizero 5K、9/27） | F34: 0.021122685 | G34: 9 | H34: 10.2 | I34: =F34*5/H34 -> 0.010354257 | J34: =ROUND((I34-D34)*86400,1) -> 75.6 | K34: =I34/D34-1 -> 0.092317269 | L34: 14

Sheet 合宿走行距離
A1: 夏合宿 走行距離（1次・2次）：出雲メンバー
A2: 出雲出走メンバーのみ。出雲区間＝その年に走った区間。1次合宿の期間：2023年 7/26〜8/16（22日）、2024・2025年 8/1〜8/19（19日）、2026年 8/2〜8/19（18日）。2次合宿は各年10〜12日。出典：各年の走行距離ランキング（Excel・PDF）
A4: 年 | B4: 選手 | C4: 1次合宿 (km) | D4: 2次合宿 (km) | E4: 1次 日数 | F4: 1次 1日あたり | G4: 出雲 区間
A5: 2023 | B5: 野村昭夢 | C5: 559 | D5: 272 | E5: 22 | F5: =IF(C5="","",C5/E5) -> 25.409091 | G5: =SUMIFS(5000m比較!$B$5:$B$34,5000m比較!$A$5:$A$34,A5,5000m比較!$C$5:$C$34,B5) -> 1
A6: 2023 | B6: 黒田朝日 | C6: 509.5 | D6: 234 | E6: 22 | F6: =IF(C6="","",C6/E6) -> 23.159091 | G6: =SUMIFS(5000m比較!$B$5:$B$34,5000m比較!$A$5:$A$34,A6,5000m比較!$C$5:$C$34,B6) -> 2
A7: 2023 | B7: 佐藤一世 | C7: 647 | D7: 160 | E7: 22 | F7: =IF(C7="","",C7/E7) -> 29.409091 | G7: =SUMIFS(5000m比較!$B$5:$B$34,5000m比較!$A$5:$A$34,A7,5000m比較!$C$5:$C$34,B7) -> 3
A8: 2023 | B8: 山内健登 | C8: 569 | D8: 237 | E8: 22 | F8: =IF(C8="","",C8/E8) -> 25.863636 | G8: =SUMIFS(5000m比較!$B$5:$B$34,5000m比較!$A$5:$A$34,A8,5000m比較!$C$5:$C$34,B8) -> 4
A9: 2023 | B9: 鳥井健太 | C9: 708 | D9: 271 | E9: 22 | F9: =IF(C9="","",C9/E9) -> 32.181818 | G9: =SUMIFS(5000m比較!$B$5:$B$34,5000m比較!$A$5:$A$34,A9,5000m比較!$C$5:$C$34,B9) -> 5
A10: 2023 | B10: 鶴川正也 | C10: 459 | D10: 220 | E10: 22 | F10: =IF(C10="","",C10/E10) -> 20.863636 | G10: =SUMIFS(5000m比較!$B$5:$B$34,5000m比較!$A$5:$A$34,A10,5000m比較!$C$5:$C$34,B10) -> 6
A11: 2024 | B11: 鶴川正也 | C11: 409 | D11: 202 | E11: 19 | F11: =IF(C11="","",C11/E11) -> 21.526316 | G11: =SUMIFS(5000m比較!$B$5:$B$34,5000m比較!$A$5:$A$34,A11,5000m比較!$C$5:$C$34,B11) -> 1
A12: 2024 | B12: 野村昭夢 | C12: 485 | D12: 202 | E12: 19 | F12: =IF(C12="","",C12/E12) -> 25.526316 | G12: =SUMIFS(5000m比較!$B$5:$B$34,5000m比較!$A$5:$A$34,A12,5000m比較!$C$5:$C$34,B12) -> 2
A13: 2024 | B13: 黒田朝日 | C13: 453 | D13: 206 | E13: 19 | F13: =IF(C13="","",C13/E13) -> 23.842105 | G13: =SUMIFS(5000m比較!$B$5:$B$34,5000m比較!$A$5:$A$34,A13,5000m比較!$C$5:$C$34,B13) -> 3
A14: 2024 | B14: 宇田川瞬矢 | C14: 500 | D14: 199 | E14: 19 | F14: =IF(C14="","",C14/E14) -> 26.315789 | G14: =SUMIFS(5000m比較!$B$5:$B$34,5000m比較!$A$5:$A$34,A14,5000m比較!$C$5:$C$34,B14) -> 4
A15: 2024 | B15: 若林宏樹 | C15: 536 | D15: 252 | E15: 19 | F15: =IF(C15="","",C15/E15) -> 28.210526 | G15: =SUMIFS(5000m比較!$B$5:$B$34,5000m比較!$A$5:$A$34,A15,5000m比較!$C$5:$C$34,B15) -> 5
A16: 2024 | B16: 太田蒼生 | C16: 463 | D16: 201 | E16: 19 | F16: =IF(C16="","",C16/E16) -> 24.368421 | G16: =SUMIFS(5000m比較!$B$5:$B$34,5000m比較!$A$5:$A$34,A16,5000m比較!$C$5:$C$34,B16) -> 6
... A28: 2026 | B28: 前川竜之将 | C28: 619 | D28: 248 | E28: 18 | F28: =IF(C28="","",C28/E28) -> 34.388889 | G28: =SUMIFS(5000m比較!$B$5:$B$34,5000m比較!$A$5:$A$34,A28,5000m比較!$C$5:$C$34,B28) -> 6

Sheet 合宿距離×区間順位
A1: 夏合宿の走行距離と出雲の区間順位：出雲メンバー（2023〜2026）
A2: 値はすべて「合宿走行距離」「5000m比較」「出雲区間記録」シートからの参照式。区間順位は留学生を含む公式記録。日本人トップとの差は1〜5区が5kmあたり、6区が10kmあたりの秒差。悪化率＝出雲5km換算÷2週間前5000m−1
A4: 年 | B4: 区間 | C4: 選手 | D4: 区間順位 | E4: 1次合宿 (km) | F4: 1次 1日あたり (km) | G4: 2次合宿 (km) | H4: 1次+2次 合計(km) | I4: 日本人トップ との差(秒) | J4: 悪化率
A5: 2023 | B5: 1 | C5: 野村昭夢 | D5: =SUMIFS(5000m比較!$G$5:$G$34,5000m比較!$A$5:$A$34,$A5,5000m比較!$C$5:$C$34,$C5) -> 6 | E5: =SUMIFS(合宿走行距離!$C$5:$C$28,合宿走行距離!$A$5:$A$28,$A5,合宿走行距離!$B$5:$B$28,$C5) -> 559 | F5: =SUMIFS(合宿走行距離!$F$5:$F$28,合宿走行距離!$A$5:$A$28,$A5,合宿走行距離!$B$5:$B$28,$C5) -> 25.409091 | G5: =SUMIFS(合宿走行距離!$D$5:$D$28,合宿走行距離!$A$5:$A$28,$A5,合宿走行距離!$B$5:$B$28,$C5) -> 272 | H5: =E5+G5 -> 831 | I5: =SUMIFS(出雲区間記録!$M$5:$M$34,出雲区間記録!$A$5:$A$34,$A5,出雲区間記録!$B$5:$B$34,$B5) -> 24.4 | J5: =SUMIFS(5000m比較!$K$5:$K$34,5000m比較!$A$5:$A$34,$A5,5000m比較!$C$5:$C$34,$C5) -> 0.074143439
A6: 2023 | B6: 2 | C6: 黒田朝日 | D6: =SUMIFS(5000m比較!$G$5:$G$34,5000m比較!$A$5:$A$34,$A6,5000m比較!$C$5:$C$34,$C6) -> 1 | E6: =SUMIFS(合宿走行距離!$C$5:$C$28,合宿走行距離!$A$5:$A$28,$A6,合宿走行距離!$B$5:$B$28,$C6) -> 509.5 | F6: =SUMIFS(合宿走行距離!$F$5:$F$28,合宿走行距離!$A$5:$A$28,$A6,合宿走行距離!$B$5:$B$28,$C6) -> 23.159091 | G6: =SUMIFS(合宿走行距離!$D$5:$D$28,合宿走行距離!$A$5:$A$28,$A6,合宿走行距離!$B$5:$B$28,$C6) -> 234 | H6: =E6+G6 -> 743.5 | I6: =SUMIFS(出雲区間記録!$M$5:$M$34,出雲区間記録!$A$5:$A$34,$A6,出雲区間記録!$B$5:$B$34,$B6) -> 0 | J6: =SUMIFS(5000m比較!$K$5:$K$34,5000m比較!$A$5:$A$34,$A6,5000m比較!$C$5:$C$34,$C6) -> 0.021961617
A7: 2023 | B7: 3 | C7: 佐藤一世 | D7: =SUMIFS(5000m比較!$G$5:$G$34,5000m比較!$A$5:$A$34,$A7,5000m比較!$C$5:$C$34,$C7) -> 3 | E7: =SUMIFS(合宿走行距離!$C$5:$C$28,合宿走行距離!$A$5:$A$28,$A7,合宿走行距離!$B$5:$B$28,$C7) -> 647 | F7: =SUMIFS(合宿走行距離!$F$5:$F$28,合宿走行距離!$A$5:$A$28,$A7,合宿走行距離!$B$5:$B$28,$C7) -> 29.409091 | G7: =SUMIFS(合宿走行距離!$D$5:$D$28,合宿走行距離!$A$5:$A$28,$A7,合宿走行距離!$B$5:$B$28,$C7) -> 160 | H7: =E7+G7 -> 807 | I7: =SUMIFS(出雲区間記録!$M$5:$M$34,出雲区間記録!$A$5:$A$34,$A7,出雲区間記録!$B$5:$B$34,$B7) -> 18.8 | J7: =SUMIFS(5000m比較!$K$5:$K$34,5000m比較!$A$5:$A$34,$A7,5000m比較!$C$5:$C$34,$C7) -> 0.074981393
A8: 2023 | B8: 4 | C8: 山内健登 | D8: =SUMIFS(5000m比較!$G$5:$G$34,5000m比較!$A$5:$A$34,$A8,5000m比較!$C$5:$C$34,$C8) -> 1 | E8: =SUMIFS(合宿走行距離!$C$5:$C$28,合宿走行距離!$A$5:$A$28,$A8,合宿走行距離!$B$5:$B$28,$C8) -> 569 | F8: =SUMIFS(合宿走行距離!$F$5:$F$28,合宿走行距離!$A$5:$A$28,$A8,合宿走行距離!$B$5:$B$28,$C8) -> 25.863636 | G8: =SUMIFS(合宿走行距離!$D$5:$D$28,合宿走行距離!$A$5:$A$28,$A8,合宿走行距離!$B$5:$B$28,$C8) -> 237 | H8: =E8+G8 -> 806 | I8: =SUMIFS(出雲区間記録!$M$5:$M$34,出雲区間記録!$A$5:$A$34,$A8,出雲区間記録!$B$5:$B$34,$B8) -> 0 | J8: =SUMIFS(5000m比較!$K$5:$K$34,5000m比較!$A$5:$A$34,$A8,5000m比較!$C$5:$C$34,$C8) -> 0.043883063
A9: 2023 | B9: 5 | C9: 鳥井健太 | D9: =SUMIFS(5000m比較!$G$5:$G$34,5000m比較!$A$5:$A$34,$A9,5000m比較!$C$5:$C$34,$C9) -> 9 | E9: =SUMIFS(合宿走行距離!$C$5:$C$28,合宿走行距離!$A$5:$A$28,$A9,合宿走行距離!$B$5:$B$28,$C9) -> 708 | F9: =SUMIFS(合宿走行距離!$F$5:$F$28,合宿走行距離!$A$5:$A$28,$A9,合宿走行距離!$B$5:$B$28,$C9) -> 32.181818 | G9: =SUMIFS(合宿走行距離!$D$5:$D$28,合宿走行距離!$A$5:$A$28,$A9,合宿走行距離!$B$5:$B$28,$C9) -> 271 | H9: =E9+G9 -> 979 | I9: =SUMIFS(出雲区間記録!$M$5:$M$34,出雲区間記録!$A$5:$A$34,$A9,出雲区間記録!$B$5:$B$34,$B9) -> 57.8 | J9: =SUMIFS(5000m比較!$K$5:$K$34,5000m比較!$A$5:$A$34,$A9,5000m比較!$C$5:$C$34,$C9) -> 0.095259449
A10: 2023 | B10: 6 | C10: 鶴川正也 | D10: =SUMIFS(5000m比較!$G$5:$G$34,5000m比較!$A$5:$A$34,$A10,5000m比較!$C$5:$C$34,$C10) -> 7 | E10: =SUMIFS(合宿走行距離!$C$5:$C$28,合宿走行距離!$A$5:$A$28,$A10,合宿走行距離!$B$5:$B$28,$C10) -> 459 | F10: =SUMIFS(合宿走行距離!$F$5:$F$28,合宿走行距離!$A$5:$A$28,$A10,合宿走行距離!$B$5:$B$28,$C10) -> 20.863636 | G10: =SUMIFS(合宿走行距離!$D$5:$D$28,合宿走行距離!$A$5:$A$28,$A10,合宿走行距離!$B$5:$B$28,$C10) -> 220 | H10: =E10+G10 -> 679 | I10: =SUMIFS(出雲区間記録!$M$5:$M$34,出雲区間記録!$A$5:$A$34,$A10,出雲区間記録!$B$5:$B$34,$B10) -> 82.4 | J10: =SUMIFS(5000m比較!$K$5:$K$34,5000m比較!$A$5:$A$34,$A10,5000m比較!$C$5:$C$34,$C10) -> 0.075617312
A11: 2024 | B11: 1 | C11: 鶴川正也 | D11: =SUMIFS(5000m比較!$G$5:$G$34,5000m比較!$A$5:$A$34,$A11,5000m比較!$C$5:$C$34,$C11) -> 1 | E11: =SUMIFS(合宿走行距離!$C$5:$C$28,合宿走行距離!$A$5:$A$28,$A11,合宿走行距離!$B$5:$B$28,$C11) -> 409 | F11: =SUMIFS(合宿走行距離!$F$5:$F$28,合宿走行距離!$A$5:$A$28,$A11,合宿走行距離!$B$5:$B$28,$C11) -> 21.526316 | G11: =SUMIFS(合宿走行距離!$D$5:$D$28,合宿走行距離!$A$5:$A$28,$A11,合宿走行距離!$B$5:$B$28,$C11) -> 202 | H11: =E11+G11 -> 611 | I11: =SUMIFS(出雲区間記録!$M$5:$M$34,出雲区間記録!$A$5:$A$34,$A11,出雲区間記録!$B$5:$B$34,$B11) -> 0 | J11: =SUMIFS(5000m比較!$K$5:$K$34,5000m比較!$A$5:$A$34,$A11,5000m比較!$C$5:$C$34,$C11) -> 0.067630642
A12: 2024 | B12: 2 | C12: 野村昭夢 | D12: =SUMIFS(5000m比較!$G$5:$G$34,5000m比較!$A$5:$A$34,$A12,5000m比較!$C$5:$C$34,$C12) -> 6 | E12: =SUMIFS(合宿走行距離!$C$5:$C$28,合宿走行距離!$A$5:$A$28,$A12,合宿走行距離!$B$5:$B$28,$C12) -> 485 | F12: =SUMIFS(合宿走行距離!$F$5:$F$28,合宿走行距離!$A$5:$A$28,$A12,合宿走行距離!$B$5:$B$28,$C12) -> 25.526316 | G12: =SUMIFS(合宿走行距離!$D$5:$D$28,合宿走行距離!$A$5:$A$28,$A12,合宿走行距離!$B$5:$B$28,$C12) -> 202 | H12: =E12+G12 -> 687 | I12: =SUMIFS(出雲区間記録!$M$5:$M$34,出雲区間記録!$A$5:$A$34,$A12,出雲区間記録!$B$5:$B$34,$B12) -> 39.7 | J12: =SUMIFS(5000m比較!$K$5:$K$34,5000m比較!$A$5:$A$34,$A12,5000m比較!$C$5:$C$34,$C12) -> 0.03129738
A13: 2024 | B13: 3 | C13: 黒田朝日 | D13: =SUMIFS(5000m比較!$G$5:$G$34,5000m比較!$A$5:$A$34,$A13,5000m比較!$C$5:$C$34,$C13) -> 3 | E13: =SUMIFS(合宿走行距離!$C$5:$C$28,合宿走行距離!$A$5:$A$28,$A13,合宿走行距離!$B$5:$B$28,$C13) -> 453 | F13: =SUMIFS(合宿走行距離!$F$5:$F$28,合宿走行距離!$A$5:$A$28,$A13,合宿走行距離!$B$5:$B$28,$C13) -> 23.842105 | G13: =SUMIFS(合宿走行距離!$D$5:$D$28,合宿走行距離!$A$5:$A$28,$A13,合宿走行距離!$B$5:$B$28,$C13) -> 206 | H13: =E13+G13 -> 659 | I13: =SUMIFS(出雲区間記録!$M$5:$M$34,出雲区間記録!$A$5:$A$34,$A13,出雲区間記録!$B$5:$B$34,$B13) -> 1.8 | J13: =SUMIFS(5000m比較!$K$5:$K$34,5000m比較!$A$5:$A$34,$A13,5000m比較!$C$5:$C$34,$C13) -> 0.029474538
A14: 2024 | B14: 4 | C14: 宇田川瞬矢 | D14: =SUMIFS(5000m比較!$G$5:$G$34,5000m比較!$A$5:$A$34,$A14,5000m比較!$C$5:$C$34,$C14) -> 5 | E14: =SUMIFS(合宿走行距離!$C$5:$C$28,合宿走行距離!$A$5:$A$28,$A14,合宿走行距離!$B$5:$B$28,$C14) -> 500 | F14: =SUMIFS(合宿走行距離!$F$5:$F$28,合宿走行距離!$A$5:$A$28,$A14,合宿走行距離!$B$5:$B$28,$C14) -> 26.315789 | G14: =SUMIFS(合宿走行距離!$D$5:$D$28,合宿走行距離!$A$5:$A$28,$A14,合宿走行距離!$B$5:$B$28,$C14) -> 199 | H14: =E14+G14 -> 699 | I14: =SUMIFS(出雲区間記録!$M$5:$M$34,出雲区間記録!$A$5:$A$34,$A14,出雲区間記録!$B$5:$B$34,$B14) -> 12.9 | J14: =SUMIFS(5000m比較!$K$5:$K$34,5000m比較!$A$5:$A$34,$A14,5000m比較!$C$5:$C$34,$C14) -> 0.063079886
A15: 2024 | B15: 5 | C15: 若林宏樹 | D15: =SUMIFS(5000m比較!$G$5:$G$34,5000m比較!$A$5:$A$34,$A15,5000m比較!$C$5:$C$34,$C15) -> 5 | E15: =SUMIFS(合宿走行距離!$C$5:$C$28,合宿走行距離!$A$5:$A$28,$A15,合宿走行距離!$B$5:$B$28,$C15) -> 536 | F15: =SUMIFS(合宿走行距離!$F$5:$F$28,合宿走行距離!$A$5:$A$28,$A15,合宿走行距離!$B$5:$B$28,$C15) -> 28.210526 | G15: =SUMIFS(合宿走行距離!$D$5:$D$28,合宿走行距離!$A$5:$A$28,$A15,合宿走行距離!$B$5:$B$28,$C15) -> 252 | H15: =E15+G15 -> 788 | I15: =SUMIFS(出雲区間記録!$M$5:$M$34,出雲区間記録!$A$5:$A$34,$A15,出雲区間記録!$B$5:$B$34,$B15) -> 21.9 | J15: =SUMIFS(5000m比較!$K$5:$K$34,5000m比較!$A$5:$A$34,$A15,5000m比較!$C$5:$C$34,$C15) -> 0.049525614
A16: 2024 | B16: 6 | C16: 太田蒼生 | D16: =SUMIFS(5000m比較!$G$5:$G$34,5000m比較!$A$5:$A$34,$A16,5000m比較!$C$5:$C$34,$C16) -> 3 | E16: =SUMIFS(合宿走行距離!$C$5:$C$28,合宿走行距離!$A$5:$A$28,$A16,合宿走行距離!$B$5:$B$28,$C16) -> 463 | F16: =SUMIFS(合宿走行距離!$F$5:$F$28,合宿走行距離!$A$5:$A$28,$A16,合宿走行距離!$B$5:$B$28,$C16) -> 24.368421 | G16: =SUMIFS(合宿走行距離!$D$5:$D$28,合宿走行距離!$A$5:$A$28,$A16,合宿走行距離!$B$5:$B$28,$C16) -> 201 | H16: =E16+G16 -> 664 | I16: =SUMIFS(出雲区間記録!$M$5:$M$34,出雲区間記録!$A$5:$A$34,$A16,出雲区間記録!$B$5:$B$34,$B16) -> 35.3 | J16: =SUMIFS(5000m比較!$K$5:$K$34,5000m比較!$A$5:$A$34,$A16,5000m比較!$C$5:$C$34,$C16) -> 0.036462506
... A28: 2026 | B28: 6 | C28: 前川竜之将 | D28: =SUMIFS(5000m比較!$G$5:$G$34,5000m比較!$A$5:$A$34,$A28,5000m比較!$C$5:$C$34,$C28) -> 9 | E28: =SUMIFS(合宿走行距離!$C$5:$C$28,合宿走行距離!$A$5:$A$28,$A28,合宿走行距離!$B$5:$B$28,$C28) -> 619 | F28: =SUMIFS(合宿走行距離!$F$5:$F$28,合宿走行距離!$A$5:$A$28,$A28,合宿走行距離!$B$5:$B$28,$C28) -> 34.388889 | G28: =SUMIFS(合宿走行距離!$D$5:$D$28,合宿走行距離!$A$5:$A$28,$A28,合宿走行距離!$B$5:$B$28,$C28) -> 248 | H28: =E28+G28 -> 867 | I28: =SUMIFS(出雲区間記録!$M$5:$M$34,出雲区間記録!$A$5:$A$34,$A28,出雲区間記録!$B$5:$B$34,$B28) -> 83.3 | J28: =SUMIFS(5000m比較!$K$5:$K$34,5000m比較!$A$5:$A$34,$A28,5000m比較!$C$5:$C$34,$C28) -> 0.092317269
A30: 年ごとの6人平均
A31: 年 | B31: 出雲 総合順位 | D31: 区間順位 平均 | E31: 1次合宿 (km) | F31: 1次 1日あたり (km) | G31: 2次合宿 (km) | H31: 1次+2次 合計(km) | I31: 日本人トップ との差(秒) | J31: 悪化率
A32: 2023 | B32: 4 | D32: =AVERAGEIFS($D$5:$D$28,$A$5:$A$28,$A32) -> 4.5 | E32: =AVERAGEIFS($E$5:$E$28,$A$5:$A$28,$A32) -> 575.25 | F32: =AVERAGEIFS($F$5:$F$28,$A$5:$A$28,$A32) -> 26.147727 | G32: =AVERAGEIFS($G$5:$G$28,$A$5:$A$28,$A32) -> 232.33333 | H32: =AVERAGEIFS($H$5:$H$28,$A$5:$A$28,$A32) -> 807.58333 | I32: =AVERAGEIFS($I$5:$I$28,$A$5:$A$28,$A32) -> 30.566667 | J32: =AVERAGEIFS($J$5:$J$28,$A$5:$A$28,$A32) -> 0.064307712
A33: 2024 | B33: 3 | D33: =AVERAGEIFS($D$5:$D$28,$A$5:$A$28,$A33) -> 3.8333333 | E33: =AVERAGEIFS($E$5:$E$28,$A$5:$A$28,$A33) -> 474.33333 | F33: =AVERAGEIFS($F$5:$F$28,$A$5:$A$28,$A33) -> 24.964912 | G33: =AVERAGEIFS($G$5:$G$28,$A$5:$A$28,$A33) -> 210.33333 | H33: =AVERAGEIFS($H$5:$H$28,$A$5:$A$28,$A33) -> 684.66667 | I33: =AVERAGEIFS($I$5:$I$28,$A$5:$A$28,$A33) -> 18.6 | J33: =AVERAGEIFS($J$5:$J$28,$A$5:$A$28,$A33) -> 0.046245094
A34: 2025 | B34: 7 | D34: =AVERAGEIFS($D$5:$D$28,$A$5:$A$28,$A34) -> 6 | E34: =AVERAGEIFS($E$5:$E$28,$A$5:$A$28,$A34) -> 578.66667 | F34: =AVERAGEIFS($F$5:$F$28,$A$5:$A$28,$A34) -> 30.45614 | G34: =AVERAGEIFS($G$5:$G$28,$A$5:$A$28,$A34) -> 230.5 | H34: =AVERAGEIFS($H$5:$H$28,$A$5:$A$28,$A34) -> 809.16667 | I34: =AVERAGEIFS($I$5:$I$28,$A$5:$A$28,$A34) -> 22.233333 | J34: =AVERAGEIFS($J$5:$J$28,$A$5:$A$28,$A34) -> 0.052597877
A35: 2026 | B35: 11 | D35: =AVERAGEIFS($D$5:$D$28,$A$5:$A$28,$A35) -> 8.1666667 | E35: =AVERAGEIFS($E$5:$E$28,$A$5:$A$28,$A35) -> 555.5 | F35: =AVERAGEIFS($F$5:$F$28,$A$5:$A$28,$A35) -> 30.861111 | G35: =AVERAGEIFS($G$5:$G$28,$A$5:$A$28,$A35) -> 227.66667 | H35: =AVERAGEIFS($H$5:$H$28,$A$5:$A$28,$A35) -> 783.16667 | I35: =AVERAGEIFS($I$5:$I$28,$A$5:$A$28,$A35) -> 34.183333 | J35: =AVERAGEIFS($J$5:$J$28,$A$5:$A$28,$A35) -> 0.051834792
A37: 区間順位との相関係数（延べ24人）
A38: 指標 | E38: 相関係数
A39: 1次合宿の距離 | E39: =CORREL(E5:E28,D5:D28) -> 0.21035603
A40: 1次合宿の1日あたり距離 | E40: =CORREL(F5:F28,D5:D28) -> 0.3528208
A41: 2次合宿の距離 | E41: =CORREL(G5:G28,D5:D28) -> 0.15882729
A42: 1次+2次の合計 | E42: =CORREL(H5:H28,D5:D28) -> 0.22112874
A43: 悪化率 | E43: =CORREL(J5:J28,D5:D28) -> 0.35779523
A44: ※正の値＝その指標が大きい選手ほど区間順位が悪い。2026年は順位・距離ともに全体が高く、年の影響が混ざっている点に注意
A46: 区間3位以内とそれ以外の比較
A47: 区分 | D47: 人数 | E47: 1次合宿 (km) | F47: 1次 1日あたり (km) | G47: 2次合宿 (km) | H47: 1次+2次 合計(km)
A48: 区間1〜3位 | D48: =COUNTIFS($D$5:$D$28,"<=3") -> 9 | E48: =AVERAGEIFS(E$5:E$28,$D$5:$D$28,"<=3") -> 529.94444 | F48: =AVERAGEIFS(F$5:F$28,$D$5:$D$28,"<=3") -> 26.678909 | G48: =AVERAGEIFS(G$5:G$28,$D$5:$D$28,"<=3") -> 216.77778 | H48: =AVERAGEIFS(H$5:H$28,$D$5:$D$28,"<=3") -> 746.72222
A49: 区間4位以下 | D49: =COUNTIFS($D$5:$D$28,">3") -> 15 | E49: =AVERAGEIFS(E$5:E$28,$D$5:$D$28,">3") -> 555.53333 | F49: =AVERAGEIFS(F$5:F$28,$D$5:$D$28,">3") -> 28.964611 | G49: =AVERAGEIFS(G$5:G$28,$D$5:$D$28,">3") -> 230.26667 | H49: =AVERAGEIFS(H$5:H$28,$D$5:$D$28,">3") -> 785.8

Sheet 合宿距離_上位35人
A1: 夏合宿 1日あたり走行距離 上位35人（2023〜2026）
A2: このシートのみ出雲メンバー以外の部員も含む（全部員の中での位置を見るため）。黄色の背景＝その年の出雲出走メンバー。1日あたり＝合宿距離÷日数（1次：2023年22日、2024・2025年19日、2026年18日／2次：各年10日、2026年チャレンジ組のみ12日）。2026年は女子選手を除く
A4: 1次合宿（km/日）
A5: 順位 | B5: 2023 7/26〜8/16 | C5: km/日 | E5: 2024 8/1〜8/19 | F5: km/日 | H5: 2025 8/1〜8/19 | I5: km/日 | K5: 2026 8/2〜8/19 | L5: km/日
A6: 1 | B6: 白石光星 | C6: 34.14 | E6: 塩出翔太 | F6: 34.63 | H6: 塩出翔太 | I6: 37.95 | K6: 折田壮太 | L6: 35.83
A7: 2 | B7: 志貴勇斗 | C7: 32.64 | E7: 本間創 | F7: 34.32 | H7: 福冨翔 | I7: 36.89 | K7: 松田煌希 | L7: 35.17
A8: 3 | B8: 鳥井健太 | C8: 32.18 | E8: 喜多村慧 | F8: 34.26 | H8: 笹川洸成 | I8: 33.16 | K8: 前川竜之将 | L8: 34.39
A9: 4 | B9: 佐藤有一 | C9: 31.23 | E9: 白石光星 | F9: 33.42 | H9: 熊井渓人 | I9: 32.89 | K9: 小河原陽琉 | L9: 34.22
A10: 5 | B10: 松下勇樹 | C10: 31.23 | E10: 村上直弥 | F10: 32.37 | H10: 村上直弥 | I10: 32.79 | K10: 田中智稀 | L10: 33.44
A11: 6 | B11: 阿戶将太朗 | C11: 31.09 | E11: 植村真登 | F11: 32.37 | H11: 佐々木大輝 | I11: 32.74 | K11: 福冨翔 | L11: 33.22
A12: 7 | B12: 松並昂勢 | C12: 30.14 | E12: 白石将隆 | F12: 32 | H12: 前川竜之将 | I12: 32.74 | K12: 鳥井健太 | L12: 33.06
A13: 8 | B13: 田中悠登 | C13: 30 | E13: 松下勇樹 | F13: 31.95 | H13: 小河原陽琉 | I13: 32.21 | K13: 中村海斗 | L13: 32.94
A14: 9 | B14: 喜多村慧 | C14: 29.64 | E14: 福冨翔 | F14: 31.53 | H14: 平松享祐 | I14: 31.58 | K14: 大竹実吹 | L14: 32.22
A15: 10 | B15: 笹川洸成 | C15: 29.55 | E15: 小河原陽琉 | F15: 31.37 | H15: 船越碧 | I15: 31.58 | K15: 本間創 | L15: 31.67
A16: 11 | B16: 佐藤一世 | C16: 29.41 | E16: 鳥井健太 | F16: 31.05 | H16: 神邑亮佑 | I16: 31.11 | K16: 花本史龍 | L16: 31.06
A17: 12 | B17: 池澤悠冬 | C17: 29.14 | E17: 浜川舜斗 | F17: 30.68 | H17: 植村真登 | I17: 31.05 | K17: 谷口僚哉 | L17: 30.89
... A40: 35 | B40: 岡本龍聖 | C40: 20.45 | E40: 太田蒼生 | F40: 24.37 | H40: 櫨元優馬 | I40: 23.05 | K40: 坂本康太 | L40: 24.33
A41: 平均 | C41: =AVERAGE(C6:C40) -> 27.412 | F41: =AVERAGE(F6:F40) -> 29.508286 | I41: =AVERAGE(I6:I40) -> 29.232 | L41: =AVERAGE(L6:L40) -> 29.456571
A44: 2次合宿（km/日）
A45: 順位 | B45: 2023 8/25〜9/3 | C45: km/日 | E45: 2024 8/27〜9/5 | F45: km/日 | H45: 2025 8/26〜9/4 | I45: km/日 | K45: 2026 選抜8/27〜9/5・チャレンジ8/26〜9/6 | L45: km/日
A46: 1 | B46: 村上直弥 | C46: 35 | E46: 喜多村慧 | F46: 29.5 | H46: 花本史龍 | I46: 28.2 | K46: 福冨翔 | L46: 28.4
A47: 2 | B47: 本間創 | C47: 34.4 | E47: 白石光星 | F47: 27.7 | H47: 塩出翔太 | I47: 26.6 | K47: 松田煌希 | L47: 27.8
A48: 3 | B48: 松下勇樹 | C48: 32.3 | E48: 村上直弥 | F48: 26.6 | H48: 福冨翔 | I48: 26.3 | K48: 佐々木大輝 | L48: 27.7
A49: 4 | B49: 喜多村慧 | C49: 32 | E49: 植村真登 | F49: 25.5 | H49: 佐々木大輝 | I49: 25.9 | K49: 大島福 | L49: 25.92
A50: 5 | B50: 白石将隆 | C50: 30.5 | E50: 若林宏樹 | F50: 25.2 | H50: 本間創 | I50: 25.5 | K50: 前川竜之将 | L50: 24.8
A51: 6 | B51: 池澤悠冬 | C51: 29.6 | E51: 本間創 | F51: 25.2 | H51: 大須賀風葵 | I51: 25.2 | K51: 本間創 | L51: 24
A52: 7 | B52: 多田奏太 | C52: 28.5 | E52: 大須賀風葵 | F52: 25.1 | H52: 佐藤有一 | I52: 25.1 | K52: 神邑亮佑 | L52: 23.8
A53: 8 | B53: 石原正翔 | C53: 27.6 | E53: 福冨翔 | F53: 25 | H53: 田中智稀 | I53: 25 | K53: 古川陽樹 | L53: 23.6
A54: 9 | B54: 野村昭夢 | C54: 27.2 | E54: 熊井渓人 | F54: 24.4 | H54: 宇田川瞬矢 | I54: 24.6 | K54: 鳥井健太 | L54: 23.3
A55: 10 | B55: 鳥井健太 | C55: 27.1 | E55: 平松享祐 | F55: 24.4 | H55: 徳本陽 | I55: 24.2 | K55: 小河原陽琉 | L55: 23
A56: 11 | B56: 笹川洸成 | C56: 27 | E56: 船越碧 | F56: 24.4 | H56: 石川浩輝 | I56: 24.2 | K56: 上野山拳士朗 | L56: 23
A57: 12 | B57: 花本史龍 | C57: 26.7 | E57: 石原正翔 | F57: 24.2 | H57: 中村海斗 | I57: 24 | K57: 坂本康太 | L57: 22.83
... A80: 35 | B80: 佐藤一世 | C80: 16 | E80: 鶴川正也 | F80: 20.2 | H80: 佐藤愛斗 | I80: 20.7 | K80: 斎藤晴樹 | L80: 20
A81: 平均 | C81: =AVERAGE(C46:C80) -> 25.539429 | F81: =AVERAGE(F46:F80) -> 23.337143 | I81: =AVERAGE(I46:I80) -> 23.468571 | L81: =AVERAGE(L46:L80) -> 22.768857

Sheet 合宿距離ランキング_全員
A1: 夏合宿 走行距離ランキング：全部員（1次・2次・1次+2次、2023〜2026年）
A2: 黄色の背景＝その年の出雲出走メンバー。同じ距離は同順位。1日あたり＝距離÷合宿日数（1次：2023年22日、2024・2025年19日、2026年18日／2次：各年10日、2026年チャレンジ組のみ12日）。※＝2次合宿の記録なし（1次のみで合計）。2026年の女子選手（芦田・池野）は除く。出典：各年の走行距離ランキング
A4: 2023年（出雲 総合4位） 1次合宿 7/26〜8/16（22日）／2次合宿 8/25〜9/3
A5: 順位 | B5: 1次合宿 | C5: km | D5: km/日 | F5: 順位 | G5: 2次合宿 | H5: km | I5: km/日 | K5: 順位 | L5: 1次+2次 | M5: km
A6: 1 | B6: 白石光星 | C6: 751 | D6: =C6/22 -> 34.136364 | F6: 1 | G6: 村上直弥 | H6: 350 | I6: =H6/10 -> 35 | K6: 1 | L6: 松下勇樹 | M6: 1010
A7: 2 | B7: 志貴勇斗 | C7: 718 | D7: =C7/22 -> 32.636364 | F7: 2 | G7: 本間創 | H7: 344 | I7: =H7/10 -> 34.4 | K7: 2 | L7: 鳥井健太 | M7: 979
A8: 3 | B8: 鳥井健太 | C8: 708 | D8: =C8/22 -> 32.181818 | F8: 3 | G8: 松下勇樹 | H8: 323 | I8: =H8/10 -> 32.3 | K8: 3 | L8: 喜多村慧 | M8: 972
A9: 4 | B9: 佐藤有一 | C9: 687 | D9: =C9/22 -> 31.227273 | F9: 4 | G9: 喜多村慧 | H9: 320 | I9: =H9/10 -> 32 | K9: 4 | L9: 村上直弥 | M9: 960
A10: 4 | B10: 松下勇樹 | C10: 687 | D10: =C10/22 -> 31.227273 | F10: 5 | G10: 白石将隆 | H10: 305 | I10: =H10/10 -> 30.5 | K10: 5 | L10: 佐藤有一 | M10: 952
A11: 6 | B11: 阿戶将太朗 | C11: 684 | D11: =C11/22 -> 31.090909 | F11: 6 | G11: 池澤悠冬 | H11: 296 | I11: =H11/10 -> 29.6 | K11: 6 | L11: 池澤悠冬 | M11: 937
A12: 7 | B12: 松並昂勢 | C12: 663 | D12: =C12/22 -> 30.136364 | F12: 7 | G12: 多田奏太 | H12: 285 | I12: =H12/10 -> 28.5 | K12: 7 | L12: 笹川洸成 | M12: 920
A13: 8 | B13: 田中悠登 | C13: 660 | D13: =C13/22 -> 30 | F13: 8 | G13: 石原正翔 | H13: 276 | I13: =H13/10 -> 27.6 | K13: 8 | L13: 志貴勇斗 | M13: 918
A14: 9 | B14: 喜多村慧 | C14: 652 | D14: =C14/22 -> 29.636364 | F14: 9 | G14: 野村昭夢 | H14: 272 | I14: =H14/10 -> 27.2 | K14: 9 | L14: 田中悠登 | M14: 912
A15: 10 | B15: 笹川洸成 | C15: 650 | D15: =C15/22 -> 29.545455 | F15: 10 | G15: 鳥井健太 | H15: 271 | I15: =H15/10 -> 27.1 | K15: 9 | L15: 石原正翔 | M15: 912
A16: 11 | B16: 佐藤一世 | C16: 647 | D16: =C16/22 -> 29.409091 | F16: 11 | G16: 笹川洸成 | H16: 270 | I16: =H16/10 -> 27 | K16: 11 | L16: 松並昂勢 | M16: 910
A17: 12 | B17: 池澤悠冬 | C17: 641 | D17: =C17/22 -> 29.136364 | F17: 12 | G17: 花本史龍 | H17: 267 | I17: =H17/10 -> 26.7 | K17: 12 | L17: 多田奏太 | M17: 903
... A47: 42 | B47: 徳丸涼大 | C47: 99 | D47: =C47/22 -> 4.5 | F47: 42 | G47: 鈴木千翔 | H47: 3 | I47: =H47/10 -> 0.3 | K47: 42 | L47: 若林宏樹 | M47: 269.8
A48: 43 | B48: 若林宏樹 | C48: 52 | D48: =C48/22 -> 2.3636364 | K48: 43 | L48: 皆渡星七 | M48: 148
A49: 43 | B49: 皆渡星七 | C49: 52 | D49: =C49/22 -> 2.3636364 | K49: 44 | L49: 徳丸涼大 | M49: 107
A50: 45 | B50: 池田知史 | C50: 0 | D50: =C50/22 -> 0 | K50: 45 | L50: 池田知史 | M50: 20
A51: 45 | B51: 鈴木千翔 | C51: 0 | D51: =C51/22 -> 0 | K51: 46 | L51: 鈴木千翔 | M51: 3
B52: 平均 | C52: =AVERAGE(C6:C51) -> 507.93696 | D52: =AVERAGE(D6:D51) -> 23.088043 | G52: 平均 | H52: =AVERAGE(H6:H51) -> 224.9 | I52: =AVERAGE(I6:I51) -> 22.49 | L52: 平均 | M52: =AVERAGE(M6:M51) -> 713.28043
A55: 2024年（出雲 総合3位） 1次合宿 8/1〜8/19（19日）／2次合宿 8/27〜9/5
A56: 順位 | B56: 1次合宿 | C56: km | D56: km/日 | F56: 順位 | G56: 2次合宿 | H56: km | I56: km/日 | K56: 順位 | L56: 1次+2次 | M56: km
A57: 1 | B57: 塩出翔太 | C57: 658 | D57: =C57/19 -> 34.631579 | F57: 1 | G57: 喜多村慧 | H57: 295 | I57: =H57/10 -> 29.5 | K57: 1 | L57: 喜多村慧 | M57: 946
A58: 2 | B58: 本間創 | C58: 652 | D58: =C58/19 -> 34.315789 | F58: 2 | G58: 白石光星 | H58: 277 | I58: =H58/10 -> 27.7 | K58: 2 | L58: 白石光星 | M58: 912
A59: 3 | B59: 喜多村慧 | C59: 651 | D59: =C59/19 -> 34.263158 | F59: 3 | G59: 村上直弥 | H59: 266 | I59: =H59/10 -> 26.6 | K59: 3 | L59: 本間創 | M59: 904
A60: 4 | B60: 白石光星 | C60: 635 | D60: =C60/19 -> 33.421053 | F60: 4 | G60: 植村真登 | H60: 255 | I60: =H60/10 -> 25.5 | K60: 4 | L60: 村上直弥 | M60: 881
A61: 5 | B61: 村上直弥 | C61: 615 | D61: =C61/19 -> 32.368421 | F61: 5 | G61: 若林宏樹 | H61: 252 | I61: =H61/10 -> 25.2 | K61: 5 | L61: 塩出翔太 | M61: 878
A62: 5 | B62: 植村真登 | C62: 615 | D62: =C62/19 -> 32.368421 | F62: 5 | G62: 本間創 | H62: 252 | I62: =H62/10 -> 25.2 | K62: 6 | L62: 植村真登 | M62: 870
A63: 7 | B63: 白石将隆 | C63: 608 | D63: =C63/19 -> 32 | F63: 7 | G63: 大須賀風葵 | H63: 251 | I63: =H63/10 -> 25.1 | K63: 7 | L63: 福冨翔 | M63: 849
A64: 8 | B64: 松下勇樹 | C64: 607 | D64: =C64/19 -> 31.947368 | F64: 8 | G64: 福冨翔 | H64: 250 | I64: =H64/10 -> 25 | K64: 8 | L64: 白石将隆 | M64: 844
A65: 9 | B65: 福冨翔 | C65: 599 | D65: =C65/19 -> 31.526316 | F65: 9 | G65: 熊井渓人 | H65: 244 | I65: =H65/10 -> 24.4 | K65: 9 | L65: 小河原陽琉 | M65: 829
A66: 10 | B66: 小河原陽琉 | C66: 596 | D66: =C66/19 -> 31.368421 | F66: 9 | G66: 平松享祐 | H66: 244 | I66: =H66/10 -> 24.4 | K66: 10 | L66: 平松享祐 | M66: 824
A67: 11 | B67: 鳥井健太 | C67: 590 | D67: =C67/19 -> 31.052632 | F67: 9 | G67: 船越碧 | H67: 244 | I67: =H67/10 -> 24.4 | K67: 11 | L67: 浜川舜斗 | M67: 821
A68: 12 | B68: 浜川舜斗 | C68: 583 | D68: =C68/19 -> 30.684211 | F68: 12 | G68: 石原正翔 | H68: 242 | I68: =H68/10 -> 24.2 | K68: 12 | L68: 池澤悠冬 | M68: 809
... A103: 47 | B103: 佐々木大輝 | C103: 98.5 | D103: =C103/19 -> 5.1842105 | F103: 47 | G103: 鈴木千翔 | H103: 106.5 | I103: =H103/10 -> 10.65 | K103: 47 | L103: 佐々木大輝 | M103: 326.5
B104: 平均 | C104: =AVERAGE(C57:C103) -> 510.58511 | D104: =AVERAGE(D57:D103) -> 26.8729 | G104: 平均 | H104: =AVERAGE(H57:H103) -> 217.71277 | I104: =AVERAGE(I57:I103) -> 21.771277 | L104: 平均 | M104: =AVERAGE(M57:M103) -> 728.29787
A107: 2025年（出雲 総合7位） 1次合宿 8/1〜8/19（19日）／2次合宿 8/26〜9/4
A108: 順位 | B108: 1次合宿 | C108: km | D108: km/日 | F108: 順位 | G108: 2次合宿 | H108: km | I108: km/日 | K108: 順位 | L108: 1次+2次 | M108: km
...

Sheet チーム平均推移
A1: チーム平均の走行距離の推移（夏合宿・月間）
A2: 合宿のチーム平均・選抜組／チャレンジ組平均と月間のチーム平均は、元資料に記載の値（出典：各年の走行距離ランキング、月間走行距離Excel）。上位35人平均は全部員の選手別データから算出（2026年は女子選手を除く）。1日あたり＝距離÷合宿日数
A4: 年 | B4: 出雲 総合順位 | C4: 1次合宿 期間 | D4: 1次 日数 | E4: 1次 チーム平均 (km) | F4: 1次 チーム平均 1日あたり | G4: 1次 上位35人 1日あたり | H4: 1次 出雲メンバー 1日あたり | I4: メンバーの チーム比 (1日あたり) | J4: 2次 チーム全体 平均(km) | K4: 2次 選抜組 平均(km) | L4: 2次 チャレンジ組 平均(km)
A5: 2023 | B5: 4 | C5: 7/26〜8/16 | D5: 22 | E5: 507.9 | F5: =E5/D5 -> 23.086364 | G5: 27.41 | H5: =AVERAGEIFS(合宿走行距離!$F$5:$F$28,合宿走行距離!$A$5:$A$28,A5) -> 26.147727 | I5: =H5/F5 -> 1.1326048 | J5: 228.3 | K5: 226 | L5: 226.1
A6: 2024 | B6: 3 | C6: 8/1〜8/19 | D6: 19 | E6: 510.6 | F6: =E6/D6 -> 26.873684 | G6: 29.51 | H6: =AVERAGEIFS(合宿走行距離!$F$5:$F$28,合宿走行距離!$A$5:$A$28,A6) -> 24.964912 | I6: =H6/F6 -> 0.92897245 | J6: 217.7 | K6: 214 | L6: 223.6
A7: 2025 | B7: 7 | C7: 8/1〜8/19 | D7: 19 | E7: 481 | F7: =E7/D7 -> 25.315789 | G7: 29.23 | H7: =AVERAGEIFS(合宿走行距離!$F$5:$F$28,合宿走行距離!$A$5:$A$28,A7) -> 30.45614 | I7: =H7/F7 -> 1.2030492 | J7: 216.4 | K7: 222.4 | L7: 204.8
A8: 2026 | B8: 11 | C8: 8/2〜8/19 | D8: 18 | E8: 460 | F8: =E8/D8 -> 25.555556 | G8: 29.46 | H8: =AVERAGEIFS(合宿走行距離!$F$5:$F$28,合宿走行距離!$A$5:$A$28,A8) -> 30.861111 | I8: =H8/F8 -> 1.2076087 | K8: 226.4 | L8: 213.2
A10: 月間走行距離のチーム平均（km）
A11: 年 | B11: 1月 | C11: 2月 | D11: 3月 | E11: 4月 | F11: 5月 | G11: 6月 | H11: 7月 | I11: 8月 | J11: 9月 | K11: 10月 | L11: 11月 | M11: 12月
A12: 2022 | B12: 282 | C12: 307 | D12: 353 | E12: 303 | F12: 323 | G12: 332 | H12: 326 | I12: 599 | J12: 346 | K12: 425 | L12: 345 | M12: 408
A13: 2023 | B13: 315 | C13: 344 | D13: 366 | E13: 313 | F13: 387 | G13: 365 | H13: 389 | I13: 586 | J13: 449 | K13: 414 | L13: 345
A14: 2024 | B14: 263 | C14: 318 | D14: 399 | E14: 272 | F14: 340 | G14: 397
A15: ※2023年12月、2024年7月以降、2025・2026年は未提供

Sheet 合宿消化率
A1: 夏合宿 消化率（1〜3次）：出雲メンバー
A2: 出雲出走メンバーのみ。消化率はポイント練習の実施度（100%＝全メニュー完遂）。出典：各年の合宿消化率（2023・2025年はExcel、2024・2026年はPDF）
A4: 年 | B4: 選手 | C4: 1次合宿 | D4: 2次合宿 | E4: 3次合宿 | F4: 夏合宿 平均 | G4: 出雲 区間
A5: 2023 | B5: 野村昭夢 | C5: 0.614 | D5: 1 | E5: 1 | F5: =IFERROR(AVERAGE(C5:E5),"") -> 0.87133333 | G5: =SUMIFS(5000m比較!$B$5:$B$34,5000m比較!$A$5:$A$34,A5,5000m比較!$C$5:$C$34,B5) -> 1
A6: 2023 | B6: 黒田朝日 | C6: 0.9 | D6: 1 | E6: 1 | F6: =IFERROR(AVERAGE(C6:E6),"") -> 0.96666667 | G6: =SUMIFS(5000m比較!$B$5:$B$34,5000m比較!$A$5:$A$34,A6,5000m比較!$C$5:$C$34,B6) -> 2
A7: 2023 | B7: 佐藤一世 | C7: 1 | D7: 0.825 | E7: 0.925 | F7: =IFERROR(AVERAGE(C7:E7),"") -> 0.91666667 | G7: =SUMIFS(5000m比較!$B$5:$B$34,5000m比較!$A$5:$A$34,A7,5000m比較!$C$5:$C$34,B7) -> 3
A8: 2023 | B8: 山内健登 | C8: 1 | D8: 1 | E8: 1 | F8: =IFERROR(AVERAGE(C8:E8),"") -> 1 | G8: =SUMIFS(5000m比較!$B$5:$B$34,5000m比較!$A$5:$A$34,A8,5000m比較!$C$5:$C$34,B8) -> 4
A9: 2023 | B9: 鳥井健太 | C9: 1 | D9: 1 | E9: 1 | F9: =IFERROR(AVERAGE(C9:E9),"") -> 1 | G9: =SUMIFS(5000m比較!$B$5:$B$34,5000m比較!$A$5:$A$34,A9,5000m比較!$C$5:$C$34,B9) -> 5
A10: 2023 | B10: 鶴川正也 | C10: 0.414 | D10: 0.925 | E10: 0.75 | F10: =IFERROR(AVERAGE(C10:E10),"") -> 0.69633333 | G10: =SUMIFS(5000m比較!$B$5:$B$34,5000m比較!$A$5:$A$34,A10,5000m比較!$C$5:$C$34,B10) -> 6
A11: 2024 | B11: 鶴川正也 | C11: 1 | D11: 0.825 | E11: 1 | F11: =IFERROR(AVERAGE(C11:E11),"") -> 0.94166667 | G11: =SUMIFS(5000m比較!$B$5:$B$34,5000m比較!$A$5:$A$34,A11,5000m比較!$C$5:$C$34,B11) -> 1
A12: 2024 | B12: 野村昭夢 | C12: 1 | D12: 1 | E12: 1 | F12: =IFERROR(AVERAGE(C12:E12),"") -> 1 | G12: =SUMIFS(5000m比較!$B$5:$B$34,5000m比較!$A$5:$A$34,A12,5000m比較!$C$5:$C$34,B12) -> 2
A13: 2024 | B13: 黒田朝日 | C13: 1 | D13: 1 | E13: 1 | F13: =IFERROR(AVERAGE(C13:E13),"") -> 1 | G13: =SUMIFS(5000m比較!$B$5:$B$34,5000m比較!$A$5:$A$34,A13,5000m比較!$C$5:$C$34,B13) -> 3
A14: 2024 | B14: 宇田川瞬矢 | C14: 1 | D14: 0.975 | E14: 1 | F14: =IFERROR(AVERAGE(C14:E14),"") -> 0.99166667 | G14: =SUMIFS(5000m比較!$B$5:$B$34,5000m比較!$A$5:$A$34,A14,5000m比較!$C$5:$C$34,B14) -> 4
A15: 2024 | B15: 若林宏樹 | C15: 0.825 | D15: 1 | E15: 1 | F15: =IFERROR(AVERAGE(C15:E15),"") -> 0.94166667 | G15: =SUMIFS(5000m比較!$B$5:$B$34,5000m比較!$A$5:$A$34,A15,5000m比較!$C$5:$C$34,B15) -> 5
A16: 2024 | B16: 太田蒼生 | C16: 0.925 | D16: 1 | E16: 0.925 | F16: =IFERROR(AVERAGE(C16:E16),"") -> 0.95 | G16: =SUMIFS(5000m比較!$B$5:$B$34,5000m比較!$A$5:$A$34,A16,5000m比較!$C$5:$C$34,B16) -> 6
... A28: 2026 | B28: 前川竜之将 | C28: 1 | D28: 1 | E28: 0.98 | F28: =IFERROR(AVERAGE(C28:E28),"") -> 0.99333333 | G28: =SUMIFS(5000m比較!$B$5:$B$34,5000m比較!$A$5:$A$34,A28,5000m比較!$C$5:$C$34,B28) -> 6

Sheet 月間走行距離
A1: 月間走行距離：出雲メンバー（2022・2023年は通年、2024年は1〜6月のみ）
A2: 出雲出走メンバーのみ。出典：月間走行距離Excel。2024年7月以降と2025・2026年はデータ未提供
A4: 年 | B4: 選手 | C4: 1月 | D4: 2月 | E4: 3月 | F4: 4月 | G4: 5月 | H4: 6月 | I4: 7月 | J4: 8月 | K4: 9月 | L4: 10月 | M4: 11月 | N4: 12月 | O4: 9月÷8月 | P4: 出雲 区間
A5: 2022 | B5: 目片将大 | C5: 286 | D5: 405 | E5: 489 | G5: 369 | H5: 404 | I5: 344 | J5: 674 | K5: 373 | L5: 443 | M5: 384 | N5: 478 | O5: =IF(OR(J5="",K5="",J5=0),"",K5/J5) -> 0.55341246 | P5: =SUMIFS(5000m比較!$B$5:$B$34,5000m比較!$A$5:$A$34,A5,5000m比較!$C$5:$C$34,B5) -> 1
A6: 2022 | B6: 横田俊吾 | C6: 370 | D6: 303 | E6: 237 | F6: 363 | G6: 421 | H6: 396 | I6: 394 | J6: 710 | K6: 384 | L6: 415 | M6: 432 | N6: 430 | O6: =IF(OR(J6="",K6="",J6=0),"",K6/J6) -> 0.54084507 | P6: =SUMIFS(5000m比較!$B$5:$B$34,5000m比較!$A$5:$A$34,A6,5000m比較!$C$5:$C$34,B6) -> 2
A7: 2022 | B7: 近藤幸太郎 | C7: 321 | D7: 23 | E7: 314 | F7: 373 | G7: 191 | H7: 169 | I7: 408 | J7: 638 | K7: 510 | L7: 430 | M7: 479 | N7: 450 | O7: =IF(OR(J7="",K7="",J7=0),"",K7/J7) -> 0.79937304 | P7: =SUMIFS(5000m比較!$B$5:$B$34,5000m比較!$A$5:$A$34,A7,5000m比較!$C$5:$C$34,B7) -> 3
A8: 2022 | B8: 志貴勇斗 | C8: 126 | D8: 411 | E8: 446 | F8: 274 | G8: 305 | H8: 384 | I8: 336 | J8: 698 | K8: 384 | L8: 350 | M8: 415 | N8: 448 | O8: =IF(OR(J8="",K8="",J8=0),"",K8/J8) -> 0.55014327 | P8: =SUMIFS(5000m比較!$B$5:$B$34,5000m比較!$A$5:$A$34,A8,5000m比較!$C$5:$C$34,B8) -> 4
A9: 2022 | B9: 田中悠登 | C9: 348 | D9: 411 | E9: 503 | F9: 345 | G9: 274 | H9: 359 | I9: 337 | J9: 630 | K9: 310 | L9: 494 | M9: 341 | N9: 491 | O9: =IF(OR(J9="",K9="",J9=0),"",K9/J9) -> 0.49206349 | P9: =SUMIFS(5000m比較!$B$5:$B$34,5000m比較!$A$5:$A$34,A9,5000m比較!$C$5:$C$34,B9) -> 5
A10: 2022 | B10: 中村唯翔 | C10: 138 | D10: 345 | E10: 439 | F10: 344 | G10: 63 | H10: 437 | I10: 405 | J10: 701 | K10: 420 | L10: 390 | M10: 415 | N10: 345 | O10: =IF(OR(J10="",K10="",J10=0),"",K10/J10) -> 0.59914408 | P10: =SUMIFS(5000m比較!$B$5:$B$34,5000m比較!$A$5:$A$34,A10,5000m比較!$C$5:$C$34,B10) -> 6
A11: 2023 | B11: 野村昭夢 | C11: 112 | D11: 177 | E11: 315 | F11: 501 | H11: 85 | I11: 303 | J11: 652 | K11: 477 | L11: 100 | M11: 415 | O11: =IF(OR(J11="",K11="",J11=0),"",K11/J11) -> 0.73159509 | P11: =SUMIFS(5000m比較!$B$5:$B$34,5000m比較!$A$5:$A$34,A11,5000m比較!$C$5:$C$34,B11) -> 1
A12: 2023 | B12: 黒田朝日 | C12: 380 | D12: 132 | E12: 462 | F12: 471 | G12: 293 | H12: 352.5 | I12: 365 | J12: 626 | K12: 435.8 | O12: =IF(OR(J12="",K12="",J12=0),"",K12/J12) -> 0.69616613 | P12: =SUMIFS(5000m比較!$B$5:$B$34,5000m比較!$A$5:$A$34,A12,5000m比較!$C$5:$C$34,B12) -> 2
A13: 2023 | B13: 佐藤一世 | C13: 207 | D13: 397 | F13: 305 | G13: 363 | H13: 389 | I13: 478 | J13: 639 | K13: 412 | L13: 398 | M13: 338 | O13: =IF(OR(J13="",K13="",J13=0),"",K13/J13) -> 0.64475743 | P13: =SUMIFS(5000m比較!$B$5:$B$34,5000m比較!$A$5:$A$34,A13,5000m比較!$C$5:$C$34,B13) -> 3
A14: 2023 | B14: 山内健登 | C14: 353 | D14: 320 | E14: 390 | F14: 319 | G14: 290 | I14: 474 | J14: 611 | K14: 467 | L14: 440 | O14: =IF(OR(J14="",K14="",J14=0),"",K14/J14) -> 0.76432079 | P14: =SUMIFS(5000m比較!$B$5:$B$34,5000m比較!$A$5:$A$34,A14,5000m比較!$C$5:$C$34,B14) -> 4
A15: 2023 | B15: 鳥井健太 | E15: 441 | F15: 232 | G15: 346 | H15: 354 | I15: 402 | J15: 672 | K15: 502 | L15: 408 | M15: 352.6 | O15: =IF(OR(J15="",K15="",J15=0),"",K15/J15) -> 0.74702381 | P15: =SUMIFS(5000m比較!$B$5:$B$34,5000m比較!$A$5:$A$34,A15,5000m比較!$C$5:$C$34,B15) -> 5
A16: 2023 | B16: 鶴川正也 | C16: 400 | D16: 430 | E16: 80 | F16: 440 | G16: 463 | H16: 137 | I16: 168 | J16: 618 | K16: 515 | L16: 402 | M16: 184 | O16: =IF(OR(J16="",K16="",J16=0),"",K16/J16) -> 0.83333333 | P16: =SUMIFS(5000m比較!$B$5:$B$34,5000m比較!$A$5:$A$34,A16,5000m比較!$C$5:$C$34,B16) -> 6
A17: 2024 | B17: 鶴川正也 | C17: 284 | D17: 423 | E17: 470 | F17: 0 | G17: 358 | H17: 364 | O17: =IF(OR(J17="",K17="",J17=0),"",K17/J17) | P17: =SUMIFS(5000m比較!$B$5:$B$34,5000m比較!$A$5:$A$34,A17,5000m比較!$C$5:$C$34,B17) -> 1
A18: 2024 | B18: 野村昭夢 | C18: 103 | D18: 134 | E18: 438 | F18: 421 | G18: 403 | H18: 407 | O18: =IF(OR(J18="",K18="",J18=0),"",K18/J18) | P18: =SUMIFS(5000m比較!$B$5:$B$34,5000m比較!$A$5:$A$34,A18,5000m比較!$C$5:$C$34,B18) -> 2
A19: 2024 | B19: 黒田朝日 | C19: 0 | D19: 0 | E19: 0 | F19: 0 | G19: 326 | H19: 307.5 | O19: =IF(OR(J19="",K19="",J19=0),"",K19/J19) | P19: =SUMIFS(5000m比較!$B$5:$B$34,5000m比較!$A$5:$A$34,A19,5000m比較!$C$5:$C$34,B19) -> 3
A20: 2024 | B20: 宇田川瞬矢 | C20: 175 | D20: 210 | E20: 452.1 | F20: 416 | G20: 425 | H20: 230 | O20: =IF(OR(J20="",K20="",J20=0),"",K20/J20) | P20: =SUMIFS(5000m比較!$B$5:$B$34,5000m比較!$A$5:$A$34,A20,5000m比較!$C$5:$C$34,B20) -> 4
A21: 2024 | B21: 若林宏樹 | C21: 265 | D21: 415.2 | E21: 387.8 | F21: 0 | G21: 275.3 | H21: 400.7 | O21: =IF(OR(J21="",K21="",J21=0),"",K21/J21) | P21: =SUMIFS(5000m比較!$B$5:$B$34,5000m比較!$A$5:$A$34,A21,5000m比較!$C$5:$C$34,B21) -> 5
A22: 2024 | B22: 太田蒼生 | C22: 156 | D22: 182 | E22: 384 | F22: 0 | G22: 463 | H22: 570 | O22: =IF(OR(J22="",K22="",J22=0),"",K22/J22) | P22: =SUMIFS(5000m比較!$B$5:$B$34,5000m比較!$A$5:$A$34,A22,5000m比較!$C$5:$C$34,B22) -> 6

Sheet 区間順位との相関
A1: 区間順位と各項目の相関（出雲メンバー延べ12〜30人）
A2: 相関係数は「選手一覧」シートからCORREL関数で計算（空欄の選手は除外）。正の値＝その値が大きい選手ほど区間順位が悪い。年の影響を除いた相関＝各年の6人の平均との差どうしで計算した値。偶然の可能性＝相関が偶然に生じる確率（両側p値）。この2列はPythonで計算した値
A4: 項目 | C4: 人数 | D4: 相関係数 | E4: 年の影響を 除いた相関 | F4: 偶然の可能性 （そのまま） | G4: 偶然の可能性 （年の影響除去後） | H4: 判定
A5: 2週間前5000mのタイム | C5: =SUMPRODUCT((選手一覧!$K$6:$K$35<>"")*(選手一覧!$G$6:$G$35<>"")) -> 30 | D5: =CORREL(選手一覧!$K$6:$K$35,選手一覧!$G$6:$G$35) -> 0.046254567 | E5: 0.347 | F5: 0.8082 | G5: 0.0822 | H5: 関係ありそう（5〜10%）
A6: 2週間前5000mの組内順位 | C6: =SUMPRODUCT((選手一覧!$M$6:$M$35<>"")*(選手一覧!$G$6:$G$35<>"")) -> 30 | D6: =CORREL(選手一覧!$M$6:$M$35,選手一覧!$G$6:$G$35) -> 0.43040679 | E6: 0.386 | F6: 0.0176 | G6: 0.0516 | H6: 関係あり（5%未満）
A7: 悪化率 | C7: =SUMPRODUCT((選手一覧!$O$6:$O$35<>"")*(選手一覧!$G$6:$G$35<>"")) -> 30 | D7: =CORREL(選手一覧!$O$6:$O$35,選手一覧!$G$6:$G$35) -> 0.37273291 | E7: 0.413 | F7: 0.0425 | G7: 0.0359 | H7: 関係あり（5%未満）
A8: 区間（何区か） | C8: =SUMPRODUCT((選手一覧!$B$6:$B$35<>"")*(選手一覧!$G$6:$G$35<>"")) -> 30 | D8: =CORREL(選手一覧!$B$6:$B$35,選手一覧!$G$6:$G$35) -> 0.061448838 | E8: 0.071 | F8: 0.747 | G8: 0.7299 | H8: 関係は弱い・なし
A9: 1次合宿の距離 | C9: =SUMPRODUCT((選手一覧!$P$6:$P$35<>"")*(選手一覧!$G$6:$G$35<>"")) -> 24 | D9: =CORREL(選手一覧!$P$6:$P$35,選手一覧!$G$6:$G$35) -> 0.21035603 | E9: 0.119 | F9: 0.3238 | G9: 0.608 | H9: 関係は弱い・なし
A10: 1次合宿の1日あたり距離 | C10: =SUMPRODUCT((選手一覧!$Q$6:$Q$35<>"")*(選手一覧!$G$6:$G$35<>"")) -> 24 | D10: =CORREL(選手一覧!$Q$6:$Q$35,選手一覧!$G$6:$G$35) -> 0.3528208 | E10: 0.117 | F10: 0.0908 | G10: 0.6133 | H10: 関係ありそう（5〜10%）
A11: 2次合宿の距離 | C11: =SUMPRODUCT((選手一覧!$S$6:$S$35<>"")*(選手一覧!$G$6:$G$35<>"")) -> 24 | D11: =CORREL(選手一覧!$S$6:$S$35,選手一覧!$G$6:$G$35) -> 0.15882729 | E11: 0.099 | F11: 0.4585 | G11: 0.6709 | H11: 関係は弱い・なし
A12: 1次+2次の合計 | C12: =SUMPRODUCT((選手一覧!$V$6:$V$35<>"")*(選手一覧!$G$6:$G$35<>"")) -> 24 | D12: =CORREL(選手一覧!$V$6:$V$35,選手一覧!$G$6:$G$35) -> 0.22112874 | E12: 0.131 | F12: 0.2991 | G12: 0.57 | H12: 関係は弱い・なし
A13: 1次合宿の消化率 | C13: =SUMPRODUCT((選手一覧!$W$6:$W$35<>"")*(選手一覧!$G$6:$G$35<>"")) -> 24 | D13: =CORREL(選手一覧!$W$6:$W$35,選手一覧!$G$6:$G$35) -> -0.15874448 | E13: -0.261 | F13: 0.4588 | G13: 0.2531 | H13: 関係は弱い・なし
A14: 2次合宿の消化率 | C14: =SUMPRODUCT((選手一覧!$X$6:$X$35<>"")*(選手一覧!$G$6:$G$35<>"")) -> 24 | D14: =CORREL(選手一覧!$X$6:$X$35,選手一覧!$G$6:$G$35) -> 0.28963451 | E14: 0.164 | F14: 0.1698 | G14: 0.4762 | H14: 関係は弱い・なし
A15: 3次合宿の消化率 | C15: =SUMPRODUCT((選手一覧!$Y$6:$Y$35<>"")*(選手一覧!$G$6:$G$35<>"")) -> 24 | D15: =CORREL(選手一覧!$Y$6:$Y$35,選手一覧!$G$6:$G$35) -> -0.0040347276 | E15: -0.135 | F15: 0.9851 | G15: 0.5596 | H15: 関係は弱い・なし
A16: 夏合宿の消化率（平均） | C16: =SUMPRODUCT((選手一覧!$Z$6:$Z$35<>"")*(選手一覧!$G$6:$G$35<>"")) -> 24 | D16: =CORREL(選手一覧!$Z$6:$Z$35,選手一覧!$G$6:$G$35) -> -0.049294624 | E16: -0.199 | F16: 0.8191 | G16: 0.3864 | H16: 関係は弱い・なし
A17: 7月の月間走行距離 | C17: =SUMPRODUCT((選手一覧!$AA$6:$AA$35<>"")*(選手一覧!$G$6:$G$35<>"")) -> 12 | D17: =CORREL(選手一覧!$AA$6:$AA$35,選手一覧!$G$6:$G$35) -> -0.51781115 | E17: -0.517 | F17: 0.0846 | G17: 0.1035 | H17: 関係ありそう（5〜10%）
A18: 8月の月間走行距離 | C18: =SUMPRODUCT((選手一覧!$AB$6:$AB$35<>"")*(選手一覧!$G$6:$G$35<>"")) -> 12 | D18: =CORREL(選手一覧!$AB$6:$AB$35,選手一覧!$G$6:$G$35) -> 0.20226945 | E18: 0.303 | F18: 0.5284 | G18: 0.3646 | H18: 関係は弱い・なし
A19: 9月の月間走行距離 | C19: =SUMPRODUCT((選手一覧!$AC$6:$AC$35<>"")*(選手一覧!$G$6:$G$35<>"")) -> 12 | D19: =CORREL(選手一覧!$AC$6:$AC$35,選手一覧!$G$6:$G$35) -> 0.14122873 | E19: 0.123 | F19: 0.6615 | G19: 0.7177 | H19: 関係は弱い・なし
A20: 9月÷8月 | C20: =SUMPRODUCT((選手一覧!$AD$6:$AD$35<>"")*(選手一覧!$G$6:$G$35<>"")) -> 12 | D20: =CORREL(選手一覧!$AD$6:$AD$35,選手一覧!$G$6:$G$35) -> 0.049647893 | E20: 0.003 | F20: 0.8782 | G20: 0.9931 | H20: 関係は弱い・なし
A22: ※人数が少なく多くの項目を同時に調べているため、偶然5%を下回る項目が出ることもある。悪化率は出雲のタイムから計算しているので区間順位と関係が出やすい
A23: ※5000mの組内順位は組ごとに出場選手の強さが違う。2026年はロード5kmで他の年とレースの性格が異なる

Sheet 合宿メニュー_2023
A1: 2023年 夏合宿ポイント練習：出雲メンバー6人の組・消化率
A2: ※ 各セルは「組 消化率」。坂PTTは「坂TT/トータル」タイム、2026年2次の3000m+12000mビルドアップは最後の1kmのタイム
A3: ※ 「–」は記録なし（その練習に入っていない）。0%・30%は実施なし・部分実施
A4: ※ 出典：各年の合宿消化率（2023・2025年はExcel、2024・2026年はPDF）
A5: ※ 2025年2次合宿は、元データの日付欄が2023年の日付のまま残っていたため、日付を「—」とし実施順に並べた
A6: ※ 2024年2次合宿と2026年3次合宿は、PDFで日付欄が複数メニューにまたがっていたため、天候の記録時刻と並び順から日付を判断した
A8: 2023年（出雲 総合4位） メンバー：1区 野村昭夢／2区 黒田朝日／3区 佐藤一世／4区 山内健登／5区 鳥井健太／6区 鶴川正也
A10: 1次合宿（7/26〜8/16）
A11: 日付 | B11: メニュー（設定） | C11: 野村 | D11: 黒田朝 | E11: 佐藤一 | F11: 山内 | G11: 鳥井 | H11: 鶴川
A12: 7/26 | B12: 16km+200m×5（3:36→3:30） | C12: 30% | D12: A 100% | E12: A 100% | F12: A 100% | G12: A 100% | H12: 0%
A13: 8/3 | B13: CC24km（A 3:36→3:30／B 3:48→3:30） | C13: B1(16km) 30% | D13: 30% | E13: A1 100% | F13: A1 100% | G13: B1 100% | H13: 30%
A14: 8/5 | B14: 25km 中×4（A 3:30通し／B 3:36→3:30） | C14: B(22.75km) 70% | D14: A 100% | E14: A 100% | F14: A 100% | G14: B 100% | H14: 30%
A15: 8/8 | B15: 20km坂PTT（3:42→3:36） | C15: 11:03/1:13:42 100% | D15: 10:11/1:12:49 100% | E15: 11:15/1:13:54 100% | F15: 11:42/1:14:20 100% | G15: 10:39/1:13:17 100% | H15: 10:53/1:13:31 30%
A16: 8/10 | B16: 30km（A 3:42→3:36→3:30） | C16: A(22km) 70% | D16: A 100% | E16: A 100% | F16: A 100% | G16: B 100% | H16: A(22km) 70%
A17: 8/13 | B17: 20km坂PTT（3:42→3:36） | C17: 11:16/1:14:39 100% | D17: 10:00/1:13:23 100% | E17: 11:05/1:14:28 100% | F17: 11:54/1:15:17 100% | G17: 10:39/1:14:02 100% | H17: 10:41/1:14:04 100%
A18: 8/15 | B18: 42.195km（4:00目安） | C18: 21km+1km 30% | D18: 100% | E18: 100% | F18: 100% | G18: 100% | H18: 21km+1km 30%
A20: 2次合宿（8/25〜9/3）
A21: 日付 | B21: メニュー（設定） | C21: 野村 | D21: 黒田朝 | E21: 佐藤一 | F21: 山内 | G21: 鳥井 | H21: 鶴川
A22: 8/26 | B22: 16km+200m×5（3:30→3:10） | C22: A 100% | D22: A 100% | E22: A 100% | F22: A 100% | G22: B 100% | H22: A 70%
A23: 8/27 | B23: CC30km（3:42→3:36→3:30） | C23: A 100% | D23: A 100% | E23: A 100% | F23: A 100% | G23: B 100% | H23: A 100%
A24: 8/30 | B24: 24000mペース走+1000m×2（3:30→3:10／2:50） | C24: A 100% | D24: A 100% | E24: A 100% | F24: A 100% | G24: B 100% | H24: A 100%
A25: 9/2 | B25: CC30km（3:42→3:36→3:30） | C25: A 100% | D25: A 100% | E25: 30% | F25: A 100% | G25: B 100% | H25: A 100%
A27: 3次合宿（9/12〜9/17）
A28: 日付 | B28: メニュー（設定） | C28: 野村 | D28: 黒田朝 | E28: 佐藤一 | F28: 山内 | G28: 鳥井 | H28: 鶴川
A29: 9/12 | B29: 15km+150m×3（3:30→3:20） | C29: A 100% | D29: A 100% | E29: A 100% | F29: A 100% | G29: A 100% | H29: 30%
A30: 9/13 | B30: 1000m+12000m+400m+200m×5（2:40／3:20→3:10／58） | C30: A1 100% | D30: A1 100% | E30: A1 100% | F30: A1 100% | G30: A1 100% | H30: 12000m以降のみ 70%
A31: 9/15 | B31: 20km+1000m+200m×5（3:30／2:45／30-28） | C31: A1 100% | D31: A1 100% | E31: A1 70% | F31: A2 100% | G31: A1 100% | H31: A1 100%
A32: 9/17 | B32: 400m×12（66）R100m | C32: A1 100% | D32: A1 100% | E32: A1 100% | F32: A1 100% | G32: A2 100% | H32: A1 100%

Sheet 合宿メニュー_2024
A1: 2024年 夏合宿ポイント練習：出雲メンバー6人の組・消化率
A2: ※ 各セルは「組 消化率」。坂PTTは「坂TT/トータル」タイム、2026年2次の3000m+12000mビルドアップは最後の1kmのタイム
A3: ※ 「–」は記録なし（その練習に入っていない）。0%・30%は実施なし・部分実施
A4: ※ 出典：各年の合宿消化率（2023・2025年はExcel、2024・2026年はPDF）
A5: ※ 2025年2次合宿は、元データの日付欄が2023年の日付のまま残っていたため、日付を「—」とし実施順に並べた
A6: ※ 2024年2次合宿と2026年3次合宿は、PDFで日付欄が複数メニューにまたがっていたため、天候の記録時刻と並び順から日付を判断した
A8: 2024年（出雲 総合3位） メンバー：1区 鶴川正也／2区 野村昭夢／3区 黒田朝日／4区 宇田川瞬矢／5区 若林宏樹／6区 太田蒼生
A10: 1次合宿（8/1〜8/19、消化率の記録は8/11以降）
A11: 日付 | B11: メニュー（設定） | C11: 鶴川 | D11: 野村 | E11: 黒田朝 | F11: 宇田川 | G11: 若林 | H11: 太田
A12: 8/11 | B12: 21km坂PTT（3:42→3:36） | C12: 10:35/1:13:56 100% | D12: 10:40/1:14:01 100% | E12: 9:56/1:13:17 100% | F12: 11:18/1:14:39 100% | G12: 10:29/1:13:50 100% | H12: 70%
A13: 8/13 | B13: 25km（3:36→3:30）／30km組 | C13: A 100% | D13: A 100% | E13: A 100% | F13: A 100% | G13: A 100% | H13: A(30km) 100%
A14: 8/15 | B14: 21km坂PTT（3:42→3:36） | C14: 10:19/1:13:56 100% | D14: 10:59/1:14:36 100% | E14: 10:06/1:13:43 100% | F14: 11:23/1:15:00 100% | G14: 10:51/1:14:28 100% | H14: 10:57/1:14:34 100%
A15: 8/18 | B15: 42.195km（2:45:00目安） | C15: 100% | D15: 100% | E15: 100% | F15: 100% | G15: 2周目以降山jog 30% | H15: 100%
A17: 2次合宿（8/27〜9/5）
A18: 日付 | B18: メニュー（設定） | C18: 鶴川 | D18: 野村 | E18: 黒田朝 | F18: 宇田川 | G18: 若林 | H18: 太田
A19: 8/28 | B19: CC25km（3:36→3:30） | C19: A1 100% | D19: A1 100% | E19: A1 100% | F19: A2 100% | G19: A1 100% | H19: A2 100%
A20: 8/30 | B20: 400m×12（A 65）R200m | C20: A1 100% | D20: A1 100% | E20: A1 100% | F20: A2 100% | G20: A1 100% | H20: A1 100%
A21: 9/1 | B21: CC21km+3000m（3:36→3:30／A 8:50） | C21: A1 100% | D21: A1 100% | E21: A1 100% | F21: A2 90% | G21: A1 100% | H21: A1 100%
A22: 9/4 | B22: CC30km（3:42→3:36→3:30） | C22: A1 30% | D22: A1 100% | E22: A1 100% | F22: A2 100% | G22: A1 100% | H22: A1 100%
A24: 3次合宿（9/13〜9/21）
A25: 日付 | B25: メニュー（設定） | C25: 鶴川 | D25: 野村 | E25: 黒田朝 | F25: 宇田川 | G25: 若林 | H25: 太田
A26: 9/14 | B26: 25km(30km)（3:42→3:30） | C26: A1 100% | D26: A1 100% | E26: A1 100% | F26: A2 100% | G26: A1 100% | H26: A1(21km) 70%
A27: 9/15 | B27: 400m×12（A 64／B2 65）R200m | C27: A1 100% | D27: A1 100% | E27: A1 100% | F27: A2 100% | G27: A1 100% | H27: A1 100%
A28: 9/18 | B28: 1000m×2+12000m+200m×5（2:40／3:20→3:10／30-28） | C28: A1 100% | D28: A1 100% | E28: A1 100% | F28: A2 100% | G28: A1 100% | H28: A1 100%
A29: 9/21 | B29: 3000m+8000mビルドアップ+1000m+400m（A 8:25／3:30→2:50／2:45／60） | C29: A 100% | D29: A 100% | E29: A 100% | F29: A 100% | G29: A 100% | H29: A 100%

Sheet 合宿メニュー_2025
A1: 2025年 夏合宿ポイント練習：出雲メンバー6人の組・消化率
A2: ※ 各セルは「組 消化率」。坂PTTは「坂TT/トータル」タイム、2026年2次の3000m+12000mビルドアップは最後の1kmのタイム
A3: ※ 「–」は記録なし（その練習に入っていない）。0%・30%は実施なし・部分実施
A4: ※ 出典：各年の合宿消化率（2023・2025年はExcel、2024・2026年はPDF）
A5: ※ 2025年2次合宿は、元データの日付欄が2023年の日付のまま残っていたため、日付を「—」とし実施順に並べた
A6: ※ 2024年2次合宿と2026年3次合宿は、PDFで日付欄が複数メニューにまたがっていたため、天候の記録時刻と並び順から日付を判断した
A8: 2025年（出雲 総合7位） メンバー：1区 小河原陽琉／2区 折田壮太／3区 飯田翔大／4区 神邑亮佑／5区 塩出翔太／6区 黒田朝日
A10: 1次合宿（8/1〜8/19）
A11: 日付 | B11: メニュー（設定） | C11: 小河原 | D11: 折田 | E11: 飯田 | F11: 神邑 | G11: 塩出 | H11: 黒田朝
A12: 8/8 | B12: 25km 中×4（3:36→3:30） | C12: A 100% | D12: A 100% | E12: A 100% | F12: B 100% | G12: A 100% | H12: A 100%
A13: 8/11 | B13: 21km坂PTT（3:42→3:36） | C13: 10:44/1:13:50 100% | D13: 11:31/1:14:37 100% | E13: 10:31/1:13:37 100% | F13: 10:54/1:14:00 100% | G13: 10:58/1:14:04 100% | H13: 9:41/1:12:47 100%
A14: 8/13 | B14: 25km 中×4（3:36→3:30） | C14: A 100% | D14: B 100% | E14: A 100% | F14: B 100% | G14: A 100% | H14: A 100%
A15: 8/15 | B15: 21km坂PTT（3:42→3:36） | C15: 11:36/1:14:48 100% | D15: 11:26/1:14:38 100% | E15: 30% | F15: 10:39/1:13:51 100% | G15: 11:04/1:14:16 100% | H15: 9:58/1:13:10 100%
A16: 最終盤 | B16: 42.195km（2時間45分前後） | C16: 100% | D16: 100% | E16: 0% | F16: 100% | G16: 100% | H16: 100%
A18: 2次合宿（8/26〜9/4）
A19: 日付 | B19: メニュー（設定） | C19: 小河原 | D19: 折田 | E19: 飯田 | F19: 神邑 | G19: 塩出 | H19: 黒田朝
A20: — | B20: CC16km（3:30） | C20: A 100% | D20: A 100% | E20: C 100% | F20: C 100% | G20: A 100% | H20: A 100%
A21: — | B21: 1000m×2+8000m+200m×5（2:45／3:20→3:10／30） | C21: A 100% | D21: A 100% | E21: C 100% | F21: C 100% | G21: A 100% | H21: A 100%
A22: — | B22: CC30km（3:42→3:36→3:30）※飯田は別メニューのCC30km（3:36→3:30） | C22: A 100% | D22: A 100% | E22: 100% | F22: C 100% | G22: A 100% | H22: A 100%
A23: — | B23: CC25km（3:36→3:30） | C23: A 100% | D23: A 100% | E23: B 100% | F23: B 100% | G23: A 100% | H23: A 100%
A24: 9/3 | B24: 400m×12（65）R200m | C24: A 100% | D24: A 100% | E24: B 100% | F24: C 100% | G24: A 100% | H24: A 100%
A26: 3次合宿（9/12〜9/20）
A27: 日付 | B27: メニュー（設定） | C27: 小河原 | D27: 折田 | E27: 飯田 | F27: 神邑 | G27: 塩出 | H27: 黒田朝
A28: 9/12 | B28: 30km（1:45目安） | C28: A 100% | D28: A 100% | E28: A 100% | F28: B 100% | G28: A 100% | H28: A 100%
A29: 9/14 | B29: 1000m×2+12000m+200m×5（2:40／3:20→3:10／30-28） | C29: A1 100% | D29: A1 100% | E29: A1 100% | F29: A2 100% | G29: A1 100% | H29: A1 100%
A30: 9/17 | B30: (1200m+800m+400m)×3（A,B 64） | C30: A 100% | D30: A 100% | E30: A 100% | F30: B 100% | G30: A 100% | H30: A 100%
A31: 9/20 | B31: 400m×12（64）R200m | C31: A 100% | D31: A 100% | E31: A 100% | F31: B 100% | G31: A 100% | H31: A 100%

Sheet 合宿メニュー_2026
A1: 2026年 夏合宿ポイント練習：出雲メンバー6人の組・消化率
A2: ※ 各セルは「組 消化率」。坂PTTは「坂TT/トータル」タイム、2026年2次の3000m+12000mビルドアップは最後の1kmのタイム
A3: ※ 「–」は記録なし（その練習に入っていない）。0%・30%は実施なし・部分実施
A4: ※ 出典：各年の合宿消化率（2023・2025年はExcel、2024・2026年はPDF）
A5: ※ 2025年2次合宿は、元データの日付欄が2023年の日付のまま残っていたため、日付を「—」とし実施順に並べた
A6: ※ 2024年2次合宿と2026年3次合宿は、PDFで日付欄が複数メニューにまたがっていたため、天候の記録時刻と並び順から日付を判断した
A8: 2026年（出雲 総合11位） メンバー：1区 石川浩輝／2区 鳥井健太／3区 飯田翔大／4区 小河原陽琉／5区 黒田然／6区 前川竜之将
A10: 1次合宿（8/2〜8/19）
A11: 日付 | B11: メニュー（設定） | C11: 石川 | D11: 鳥井 | E11: 飯田 | F11: 小河原 | G11: 黒田然 | H11: 前川
A12: 8/6 | B12: CC25km【(485m×6+1003m×2+2000m)×3+485m×6+1003m】（3:42→3:36→3:30） | C12: A 100% | D12: A 100% | E12: 30% | F12: A 100% | G12: CC21km(山の家) 11:19/1:11:34 100% | H12: B 100%
